{"topic":"orderbook.50.BTCUSDT","type":"snapshot","ts":1787954747128,"data":{"s":"BTCUSDT","b":[["77364.60","3.756"],["77364.50","0.540"],["77364.40","0.083"],["77364.20","0.303"],["77364.00","0.001"],["77362.90","0.001"],["77362.80","0.205"],["77362.60","0.001"],["77362.50","0.370"],["77362.00","0.373"],["77361.80","0.238"],["77361.60","0.001"],["77361.50","0.004"],["77361.20","0.444"],["77361.00","0.243"],["77360.50","0.002"],["77360.10","0.002"],["77360.00","0.001"],["77359.70","1.504"],["77359.60","2.307"],["77359.40","1.993"],["77359.20","0.001"],["77358.90","0.005"],["77358.80","0.001"],["77358.70","0.002"],["77358.60","0.011"],["77358.20","0.002"],["77358.00","0.014"],["77357.90","0.008"],["77357.60","0.002"],["77357.30","0.001"],["77357.10","0.380"],["77357.00","0.013"],["77356.90","0.009"],["77356.80","0.058"],["77356.60","0.001"],["77356.50","0.372"],["77356.40","0.397"],["77356.30","0.001"],["77356.20","0.130"],["77356.10","0.987"],["77356.00","1.937"],["77355.80","0.264"],["77355.70","0.006"],["77355.60","0.027"],["77355.50","0.002"],["77355.30","0.002"],["77355.20","0.013"],["77355.10","0.001"],["77355.00","0.013"]],"a":[["77364.70","9.673"],["77364.80","0.001"],["77364.90","0.001"],["77365.00","0.004"],["77365.60","0.001"],["77365.80","0.004"],["77365.90","0.001"],["77366.40","0.003"],["77366.50","0.002"],["77366.70","0.001"],["77366.80","0.001"],["77367.20","0.030"],["77367.30","0.002"],["77367.40","0.001"],["77367.50","0.006"],["77367.70","0.001"],["77367.90","3.554"],["77368.00","14.003"],["77368.50","0.002"],["77368.60","0.002"],["77368.80","0.001"],["77368.90","0.056"],["77369.30","0.002"],["77369.50","0.003"],["77369.80","0.001"],["77370.00","0.005"],["77370.30","0.001"],["77370.50","0.001"],["77370.60","0.007"],["77370.80","0.010"],["77371.00","0.031"],["77371.10","0.006"],["77371.20","4.194"],["77371.30","14.001"],["77371.40","0.003"],["77371.50","0.006"],["77371.60","0.031"],["77371.80","0.001"],["77372.10","0.323"],["77372.30","0.002"],["77372.60","0.001"],["77372.90","0.002"],["77373.00","0.002"],["77373.10","0.005"],["77373.20","0.072"],["77373.70","0.007"],["77373.80","0.003"],["77374.00","0.188"],["77374.10","0.051"],["77374.20","0.002"]],"u":101054915,"seq":800573227279},"cts":1787954747125}
{"topic":"orderbook.50.BTCUSDT","type":"delta","ts":1787954747148,"data":{"s":"BTCUSDT","b":[["77357.00","0.012"],["77356.10","0.988"]],"a":[],"u":101054916,"seq":800573227328},"cts":1787954747147}
{"topic":"orderbook.50.BTCUSDT","type":"delta","ts":1787954747169,"data":{"s":"BTCUSDT","b":[["77359.30","0.001"],["77356.10","0.987"],["77355.00","0"]],"a":[["77373.50","0.002"],["77374.20","0"]],"u":101054917,"seq":800573227356},"cts":1787954747167}
{"topic":"orderbook.50.BTCUSDT","type":"delta","ts":1787954747189,"data":{"s":"BTCUSDT","b":[],"a":[["77367.80","0.006"],["77371.10","0"]],"u":101054918,"seq":800573227392},"cts":1787954747184}
{"topic":"orderbook.50.BTCUSDT","type":"delta","ts":1787954747208,"data":{"s":"BTCUSDT","b":[["77359.30","0"],["77356.40","0.398"],["77355.00","0.013"]],"a":[],"u":101054919,"seq":800573227431},"cts":1787954747207}
{"topic":"orderbook.50.BTCUSDT","type":"delta","ts":1787954747248,"data":{"s":"BTCUSDT","b":[["77359.40","1.873"]],"a":[],"u":101054920,"seq":800573227503},"cts":1787954747243}
{"topic":"orderbook.50.BTCUSDT","type":"delta","ts":1787954747268,"data":{"s":"BTCUSDT","b":[["77359.40","1.848"]],"a":[["77373.50","0"],["77373.90","0.002"]],"u":101054921,"seq":800573227537},"cts":1787954747266}
{"topic":"orderbook.50.BTCUSDT","type":"delta","ts":1787954747289,"data":{"s":"BTCUSDT","b":[["77355.20","0.271"]],"a":[["77367.80","0"],["77371.10","0.006"],["77373.90","0"],["77374.20","0.002"]],"u":101054922,"seq":800573227608},"cts":1787954747286}
{"topic":"orderbook.50.BTCUSDT","type":"delta","ts":1787954747308,"data":{"s":"BTCUSDT","b":[["77364.60","3.806"],["77358.60","0.080"],["77355.40","0.258"],["77355.20","0.013"],["77355.00","0"]],"a":[],"u":101054923,"seq":800573227665},"cts":1787954747307}
{"topic":"orderbook.50.BTCUSDT","type":"delta","ts":1787954747369,"data":{"s":"BTCUSDT","b":[["77364.60","3.831"]],"a":[["77366.60","0.002"],["77374.20","0"]],"u":101054924,"seq":800573227739},"cts":1787954747364}
{"topic":"orderbook.50.BTCUSDT","type":"delta","ts":1787954747429,"data":{"s":"BTCUSDT","b":[["77355.40","0"],["77355.30","0.260"],["77355.00","0.013"]],"a":[["77364.70","9.655"]],"u":101054925,"seq":800573227846},"cts":1787954747427}
{"topic":"orderbook.50.BTCUSDT","type":"delta","ts":1787954747448,"data":{"s":"BTCUSDT","b":[["77355.30","0.002"],["77355.10","0.259"]],"a":[],"u":101054926,"seq":800573227926},"cts":1787954747443}
{"success":true,"ret_msg":"","conn_id":"da7tn48ppdl4sp3gt52g-iavr","req_id":"","op":"subscribe"}
{"topic":"orderbook.50.BTCUSDT","type":"delta","ts":1787954747608,"data":{"s":"BTCUSDT","b":[["77359.40","1.858"]],"a":[],"u":101054927,"seq":800573228128},"cts":1787954747605}
{"topic":"orderbook.50.BTCUSDT","type":"delta","ts":1787954747628,"data":{"s":"BTCUSDT","b":[["77361.20","0.336"]],"a":[],"u":101054928,"seq":800573228170},"cts":1787954747627}
{"topic":"orderbook.50.BTCUSDT","type":"delta","ts":1787954747649,"data":{"s":"BTCUSDT","b":[["77363.80","0.002"],["77361.20","0.226"],["77355.10","0.001"],["77355.00","0"]],"a":[["77365.70","0.011"],["77367.90","3.560"],["77371.00","0.033"],["77371.10","0"],["77371.60","0.033"],["77373.10","0.007"],["77373.80","0.005"]],"u":101054929,"seq":800573228276},"cts":1787954747646}
{"topic":"orderbook.50.BTCUSDT","type":"delta","ts":1787954747669,"data":{"s":"BTCUSDT","b":[],"a":[["77371.00","0.031"],["77371.60","0.031"],["77372.10","0.703"]],"u":101054930,"seq":800573228304},"cts":1787954747665}
{"topic":"orderbook.50.BTCUSDT","type":"delta","ts":1787954747709,"data":{"s":"BTCUSDT","b":[],"a":[["77372.30","0.004"]],"u":101054931,"seq":800573228346},"cts":1787954747706}
{"topic":"orderbook.50.BTCUSDT","type":"delta","ts":1787954747729,"data":{"s":"BTCUSDT","b":[],"a":[["77371.60","0.033"],["77372.30","0.002"]],"u":101054932,"seq":800573228380},"cts":1787954747724}
{"topic":"orderbook.50.BTCUSDT","type":"delta","ts":1787954747748,"data":{"s":"BTCUSDT","b":[],"a":[["77371.60","0.031"],["77372.60","0.003"]],"u":101054933,"seq":800573228407},"cts":1787954747743}
{"topic":"orderbook.50.BTCUSDT","type":"delta","ts":1787954747808,"data":{"s":"BTCUSDT","b":[],"a":[["77372.60","0.001"],["77373.10","0.005"]],"u":101054934,"seq":800573228476},"cts":1787954747807}
{"topic":"orderbook.50.BTCUSDT","type":"delta","ts":1787954747848,"data":{"s":"BTCUSDT","b":[],"a":[["77373.20","0.074"]],"u":101054935,"seq":800573228534},"cts":1787954747844}
{"topic":"orderbook.50.BTCUSDT","type":"delta","ts":1787954747868,"data":{"s":"BTCUSDT","b":[],"a":[["77371.80","0.003"],["77372.70","0.002"],["77374.10","0"]],"u":101054936,"seq":800573228557},"cts":1787954747864}
{"topic":"orderbook.50.BTCUSDT","type":"delta","ts":1787954747929,"data":{"s":"BTCUSDT","b":[["77364.60","3.896"]],"a":[["77371.80","0.001"]],"u":101054937,"seq":800573228624},"cts":1787954747923}
{"topic":"orderbook.50.BTCUSDT","type":"delta","ts":1787954747948,"data":{"s":"BTCUSDT","b":[],"a":[["77367.40","0.003"]],"u":101054938,"seq":800573228652},"cts":1787954747945}
{"topic":"orderbook.50.BTCUSDT","type":"delta","ts":1787954748008,"data":{"s":"BTCUSDT","b":[],"a":[["77372.70","0"],["77373.20","0.072"],["77373.80","0.003"],["77374.10","0.051"]],"u":101054939,"seq":800573228727},"cts":1787954748008}
{"topic":"orderbook.50.BTCUSDT","type":"delta","ts":1787954748029,"data":{"s":"BTCUSDT","b":[["77355.40","0.258"],["77355.10","0"]],"a":[["77367.90","3.554"],["77371.10","0.006"],["77374.10","0"]],"u":101054940,"seq":800573228827},"cts":1787954748026}
{"topic":"orderbook.50.BTCUSDT","type":"delta","ts":1787954748049,"data":{"s":"BTCUSDT","b":[["77359.80","0.006"],["77355.20","0"]],"a":[["77367.90","0.002"]],"u":101054941,"seq":800573228894},"cts":1787954748046}
{"topic":"orderbook.50.BTCUSDT","type":"delta","ts":1787954748069,"data":{"s":"BTCUSDT","b":[["77355.40","0"],["77355.20","0.013"]],"a":[],"u":101054942,"seq":800573228926},"cts":1787954748067}
{"topic":"orderbook.50.BTCUSDT","type":"delta","ts":1787954748089,"data":{"s":"BTCUSDT","b":[["77359.80","0"],["77355.10","0.001"]],"a":[],"u":101054943,"seq":800573228956},"cts":1787954748086}
{"topic":"orderbook.50.BTCUSDT","type":"delta","ts":1787954748129,"data":{"s":"BTCUSDT","b":[],"a":[["77368.00","14.001"],["77368.10","0.002"],["77371.50","0.005"],["77374.00","0"]],"u":101054944,"seq":800573229042},"cts":1787954748127}
{"topic":"orderbook.50.BTCUSDT","type":"delta","ts":1787954748168,"data":{"s":"BTCUSDT","b":[["77360.40","0.003"],["77355.10","0"]],"a":[],"u":101054945,"seq":800573229100},"cts":1787954748158}
{"topic":"orderbook.50.BTCUSDT","type":"delta","ts":1787954748228,"data":{"s":"BTCUSDT","b":[],"a":[["77364.70","9.680"]],"u":101054946,"seq":800573229195},"cts":1787954748220}
{"topic":"orderbook.50.BTCUSDT","type":"delta","ts":1787954748269,"data":{"s":"BTCUSDT","b":[],"a":[["77364.70","9.705"]],"u":101054947,"seq":800573229245},"cts":1787954748266}
{"topic":"orderbook.50.BTCUSDT","type":"delta","ts":1787954748288,"data":{"s":"BTCUSDT","b":[],"a":[["77364.70","9.730"],["77367.90","0.008"],["77371.10","0"],["77372.10","0.323"],["77374.00","0.188"]],"u":101054948,"seq":800573229343},"cts":1787954748286}
{"topic":"orderbook.50.BTCUSDT","type":"delta","ts":1787954748328,"data":{"s":"BTCUSDT","b":[["77359.80","0.135"],["77355.20","0"]],"a":[["77367.90","0.002"],["77371.10","0.006"],["77374.00","0"]],"u":101054949,"seq":800573229453},"cts":1787954748326}
{"topic":"orderbook.50.BTCUSDT","type":"delta","ts":1787954748348,"data":{"s":"BTCUSDT","b":[["77359.80","0.129"]],"a":[],"u":101054950,"seq":800573229498},"cts":1787954748346}
{"topic":"orderbook.50.BTCUSDT","type":"delta","ts":1787954748388,"data":{"s":"BTCUSDT","b":[["77364.60","4.455"],["77364.40","0"],["77364.20","0.225"],["77359.80","0"],["77356.70","0.258"],["77355.20","0.013"]],"a":[["77364.70","9.157"],["77368.80","0"],["77370.60","0.004"],["77371.20","0.002"],["77373.70","0.003"],["77374.00","0.188"]],"u":101054951,"seq":800573229800},"cts":1787954748387}
{"topic":"orderbook.50.BTCUSDT","type":"delta","ts":1787954748408,"data":{"s":"BTCUSDT","b":[["77359.90","0.006"],["77359.80","0.129"],["77355.30","0"],["77355.20","0"]],"a":[["77371.10","0"],["77371.20","0.007"],["77374.10","0.051"]],"u":101054952,"seq":800573229896},"cts":1787954748406}
{"topic":"orderbook.50.BTCUSDT","type":"delta","ts":1787954748429,"data":{"s":"BTCUSDT","b":[["77364.60","4.457"],["77359.40","1.856"]],"a":[["77374.00","0.001"]],"u":101054953,"seq":800573229974},"cts":1787954748427}
{"topic":"orderbook.50.BTCUSDT","type":"delta","ts":1787954748449,"data":{"s":"BTCUSDT","b":[["77358.50","0.001"],["77356.40","0.397"],["77355.50","0"]],"a":[],"u":101054954,"seq":800573230017},"cts":1787954748446}
{"topic":"orderbook.50.BTCUSDT","type":"delta","ts":1787954748468,"data":{"s":"BTCUSDT","b":[["77358.50","0"],["77357.00","0.013"],["77355.50","0.002"]],"a":[["77371.40","0"],["77374.20","0.002"]],"u":101054955,"seq":800573230079},"cts":1787954748466}
{"topic":"orderbook.50.BTCUSDT","type":"delta","ts":1787954748488,"data":{"s":"BTCUSDT","b":[],"a":[["77371.20","4.294"]],"u":101054956,"seq":800573230122},"cts":1787954748482}
{"topic":"orderbook.50.BTCUSDT","type":"delta","ts":1787954748508,"data":{"s":"BTCUSDT","b":[["77364.60","4.455"],["77356.70","0"],["77356.50","0.630"],["77355.30","0.002"]],"a":[],"u":101054957,"seq":800573230190},"cts":1787954748507}
{"topic":"orderbook.50.BTCUSDT","type":"delta","ts":1787954748548,"data":{"s":"BTCUSDT","b":[["77356.50","0.372"],["77356.30","0.259"]],"a":[],"u":101054958,"seq":800573230261},"cts":1787954748547}
{"topic":"orderbook.50.BTCUSDT","type":"delta","ts":1787954748569,"data":{"s":"BTCUSDT","b":[],"a":[["77371.40","0.003"],["77374.00","0.188"],["77374.20","0"]],"u":101054959,"seq":800573230301},"cts":1787954748560}
{"topic":"orderbook.50.BTCUSDT","type":"delta","ts":1787954748608,"data":{"s":"BTCUSDT","b":[["77356.30","0.001"],["77356.20","0.388"]],"a":[],"u":101054960,"seq":800573230344},"cts":1787954748607}
{"topic":"orderbook.50.BTCUSDT","type":"delta","ts":1787954748629,"data":{"s":"BTCUSDT","b":[],"a":[["77367.00","0.010"],["77374.10","0"]],"u":101054961,"seq":800573230378},"cts":1787954748625}
{"topic":"orderbook.50.BTCUSDT","type":"delta","ts":1787954748688,"data":{"s":"BTCUSDT","b":[["77364.60","4.625"]],"a":[],"u":101054962,"seq":800573230446},"cts":1787954748686}
{"topic":"orderbook.50.BTCUSDT","type":"delta","ts":1787954748708,"data":{"s":"BTCUSDT","b":[["77356.20","0.130"],["77356.10","1.245"]],"a":[],"u":101054963,"seq":800573230464},"cts":1787954748707}
{"topic":"orderbook.50.BTCUSDT","type":"delta","ts":1787954748748,"data":{"s":"BTCUSDT","b":[["77358.50","0.001"],["77357.00","0.012"],["77355.30","0"]],"a":[],"u":101054964,"seq":800573230544},"cts":1787954748748}
{"topic":"orderbook.50.BTCUSDT","type":"delta","ts":1787954748788,"data":{"s":"BTCUSDT","b":[],"a":[["77364.70","9.154"]],"u":101054965,"seq":800573230608},"cts":1787954748787}
{"topic":"orderbook.50.BTCUSDT","type":"delta","ts":1787954748849,"data":{"s":"BTCUSDT","b":[["77364.60","4.066"],["77356.10","0.987"],["77355.70","0.264"]],"a":[["77371.20","4.295"]],"u":101054966,"seq":800573230732},"cts":1787954748844}
{"topic":"orderbook.50.BTCUSDT","type":"delta","ts":1787954748868,"data":{"s":"BTCUSDT","b":[],"a":[["77373.70","0.005"]],"u":101054967,"seq":800573230788},"cts":1787954748867}
{"topic":"orderbook.50.BTCUSDT","type":"delta","ts":1787954748909,"data":{"s":"BTCUSDT","b":[["77355.90","0.258"],["77355.70","0.006"],["77355.50","0"]],"a":[],"u":101054968,"seq":800573230855},"cts":1787954748907}
{"topic":"orderbook.50.BTCUSDT","type":"delta","ts":1787954748928,"data":{"s":"BTCUSDT","b":[["77358.50","0"],["77356.40","0.398"],["77355.50","0.002"]],"a":[],"u":101054969,"seq":800573230872},"cts":1787954748913}
{"topic":"orderbook.50.BTCUSDT","type":"delta","ts":1787954748949,"data":{"s":"BTCUSDT","b":[],"a":[["77373.70","0.007"]],"u":101054970,"seq":800573230911},"cts":1787954748943}
{"topic":"orderbook.50.BTCUSDT","type":"delta","ts":1787954749169,"data":{"s":"BTCUSDT","b":[],"a":[["77364.70","9.164"]],"u":101054971,"seq":800573231153},"cts":1787954749166}
{"topic":"orderbook.50.BTCUSDT","type":"delta","ts":1787954749188,"data":{"s":"BTCUSDT","b":[["77362.50","0.371"]],"a":[],"u":101054972,"seq":800573231172},"cts":1787954749184}
{"topic":"orderbook.50.BTCUSDT","type":"delta","ts":1787954749348,"data":{"s":"BTCUSDT","b":[["77362.50","0.370"],["77356.10","1.245"],["77355.90","0"],["77355.30","0.002"]],"a":[],"u":101054973,"seq":800573231450},"cts":1787954749346}
{"topic":"orderbook.50.BTCUSDT","type":"delta","ts":1787954749368,"data":{"s":"BTCUSDT","b":[["77356.10","0.987"],["77355.90","0.258"],["77355.30","0"]],"a":[],"u":101054974,"seq":800573231476},"cts":1787954749364}
{"topic":"orderbook.50.BTCUSDT","type":"delta","ts":1787954749389,"data":{"s":"BTCUSDT","b":[["77356.80","0.057"]],"a":[],"u":101054975,"seq":800573231525},"cts":1787954749383}
{"topic":"orderbook.50.BTCUSDT","type":"delta","ts":1787954749448,"data":{"s":"BTCUSDT","b":[["77362.30","0.010"],["77360.60","0.012"],["77355.60","0"],["77355.50","0"]],"a":[],"u":101054976,"seq":800573231603},"cts":1787954749446}
{"topic":"orderbook.50.BTCUSDT","type":"delta","ts":1787954749549,"data":{"s":"BTCUSDT","b":[["77355.90","0"],["77355.60","0.027"]],"a":[],"u":101054977,"seq":800573231754},"cts":1787954749546}
{"topic":"orderbook.50.BTCUSDT","type":"delta","ts":1787954749568,"data":{"s":"BTCUSDT","b":[["77364.60","4.085"],["77355.80","0.245"]],"a":[],"u":101054978,"seq":800573231790},"cts":1787954749566}
{"topic":"orderbook.50.BTCUSDT","type":"delta","ts":1787954749609,"data":{"s":"BTCUSDT","b":[["77355.80","0.503"]],"a":[],"u":101054979,"seq":800573231839},"cts":1787954749605}
{"topic":"orderbook.50.BTCUSDT","type":"delta","ts":1787954749629,"data":{"s":"BTCUSDT","b":[["77355.80","0.245"]],"a":[],"u":101054980,"seq":800573231878},"cts":1787954749616}
{"topic":"orderbook.50.BTCUSDT","type":"delta","ts":1787954749709,"data":{"s":"BTCUSDT","b":[["77355.80","0.503"]],"a":[],"u":101054981,"seq":800573232036},"cts":1787954749706}
{"topic":"orderbook.50.BTCUSDT","type":"delta","ts":1787954749808,"data":{"s":"BTCUSDT","b":[["77355.90","0.258"],["77355.80","0.245"],["77355.60","0"]],"a":[],"u":101054982,"seq":800573232190},"cts":1787954749806}
{"topic":"orderbook.50.BTCUSDT","type":"delta","ts":1787954750108,"data":{"s":"BTCUSDT","b":[["77355.90","0"],["77355.80","0.503"],["77355.60","0.027"]],"a":[],"u":101054983,"seq":800573232464},"cts":1787954750107}
{"topic":"orderbook.50.BTCUSDT","type":"delta","ts":1787954750129,"data":{"s":"BTCUSDT","b":[["77362.50","0.371"],["77355.60","0"],["77355.50","0.002"]],"a":[],"u":101054984,"seq":800573232499},"cts":1787954750124}
{"topic":"orderbook.50.BTCUSDT","type":"delta","ts":1787954750148,"data":{"s":"BTCUSDT","b":[["77355.80","0.245"],["77355.60","0.258"],["77355.50","0"]],"a":[["77371.60","0.033"],["77372.50","0.002"],["77373.00","0.004"],["77374.00","0"]],"u":101054985,"seq":800573232596},"cts":1787954750147}
{"topic":"orderbook.50.BTCUSDT","type":"delta","ts":1787954750169,"data":{"s":"BTCUSDT","b":[["77355.60","0"],["77355.50","0.002"]],"a":[["77371.60","0.031"],["77372.50","0"],["77373.00","0.002"],["77373.50","0.002"]],"u":101054986,"seq":800573232646},"cts":1787954750164}
{"topic":"orderbook.50.BTCUSDT","type":"delta","ts":1787954750188,"data":{"s":"BTCUSDT","b":[["77359.90","0"],["77355.30","0.002"]],"a":[["77373.50","0"],["77373.90","0.002"]],"u":101054987,"seq":800573232661},"cts":1787954750176}
{"topic":"orderbook.50.BTCUSDT","type":"delta","ts":1787954750248,"data":{"s":"BTCUSDT","b":[["77359.80","0"],["77355.20","0.013"]],"a":[["77373.90","0"],["77374.00","0.188"]],"u":101054988,"seq":800573232759},"cts":1787954750247}
{"topic":"orderbook.50.BTCUSDT","type":"delta","ts":1787954750268,"data":{"s":"BTCUSDT","b":[],"a":[["77367.90","0.008"],["77371.20","4.289"]],"u":101054989,"seq":800573232821},"cts":1787954750266}
{"topic":"orderbook.50.BTCUSDT","type":"delta","ts":1787954750288,"data":{"s":"BTCUSDT","b":[["77362.50","0.370"]],"a":[["77367.90","0.002"],["77371.10","0.006"],["77374.00","0"]],"u":101054990,"seq":800573232857},"cts":1787954750286}
{"topic":"orderbook.50.BTCUSDT","type":"delta","ts":1787954750369,"data":{"s":"BTCUSDT","b":[["77360.00","0.013"]],"a":[],"u":101054991,"seq":800573232952},"cts":1787954750366}
{"topic":"orderbook.50.BTCUSDT","type":"delta","ts":1787954750448,"data":{"s":"BTCUSDT","b":[],"a":[["77367.90","0.008"],["77371.10","0"],["77374.00","0.188"]],"u":101054992,"seq":800573233052},"cts":1787954750447}
{"topic":"orderbook.50.BTCUSDT","type":"delta","ts":1787954750469,"data":{"s":"BTCUSDT","b":[],"a":[["77364.70","9.173"]],"u":101054993,"seq":800573233106},"cts":1787954750466}
{"topic":"orderbook.50.BTCUSDT","type":"delta","ts":1787954750488,"data":{"s":"BTCUSDT","b":[["77361.80","0.270"]],"a":[],"u":101054994,"seq":800573233140},"cts":1787954750487}
{"topic":"orderbook.50.BTCUSDT","type":"delta","ts":1787954750549,"data":{"s":"BTCUSDT","b":[],"a":[["77367.90","0.002"],["77371.10","0.006"],["77374.00","0"]],"u":101054995,"seq":800573233228},"cts":1787954750540}
{"topic":"orderbook.50.BTCUSDT","type":"delta","ts":1787954750808,"data":{"s":"BTCUSDT","b":[["77356.10","1.357"]],"a":[],"u":101054996,"seq":800573233428},"cts":1787954750807}
{"topic":"orderbook.50.BTCUSDT","type":"delta","ts":1787954750988,"data":{"s":"BTCUSDT","b":[["77359.40","1.842"]],"a":[["77364.70","9.169"]],"u":101054997,"seq":800573233585},"cts":1787954750986}
{"topic":"orderbook.50.BTCUSDT","type":"delta","ts":1787954751089,"data":{"s":"BTCUSDT","b":[["77362.50","0.371"]],"a":[],"u":101054998,"seq":800573233669},"cts":1787954751086}
{"topic":"orderbook.50.BTCUSDT","type":"delta","ts":1787954751228,"data":{"s":"BTCUSDT","b":[["77362.50","0.370"]],"a":[],"u":101054999,"seq":800573233752},"cts":1787954751223}
{"topic":"orderbook.50.BTCUSDT","type":"delta","ts":1787954751308,"data":{"s":"BTCUSDT","b":[["77359.40","0.302"]],"a":[],"u":101055000,"seq":800573233804},"cts":1787954751303}
{"topic":"orderbook.50.BTCUSDT","type":"delta","ts":1787954751328,"data":{"s":"BTCUSDT","b":[["77359.70","1.061"]],"a":[],"u":101055001,"seq":800573233833},"cts":1787954751327}
{"topic":"orderbook.50.BTCUSDT","type":"delta","ts":1787954751388,"data":{"s":"BTCUSDT","b":[["77356.40","0.397"],["77356.00","1.938"]],"a":[],"u":101055002,"seq":800573233893},"cts":1787954751382}
{"topic":"orderbook.50.BTCUSDT","type":"delta","ts":1787954751589,"data":{"s":"BTCUSDT","b":[],"a":[["77373.20","0"],["77374.00","0.188"]],"u":101055003,"seq":800573234081},"cts":1787954751584}
{"topic":"orderbook.50.BTCUSDT","type":"delta","ts":1787954751708,"data":{"s":"BTCUSDT","b":[],"a":[["77364.70","9.381"]],"u":101055004,"seq":800573234169},"cts":1787954751707}
{"topic":"orderbook.50.BTCUSDT","type":"delta","ts":1787954751849,"data":{"s":"BTCUSDT","b":[],"a":[["77367.90","0.008"],["77371.10","0"],["77374.10","0.051"]],"u":101055005,"seq":800573234311},"cts":1787954751846}
{"topic":"orderbook.50.BTCUSDT","type":"delta","ts":1787954751889,"data":{"s":"BTCUSDT","b":[],"a":[["77367.90","0.002"],["77371.10","0.006"],["77374.10","0"]],"u":101055006,"seq":800573234358},"cts":1787954751886}
{"topic":"orderbook.50.BTCUSDT","type":"delta","ts":1787954752049,"data":{"s":"BTCUSDT","b":[],"a":[["77373.60","0.002"],["77374.00","0"]],"u":101055007,"seq":800573234491},"cts":1787954752046}
{"topic":"orderbook.50.BTCUSDT","type":"delta","ts":1787954752148,"data":{"s":"BTCUSDT","b":[],"a":[["77373.60","0"],["77374.00","0.188"]],"u":101055008,"seq":800573234573},"cts":1787954752147}
{"topic":"orderbook.50.BTCUSDT","type":"delta","ts":1787954752288,"data":{"s":"BTCUSDT","b":[],"a":[["77372.80","0.002"],["77374.00","0"]],"u":101055009,"seq":800573234668},"cts":1787954752286}
{"topic":"orderbook.50.BTCUSDT","type":"delta","ts":1787954752389,"data":{"s":"BTCUSDT","b":[],"a":[["77367.90","0.008"],["77371.10","0"],["77373.60","0.002"]],"u":101055010,"seq":800573234768},"cts":1787954752386}
{"topic":"orderbook.50.BTCUSDT","type":"delta","ts":1787954752408,"data":{"s":"BTCUSDT","b":[["77356.50","0.518"]],"a":[],"u":101055011,"seq":800573234786},"cts":1787954752396}
{"topic":"orderbook.50.BTCUSDT","type":"delta","ts":1787954752428,"data":{"s":"BTCUSDT","b":[],"a":[["77372.80","0"],["77373.60","0"],["77374.00","0.188"],["77374.10","0.051"]],"u":101055012,"seq":800573234810},"cts":1787954752427}
{"topic":"orderbook.50.BTCUSDT","type":"delta","ts":1787954752448,"data":{"s":"BTCUSDT","b":[],"a":[["77373.60","0.002"],["77374.10","0"]],"u":101055013,"seq":800573234833},"cts":1787954752447}
{"topic":"orderbook.50.BTCUSDT","type":"delta","ts":1787954752488,"data":{"s":"BTCUSDT","b":[],"a":[["77373.60","0"],["77374.10","0.051"]],"u":101055014,"seq":800573234855},"cts":1787954752485}
{"topic":"orderbook.50.BTCUSDT","type":"delta","ts":1787954752549,"data":{"s":"BTCUSDT","b":[["77361.90","0.001"],["77355.20","0"]],"a":[],"u":101055015,"seq":800573234912},"cts":1787954752540}
{"topic":"orderbook.50.BTCUSDT","type":"delta","ts":1787954752568,"data":{"s":"BTCUSDT","b":[["77356.50","0.372"]],"a":[],"u":101055016,"seq":800573234937},"cts":1787954752564}
{"topic":"orderbook.50.BTCUSDT","type":"delta","ts":1787954752648,"data":{"s":"BTCUSDT","b":[["77364.60","3.663"],["77364.50","0.539"],["77362.80","0.002"],["77362.50","0"],["77362.00","0.003"],["77356.10","0.987"],["77355.20","0.013"]],"a":[["77370.90","0.002"],["77371.50","0.007"],["77373.00","0.004"],["77373.80","0.005"],["77374.10","0"]],"u":101055017,"seq":800573235074},"cts":1787954752646}
{"topic":"orderbook.50.BTCUSDT","type":"delta","ts":1787954752669,"data":{"s":"BTCUSDT","b":[["77364.60","1.443"],["77364.50","0.002"],["77363.80","0"],["77361.80","0.036"],["77361.50","0.002"],["77361.20","0"],["77361.00","0.003"],["77360.50","0"],["77360.40","0.373"],["77359.60","0.371"],["77357.10","0"],["77356.00","0.002"],["77355.10","0.001"],["77355.00","0.015"],["77354.90","0.001"],["77354.80","0.004"]],"a":[["77364.70","9.518"],["77365.60","0.003"],["77366.10","0.002"],["77367.00","0.012"],["77367.50","0.008"],["77367.90","4.188"],["77370.90","0"],["77371.50","0.005"],["77373.00","0.002"],["77373.30","0.072"],["77373.80","0.003"],["77374.00","0"]],"u":101055018,"seq":800573235461},"cts":1787954752667}
{"topic":"orderbook.50.BTCUSDT","type":"delta","ts":1787954752688,"data":{"s":"BTCUSDT","b":[["77362.50","0.370"],["77361.90","0"],["77359.70","0.370"],["77356.10","0.450"],["77355.00","0.013"]],"a":[["77372.10","0.703"]],"u":101055019,"seq":800573235566},"cts":1787954752686}
{"topic":"orderbook.50.BTCUSDT","type":"delta","ts":1787954752708,"data":{"s":"BTCUSDT","b":[["77354.80","1.940"]],"a":[["77368.80","0.001"],["77373.80","0"]],"u":101055020,"seq":800573235656},"cts":1787954752706}
{"topic":"orderbook.50.BTCUSDT","type":"delta","ts":1787954752728,"data":{"s":"BTCUSDT","b":[["77356.50","0.518"],["77356.10","0.970"],["77356.00","0.001"]],"a":[],"u":101055021,"seq":800573235693},"cts":1787954752724}
{"topic":"orderbook.50.BTCUSDT","type":"delta","ts":1787954752748,"data":{"s":"BTCUSDT","b":[["77364.60","1.429"],["77364.30","0.310"],["77356.60","0.136"],["77354.80","0"]],"a":[["77371.50","0.006"]],"u":101055022,"seq":800573235748},"cts":1787954752747}
{"topic":"orderbook.50.BTCUSDT","type":"delta","ts":1787954752768,"data":{"s":"BTCUSDT","b":[["77356.60","0.001"],["77355.10","0.003"]],"a":[],"u":101055023,"seq":800573235817},"cts":1787954752764}
{"topic":"orderbook.50.BTCUSDT","type":"delta","ts":1787954752808,"data":{"s":"BTCUSDT","b":[["77364.60","1.443"],["77355.70","0.008"]],"a":[],"u":101055024,"seq":800573235873},"cts":1787954752807}
{"topic":"orderbook.50.BTCUSDT","type":"delta","ts":1787954752848,"data":{"s":"BTCUSDT","b":[["77356.60","0.003"]],"a":[],"u":101055025,"seq":800573235920},"cts":1787954752842}
{"topic":"orderbook.50.BTCUSDT","type":"delta","ts":1787954752868,"data":{"s":"BTCUSDT","b":[],"a":[["77364.70","9.583"]],"u":101055026,"seq":800573235970},"cts":1787954752866}
{"topic":"orderbook.50.BTCUSDT","type":"delta","ts":1787954752889,"data":{"s":"BTCUSDT","b":[["77364.60","1.453"]],"a":[],"u":101055027,"seq":800573235989},"cts":1787954752882}
{"topic":"orderbook.50.BTCUSDT","type":"delta","ts":1787954752909,"data":{"s":"BTCUSDT","b":[],"a":[["77368.00","14.003"],["77368.10","0"],["77373.80","0.003"]],"u":101055028,"seq":800573236020},"cts":1787954752907}
{"topic":"orderbook.50.BTCUSDT","type":"delta","ts":1787954752988,"data":{"s":"BTCUSDT","b":[["77364.60","1.561"],["77358.10","0.002"],["77357.30","0.003"],["77354.90","0"]],"a":[],"u":101055029,"seq":800573236190},"cts":1787954752985}
{"topic":"orderbook.50.BTCUSDT","type":"delta","ts":1787954753069,"data":{"s":"BTCUSDT","b":[["77359.60","0.373"],["77359.10","0.002"],["77358.60","0.082"],["77356.60","0.001"],["77355.70","0.006"],["77355.10","0.001"],["77355.00","0"]],"a":[["77364.70","9.581"]],"u":101055030,"seq":800573236375},"cts":1787954753060}
{"topic":"orderbook.50.BTCUSDT","type":"delta","ts":1787954753108,"data":{"s":"BTCUSDT","b":[["77360.50","0.002"],["77357.30","0.001"],["77355.10","0"]],"a":[["77365.60","0.001"],["77368.00","14.005"]],"u":101055031,"seq":800573236433},"cts":1787954753106}
{"topic":"orderbook.50.BTCUSDT","type":"delta","ts":1787954753128,"data":{"s":"BTCUSDT","b":[["77364.60","2.273"],["77362.20","0.002"],["77361.50","0.004"],["77359.40","0.306"],["77358.60","0.080"],["77358.10","0"]],"a":[["77366.10","0"],["77367.00","0.010"],["77367.50","0.006"],["77368.50","0.004"],["77368.90","0.058"],["77369.40","0.002"]],"u":101055032,"seq":800573236519},"cts":1787954753127}
{"topic":"orderbook.50.BTCUSDT","type":"delta","ts":1787954753208,"data":{"s":"BTCUSDT","b":[["77356.50","0.372"]],"a":[],"u":101055033,"seq":800573236587},"cts":1787954753206}
{"topic":"orderbook.50.BTCUSDT","type":"delta","ts":1787954753228,"data":{"s":"BTCUSDT","b":[["77362.70","0.002"],["77359.10","0"]],"a":[["77368.00","14.003"],["77369.90","0.002"],["77373.80","0"]],"u":101055034,"seq":800573236626},"cts":1787954753220}
{"topic":"orderbook.50.BTCUSDT","type":"delta","ts":1787954753348,"data":{"s":"BTCUSDT","b":[["77362.70","0"],["77362.20","0"],["77355.10","0.001"],["77355.00","0.013"]],"a":[["77367.30","0.004"]],"u":101055035,"seq":800573236707},"cts":1787954753347}
{"topic":"orderbook.50.BTCUSDT","type":"delta","ts":1787954753369,"data":{"s":"BTCUSDT","b":[["77361.00","0.005"]],"a":[],"u":101055036,"seq":800573236749},"cts":1787954753367}
{"topic":"orderbook.50.BTCUSDT","type":"delta","ts":1787954753408,"data":{"s":"BTCUSDT","b":[["77362.30","0.012"]],"a":[["77367.30","0.002"],["77367.90","4.190"]],"u":101055037,"seq":800573236809},"cts":1787954753405}
{"topic":"orderbook.50.BTCUSDT","type":"delta","ts":1787954753508,"data":{"s":"BTCUSDT","b":[["77362.30","0.010"]],"a":[["77367.40","0.005"],["77369.90","0"],["77373.80","0.003"]],"u":101055038,"seq":800573236910},"cts":1787954753505}
{"topic":"orderbook.50.BTCUSDT","type":"delta","ts":1787954753528,"data":{"s":"BTCUSDT","b":[],"a":[["77367.30","0.004"],["77367.40","0.003"]],"u":101055039,"seq":800573236988},"cts":1787954753526}
{"topic":"orderbook.50.BTCUSDT","type":"delta","ts":1787954753588,"data":{"s":"BTCUSDT","b":[["77361.50","0.002"]],"a":[["77366.40","0.005"],["77369.40","0"],["77374.00","0.188"]],"u":101055040,"seq":800573237024},"cts":1787954753587}
{"topic":"orderbook.50.BTCUSDT","type":"delta","ts":1787954753608,"data":{"s":"BTCUSDT","b":[["77361.50","0.004"],["77359.10","0.002"],["77355.70","0"]],"a":[["77366.40","0.003"]],"u":101055041,"seq":800573237068},"cts":1787954753606}
{"topic":"orderbook.50.BTCUSDT","type":"delta","ts":1787954753648,"data":{"s":"BTCUSDT","b":[["77364.60","2.259"],["77361.50","0.002"]],"a":[["77366.60","0.004"]],"u":101055042,"seq":800573237112},"cts":1787954753647}
{"topic":"orderbook.50.BTCUSDT","type":"delta","ts":1787954753709,"data":{"s":"BTCUSDT","b":[],"a":[["77366.60","0.002"],["77366.80","0.003"]],"u":101055043,"seq":800573237178},"cts":1787954753706}
{"topic":"orderbook.50.BTCUSDT","type":"delta","ts":1787954753748,"data":{"s":"BTCUSDT","b":[["77361.80","0.038"]],"a":[["77366.80","0.001"],["77367.30","0.002"],["77369.40","0.002"],["77374.00","0"]],"u":101055044,"seq":800573237216},"cts":1787954753745}
{"topic":"orderbook.50.BTCUSDT","type":"delta","ts":1787954753768,"data":{"s":"BTCUSDT","b":[["77362.50","0.372"],["77361.70","0.001"],["77359.10","0"]],"a":[["77367.90","4.188"],["77369.90","0.002"],["77373.80","0"]],"u":101055045,"seq":800573237261},"cts":1787954753767}
{"topic":"orderbook.50.BTCUSDT","type":"delta","ts":1787954753889,"data":{"s":"BTCUSDT","b":[["77361.70","0"],["77354.90","0.001"]],"a":[],"u":101055046,"seq":800573237355},"cts":1787954753886}
{"topic":"orderbook.50.BTCUSDT","type":"delta","ts":1787954754149,"data":{"s":"BTCUSDT","b":[["77362.30","0.016"]],"a":[],"u":101055047,"seq":800573237531},"cts":1787954754144}
{"topic":"orderbook.50.BTCUSDT","type":"delta","ts":1787954754168,"data":{"s":"BTCUSDT","b":[],"a":[["77367.90","4.190"]],"u":101055048,"seq":800573237572},"cts":1787954754167}
{"topic":"orderbook.50.BTCUSDT","type":"delta","ts":1787954754228,"data":{"s":"BTCUSDT","b":[["77364.60","2.783"],["77363.10","0.002"],["77359.60","0.371"],["77354.90","0"]],"a":[["77367.90","4.188"]],"u":101055049,"seq":800573237672},"cts":1787954754220}
{"topic":"orderbook.50.BTCUSDT","type":"delta","ts":1787954754268,"data":{"s":"BTCUSDT","b":[],"a":[["77368.50","0.002"],["77370.40","0.002"],["77373.70","0"]],"u":101055050,"seq":800573237708},"cts":1787954754266}
{"topic":"orderbook.50.BTCUSDT","type":"delta","ts":1787954754448,"data":{"s":"BTCUSDT","b":[],"a":[["77364.70","9.535"]],"u":101055051,"seq":800573237819},"cts":1787954754445}
{"topic":"orderbook.50.BTCUSDT","type":"delta","ts":1787954754468,"data":{"s":"BTCUSDT","b":[["77364.60","2.798"],["77364.50","0.004"],["77360.50","0"],["77354.90","0.001"]],"a":[["77368.90","0.056"],["77369.40","0"],["77369.90","0"],["77370.90","0.002"],["77371.40","0.005"],["77371.90","0.002"]],"u":101055052,"seq":800573237862},"cts":1787954754463}
{"topic":"orderbook.50.BTCUSDT","type":"delta","ts":1787954754488,"data":{"s":"BTCUSDT","b":[],"a":[["77370.40","0"],["77372.30","0.004"],["77373.70","0.007"]],"u":101055053,"seq":800573237878},"cts":1787954754485}
{"topic":"orderbook.50.BTCUSDT","type":"delta","ts":1787954754508,"data":{"s":"BTCUSDT","b":[["77356.80","0.049"],["77354.90","0"],["77354.80","1.940"]],"a":[],"u":101055054,"seq":800573237903},"cts":1787954754503}
{"topic":"orderbook.50.BTCUSDT","type":"delta","ts":1787954754528,"data":{"s":"BTCUSDT","b":[["77364.00","0.003"],["77361.00","0.003"],["77356.60","0.136"]],"a":[["77370.30","0.003"]],"u":101055055,"seq":800573237958},"cts":1787954754527}
{"topic":"orderbook.50.BTCUSDT","type":"delta","ts":1787954754569,"data":{"s":"BTCUSDT","b":[["77363.80","0.006"],["77363.30","0.007"],["77360.70","0.002"],["77355.10","0"],["77355.00","0"],["77354.80","0"]],"a":[],"u":101055056,"seq":800573238010},"cts":1787954754561}
{"topic":"orderbook.50.BTCUSDT","type":"delta","ts":1787954754588,"data":{"s":"BTCUSDT","b":[["77357.90","0.001"],["77356.60","0.001"]],"a":[],"u":101055057,"seq":800573238040},"cts":1787954754579}
{"topic":"orderbook.50.BTCUSDT","type":"delta","ts":1787954754649,"data":{"s":"BTCUSDT","b":[["77356.60","0.136"]],"a":[],"u":101055058,"seq":800573238093},"cts":1787954754643}
{"topic":"orderbook.50.BTCUSDT","type":"delta","ts":1787954754688,"data":{"s":"BTCUSDT","b":[],"a":[["77370.30","0.001"]],"u":101055059,"seq":800573238134},"cts":1787954754687}
{"topic":"orderbook.50.BTCUSDT","type":"delta","ts":1787954754708,"data":{"s":"BTCUSDT","b":[],"a":[["77370.90","0"],["77372.80","0.002"]],"u":101055060,"seq":800573238172},"cts":1787954754705}
{"topic":"orderbook.50.BTCUSDT","type":"delta","ts":1787954754748,"data":{"s":"BTCUSDT","b":[["77364.60","2.863"]],"a":[["77364.70","8.242"],["77371.40","0.003"],["77371.90","0"],["77372.30","0.002"],["77372.80","0"],["77373.80","0.003"],["77374.00","0.188"]],"u":101055061,"seq":800573238220},"cts":1787954754747}
{"topic":"orderbook.50.BTCUSDT","type":"delta","ts":1787954754768,"data":{"s":"BTCUSDT","b":[["77364.00","0.002"]],"a":[],"u":101055062,"seq":800573238249},"cts":1787954754757}
{"topic":"orderbook.50.BTCUSDT","type":"delta","ts":1787954754829,"data":{"s":"BTCUSDT","b":[],"a":[["77368.00","14.001"],["77368.10","0.002"],["77371.50","0.005"],["77372.20","0.001"],["77373.80","0"],["77374.00","0"]],"u":101055063,"seq":800573238308},"cts":1787954754825}
{"topic":"orderbook.50.BTCUSDT","type":"delta","ts":1787954754849,"data":{"s":"BTCUSDT","b":[],"a":[["77364.70","8.177"]],"u":101055064,"seq":800573238353},"cts":1787954754844}
{"topic":"orderbook.50.BTCUSDT","type":"delta","ts":1787954754888,"data":{"s":"BTCUSDT","b":[["77361.70","0.001"],["77355.20","0"]],"a":[],"u":101055065,"seq":800573238374},"cts":1787954754883}
{"topic":"orderbook.50.BTCUSDT","type":"delta","ts":1787954754928,"data":{"s":"BTCUSDT","b":[["77364.60","2.798"]],"a":[],"u":101055066,"seq":800573238460},"cts":1787954754921}
{"topic":"orderbook.50.BTCUSDT","type":"delta","ts":1787954754988,"data":{"s":"BTCUSDT","b":[],"a":[["77373.50","0.002"],["77373.70","0"]],"u":101055067,"seq":800573238506},"cts":1787954754985}
{"topic":"orderbook.50.BTCUSDT","type":"delta","ts":1787954755049,"data":{"s":"BTCUSDT","b":[["77361.70","0"],["77355.20","0.013"]],"a":[],"u":101055068,"seq":800573238576},"cts":1787954755045}
{"topic":"orderbook.50.BTCUSDT","type":"delta","ts":1787954755148,"data":{"s":"BTCUSDT","b":[],"a":[["77372.70","0.002"],["77373.50","0"]],"u":101055069,"seq":800573238682},"cts":1787954755147}
{"topic":"orderbook.50.BTCUSDT","type":"delta","ts":1787954755188,"data":{"s":"BTCUSDT","b":[],"a":[["77372.50","0.002"],["77372.70","0"]],"u":101055070,"seq":800573238725},"cts":1787954755185}
{"topic":"orderbook.50.BTCUSDT","type":"delta","ts":1787954755289,"data":{"s":"BTCUSDT","b":[],"a":[["77364.70","8.167"],["77371.60","0.033"]],"u":101055071,"seq":800573238831},"cts":1787954755286}
{"topic":"orderbook.50.BTCUSDT","type":"delta","ts":1787954755389,"data":{"s":"BTCUSDT","b":[],"a":[["77371.10","0.002"],["77373.30","0"]],"u":101055072,"seq":800573238894},"cts":1787954755385}
{"topic":"orderbook.50.BTCUSDT","type":"delta","ts":1787954755688,"data":{"s":"BTCUSDT","b":[["77364.50","0.002"],["77364.00","0"],["77363.10","0"],["77361.40","0.002"],["77360.90","0.002"]],"a":[["77366.90","0.002"],["77367.90","4.190"],["77373.10","0"]],"u":101055073,"seq":800573239108},"cts":1787954755686}
{"topic":"orderbook.50.BTCUSDT","type":"delta","ts":1787954755709,"data":{"s":"BTCUSDT","b":[["77364.10","0.002"],["77355.20","0"]],"a":[["77366.90","0"],["77367.90","4.188"],["77371.10","0"],["77371.60","0.031"],["77373.00","0.004"],["77373.10","0.005"],["77373.30","0.072"]],"u":101055074,"seq":800573239165},"cts":1787954755708}
{"topic":"orderbook.50.BTCUSDT","type":"delta","ts":1787954755828,"data":{"s":"BTCUSDT","b":[],"a":[["77364.70","8.232"],["77370.80","0.012"]],"u":101055075,"seq":800573239277},"cts":1787954755825}
{"topic":"orderbook.50.BTCUSDT","type":"delta","ts":1787954756048,"data":{"s":"BTCUSDT","b":[["77362.00","0.004"]],"a":[],"u":101055076,"seq":800573239423},"cts":1787954756046}
{"topic":"orderbook.50.BTCUSDT","type":"delta","ts":1787954756068,"data":{"s":"BTCUSDT","b":[],"a":[["77370.80","0.010"],["77371.00","0.033"]],"u":101055077,"seq":800573239465},"cts":1787954756067}
{"topic":"orderbook.50.BTCUSDT","type":"delta","ts":1787954756208,"data":{"s":"BTCUSDT","b":[["77362.00","0.003"]],"a":[],"u":101055078,"seq":800573239595},"cts":1787954756205}
{"topic":"orderbook.50.BTCUSDT","type":"delta","ts":1787954756288,"data":{"s":"BTCUSDT","b":[],"a":[["77371.00","0.031"],["77371.50","0.007"]],"u":101055079,"seq":800573239662},"cts":1787954756286}
{"topic":"orderbook.50.BTCUSDT","type":"delta","ts":1787954756348,"data":{"s":"BTCUSDT","b":[],"a":[["77370.80","0.012"]],"u":101055080,"seq":800573239714},"cts":1787954756344}
{"topic":"orderbook.50.BTCUSDT","type":"delta","ts":1787954756408,"data":{"s":"BTCUSDT","b":[],"a":[["77370.80","0.010"]],"u":101055081,"seq":800573239747},"cts":1787954756404}
{"topic":"orderbook.50.BTCUSDT","type":"delta","ts":1787954756429,"data":{"s":"BTCUSDT","b":[],"a":[["77370.30","0.003"],["77370.80","0.012"]],"u":101055082,"seq":800573239790},"cts":1787954756427}
{"topic":"orderbook.50.BTCUSDT","type":"delta","ts":1787954756488,"data":{"s":"BTCUSDT","b":[],"a":[["77370.30","0.001"]],"u":101055083,"seq":800573239820},"cts":1787954756484}
{"topic":"orderbook.50.BTCUSDT","type":"delta","ts":1787954756568,"data":{"s":"BTCUSDT","b":[],"a":[["77370.80","0.010"],["77371.90","0.002"],["77373.30","0"]],"u":101055084,"seq":800573239877},"cts":1787954756562}
{"topic":"orderbook.50.BTCUSDT","type":"delta","ts":1787954756609,"data":{"s":"BTCUSDT","b":[],"a":[["77371.50","0.005"]],"u":101055085,"seq":800573239910},"cts":1787954756607}
{"topic":"orderbook.50.BTCUSDT","type":"delta","ts":1787954756748,"data":{"s":"BTCUSDT","b":[],"a":[["77364.70","8.135"],["77371.90","0"],["77372.50","0"],["77373.30","0.072"],["77373.40","0.002"]],"u":101055086,"seq":800573240059},"cts":1787954756745}
{"topic":"orderbook.50.BTCUSDT","type":"delta","ts":1787954756828,"data":{"s":"BTCUSDT","b":[],"a":[["77364.70","8.070"],["77373.00","0.002"]],"u":101055087,"seq":800573240133},"cts":1787954756827}
{"topic":"orderbook.50.BTCUSDT","type":"delta","ts":1787954756889,"data":{"s":"BTCUSDT","b":[],"a":[["77371.90","0.002"],["77372.80","0.002"],["77373.30","0"],["77373.40","0"]],"u":101055088,"seq":800573240180},"cts":1787954756885}
{"topic":"orderbook.50.BTCUSDT","type":"delta","ts":1787954756908,"data":{"s":"BTCUSDT","b":[],"a":[["77371.90","0"],["77373.30","0.072"]],"u":101055089,"seq":800573240210},"cts":1787954756906}
{"topic":"orderbook.50.BTCUSDT","type":"delta","ts":1787954757029,"data":{"s":"BTCUSDT","b":[],"a":[["77372.20","0.003"]],"u":101055090,"seq":800573240290},"cts":1787954757022}
{"topic":"orderbook.50.BTCUSDT","type":"delta","ts":1787954757129,"data":{"s":"BTCUSDT","b":[],"a":[["77371.50","0.007"]],"u":101055091,"seq":800573240359},"cts":1787954757123}
{"topic":"orderbook.50.BTCUSDT","type":"delta","ts":1787954757209,"data":{"s":"BTCUSDT","b":[["77364.60","2.799"]],"a":[],"u":101055092,"seq":800573240437},"cts":1787954757206}
{"topic":"orderbook.50.BTCUSDT","type":"delta","ts":1787954757228,"data":{"s":"BTCUSDT","b":[["77359.40","0.302"]],"a":[],"u":101055093,"seq":800573240454},"cts":1787954757220}
{"topic":"orderbook.50.BTCUSDT","type":"delta","ts":1787954757308,"data":{"s":"BTCUSDT","b":[["77364.60","2.798"]],"a":[["77370.70","0.002"],["77373.30","0"]],"u":101055094,"seq":800573240521},"cts":1787954757306}
{"topic":"orderbook.50.BTCUSDT","type":"delta","ts":1787954757449,"data":{"s":"BTCUSDT","b":[],"a":[["77370.70","0"],["77373.30","0.072"]],"u":101055095,"seq":800573240634},"cts":1787954757440}
{"topic":"orderbook.50.BTCUSDT","type":"delta","ts":1787954757648,"data":{"s":"BTCUSDT","b":[],"a":[["77371.00","0.033"]],"u":101055096,"seq":800573240754},"cts":1787954757647}
{"topic":"orderbook.50.BTCUSDT","type":"delta","ts":1787954757669,"data":{"s":"BTCUSDT","b":[["77364.60","2.802"]],"a":[],"u":101055097,"seq":800573240770},"cts":1787954757663}
{"topic":"orderbook.50.BTCUSDT","type":"delta","ts":1787954757708,"data":{"s":"BTCUSDT","b":[],"a":[["77371.00","0.031"]],"u":101055098,"seq":800573240806},"cts":1787954757706}
{"topic":"orderbook.50.BTCUSDT","type":"delta","ts":1787954757808,"data":{"s":"BTCUSDT","b":[],"a":[["77364.70","8.135"],["77370.00","0.007"]],"u":101055099,"seq":800573240903},"cts":1787954757806}
{"topic":"orderbook.50.BTCUSDT","type":"delta","ts":1787954758068,"data":{"s":"BTCUSDT","b":[["77364.60","1.687"],["77364.20","0"],["77364.10","0"],["77362.50","0"],["77361.80","0.036"],["77361.40","0"],["77360.90","0"],["77360.50","0.320"],["77360.40","0.003"],["77359.60","0.001"],["77358.30","0.370"],["77357.40","0.002"],["77356.90","0.011"],["77356.70","0.006"],["77356.60","0.001"],["77356.40","0.399"],["77355.90","0.002"]],"a":[["77364.70","8.137"],["77367.80","0.370"],["77367.90","4.190"],["77371.10","0.129"],["77372.10","0.707"],["77372.80","0"],["77373.30","0"]],"u":101055100,"seq":800573241300},"cts":1787954758066}
{"topic":"orderbook.50.BTCUSDT","type":"delta","ts":1787954758089,"data":{"s":"BTCUSDT","b":[["77364.30","0.124"],["77357.40","0"],["77356.90","0.009"],["77356.40","0.397"],["77355.50","0.004"],["77355.20","0.013"]],"a":[],"u":101055101,"seq":800573241397},"cts":1787954758086}
{"topic":"orderbook.50.BTCUSDT","type":"delta","ts":1787954758109,"data":{"s":"BTCUSDT","b":[["77362.50","0.370"],["77355.20","0"]],"a":[["77367.80","0"],["77373.30","0.072"]],"u":101055102,"seq":800573241433},"cts":1787954758104}
{"topic":"orderbook.50.BTCUSDT","type":"delta","ts":1787954758128,"data":{"s":"BTCUSDT","b":[["77364.30","0.218"],["77357.40","0.002"],["77356.80","0.051"],["77355.30","0"]],"a":[["77372.10","0.703"],["77372.20","0.007"]],"u":101055103,"seq":800573241518},"cts":1787954758126}
{"topic":"orderbook.50.BTCUSDT","type":"delta","ts":1787954758148,"data":{"s":"BTCUSDT","b":[],"a":[["77371.50","0.008"],["77372.20","0.006"]],"u":101055104,"seq":800573241550},"cts":1787954758141}
{"topic":"orderbook.50.BTCUSDT","type":"delta","ts":1787954758168,"data":{"s":"BTCUSDT","b":[],"a":[["77372.10","0.707"],["77372.20","0.002"]],"u":101055105,"seq":800573241579},"cts":1787954758162}
{"topic":"orderbook.50.BTCUSDT","type":"delta","ts":1787954758188,"data":{"s":"BTCUSDT","b":[["77358.30","0.372"]],"a":[["77371.50","0.007"],["77372.90","0.257"]],"u":101055106,"seq":800573241628},"cts":1787954758186}
{"topic":"orderbook.50.BTCUSDT","type":"delta","ts":1787954758208,"data":{"s":"BTCUSDT","b":[],"a":[["77372.00","0.004"],["77372.10","0.703"],["77373.30","0"]],"u":101055107,"seq":800573241659},"cts":1787954758205}
{"topic":"orderbook.50.BTCUSDT","type":"delta","ts":1787954758228,"data":{"s":"BTCUSDT","b":[],"a":[["77371.10","0.384"]],"u":101055108,"seq":800573241680},"cts":1787954758227}
{"topic":"orderbook.50.BTCUSDT","type":"delta","ts":1787954758248,"data":{"s":"BTCUSDT","b":[],"a":[["77371.00","0.160"],["77371.10","0.255"]],"u":101055109,"seq":800573241710},"cts":1787954758247}
{"topic":"orderbook.50.BTCUSDT","type":"delta","ts":1787954758268,"data":{"s":"BTCUSDT","b":[],"a":[["77372.20","0.003"]],"u":101055110,"seq":800573241733},"cts":1787954758266}
{"topic":"orderbook.50.BTCUSDT","type":"delta","ts":1787954758309,"data":{"s":"BTCUSDT","b":[],"a":[["77371.70","0.001"],["77372.20","0.002"],["77373.10","0"]],"u":101055111,"seq":800573241769},"cts":1787954758307}
{"topic":"orderbook.50.BTCUSDT","type":"delta","ts":1787954758329,"data":{"s":"BTCUSDT","b":[["77358.80","0.002"]],"a":[],"u":101055112,"seq":800573241793},"cts":1787954758325}
{"topic":"orderbook.50.BTCUSDT","type":"delta","ts":1787954758348,"data":{"s":"BTCUSDT","b":[],"a":[["77371.00","0.031"],["77371.10","0.384"]],"u":101055113,"seq":800573241823},"cts":1787954758346}
{"topic":"orderbook.50.BTCUSDT","type":"delta","ts":1787954758369,"data":{"s":"BTCUSDT","b":[["77364.60","1.569"],["77362.50","0"],["77360.50","0"],["77360.40","0"],["77358.30","0.370"],["77355.30","0.002"],["77355.20","0.013"],["77355.10","0.001"]],"a":[["77366.80","0.371"],["77367.80","0.363"],["77371.00","0.160"],["77371.10","0.255"],["77371.20","4.293"],["77372.00","0"]],"u":101055114,"seq":800573241988},"cts":1787954758367}
{"topic":"orderbook.50.BTCUSDT","type":"delta","ts":1787954758388,"data":{"s":"BTCUSDT","b":[["77364.30","0.027"],["77359.40","0.297"],["77357.40","0"],["77356.80","0.049"],["77355.90","0"],["77355.30","0.005"],["77355.00","0.015"],["77354.80","1.940"]],"a":[["77371.20","4.289"],["77371.30","14.005"]],"u":101055115,"seq":800573242086},"cts":1787954758387}
{"topic":"orderbook.50.BTCUSDT","type":"delta","ts":1787954758408,"data":{"s":"BTCUSDT","b":[["77355.50","0.002"],["77355.00","0.013"]],"a":[["77364.70","8.209"]],"u":101055116,"seq":800573242134},"cts":1787954758407}
{"topic":"orderbook.50.BTCUSDT","type":"delta","ts":1787954758428,"data":{"s":"BTCUSDT","b":[["77358.80","0.001"]],"a":[],"u":101055117,"seq":800573242187},"cts":1787954758427}
{"topic":"orderbook.50.BTCUSDT","type":"delta","ts":1787954758448,"data":{"s":"BTCUSDT","b":[],"a":[["77368.00","14.003"],["77368.10","0"],["77371.50","0.008"],["77371.70","0"],["77373.10","0.005"],["77373.70","0.007"]],"u":101055118,"seq":800573242230},"cts":1787954758445}
{"topic":"orderbook.50.BTCUSDT","type":"delta","ts":1787954758488,"data":{"s":"BTCUSDT","b":[["77354.90","0.129"],["77354.80","0"]],"a":[],"u":101055119,"seq":800573242285},"cts":1787954758486}
{"topic":"orderbook.50.BTCUSDT","type":"delta","ts":1787954758508,"data":{"s":"BTCUSDT","b":[["77356.70","0"],["77354.90","0"],["77354.80","1.940"],["77354.50","0.002"]],"a":[["77371.30","14.001"],["77371.40","0.007"]],"u":101055120,"seq":800573242330},"cts":1787954758505}
{"topic":"orderbook.50.BTCUSDT","type":"delta","ts":1787954758529,"data":{"s":"BTCUSDT","b":[["77356.60","0.007"],["77354.90","0.129"],["77354.50","0"]],"a":[],"u":101055121,"seq":800573242356},"cts":1787954758523}
{"topic":"orderbook.50.BTCUSDT","type":"delta","ts":1787954758549,"data":{"s":"BTCUSDT","b":[["77354.90","0"],["77354.50","0.002"]],"a":[],"u":101055122,"seq":800573242381},"cts":1787954758538}
{"topic":"orderbook.50.BTCUSDT","type":"delta","ts":1787954758688,"data":{"s":"BTCUSDT","b":[["77364.60","1.399"]],"a":[],"u":101055123,"seq":800573242611},"cts":1787954758687}
{"topic":"orderbook.50.BTCUSDT","type":"delta","ts":1787954758708,"data":{"s":"BTCUSDT","b":[["77364.60","1.318"],["77354.50","0"],["77354.40","0.002"]],"a":[["77364.70","9.051"]],"u":101055124,"seq":800573242714},"cts":1787954758704}
{"topic":"orderbook.50.BTCUSDT","type":"delta","ts":1787954758728,"data":{"s":"BTCUSDT","b":[["77355.20","0.015"]],"a":[],"u":101055125,"seq":800573242738},"cts":1787954758715}
{"topic":"orderbook.50.BTCUSDT","type":"delta","ts":1787954758768,"data":{"s":"BTCUSDT","b":[["77355.80","0.247"]],"a":[],"u":101055126,"seq":800573242802},"cts":1787954758758}
{"topic":"orderbook.50.BTCUSDT","type":"delta","ts":1787954758788,"data":{"s":"BTCUSDT","b":[],"a":[["77371.40","0.003"],["77371.50","0.012"]],"u":101055127,"seq":800573242829},"cts":1787954758787}
{"topic":"orderbook.50.BTCUSDT","type":"delta","ts":1787954758808,"data":{"s":"BTCUSDT","b":[],"a":[["77366.40","0.004"]],"u":101055128,"seq":800573242877},"cts":1787954758807}
{"topic":"orderbook.50.BTCUSDT","type":"delta","ts":1787954758829,"data":{"s":"BTCUSDT","b":[["77364.60","1.323"],["77359.40","0.292"]],"a":[],"u":101055129,"seq":800573242906},"cts":1787954758824}
{"topic":"orderbook.50.BTCUSDT","type":"delta","ts":1787954758869,"data":{"s":"BTCUSDT","b":[["77355.80","0.245"],["77355.20","0.013"]],"a":[],"u":101055130,"seq":800573242956},"cts":1787954758866}
{"topic":"orderbook.50.BTCUSDT","type":"delta","ts":1787954758888,"data":{"s":"BTCUSDT","b":[],"a":[["77371.40","0.007"],["77371.50","0.008"]],"u":101055131,"seq":800573242981},"cts":1787954758887}
{"topic":"orderbook.50.BTCUSDT","type":"delta","ts":1787954758929,"data":{"s":"BTCUSDT","b":[["77360.40","0.370"],["77354.40","0"]],"a":[],"u":101055132,"seq":800573243058},"cts":1787954758925}
{"topic":"orderbook.50.BTCUSDT","type":"delta","ts":1787954758948,"data":{"s":"BTCUSDT","b":[["77364.60","1.324"],["77364.30","0.134"],["77359.40","0.291"],["77356.80","0.051"],["77355.50","0.004"],["77355.00","0.015"]],"a":[["77364.70","8.209"]],"u":101055133,"seq":800573243123},"cts":1787954758944}
{"topic":"orderbook.50.BTCUSDT","type":"delta","ts":1787954758968,"data":{"s":"BTCUSDT","b":[["77364.60","0.425"],["77356.80","0.049"],["77356.40","0.399"],["77354.90","0.129"],["77354.80","0"]],"a":[["77371.30","14.005"],["77371.40","0.003"]],"u":101055134,"seq":800573243839},"cts":1787954758967}
{"topic":"orderbook.50.BTCUSDT","type":"delta","ts":1787954758988,"data":{"s":"BTCUSDT","b":[["77356.60","0.001"],["77354.90","0"],["77354.80","1.940"]],"a":[],"u":101055135,"seq":800573244732},"cts":1787954758985}
{"topic":"orderbook.50.BTCUSDT","type":"delta","ts":1787954759008,"data":{"s":"BTCUSDT","b":[["77356.60","0.007"],["77354.90","0.129"],["77354.80","0"]],"a":[],"u":101055136,"seq":800573245617},"cts":1787954759004}
{"topic":"orderbook.50.BTCUSDT","type":"delta","ts":1787954759028,"data":{"s":"BTCUSDT","b":[["77356.60","0.001"],["77356.40","0.397"],["77354.90","0"],["77354.80","1.940"]],"a":[["77364.70","9.051"]],"u":101055137,"seq":800573246710},"cts":1787954759024}
{"topic":"orderbook.50.BTCUSDT","type":"delta","ts":1787954759048,"data":{"s":"BTCUSDT","b":[["77356.60","0.007"],["77354.90","0.129"],["77354.80","0"]],"a":[],"u":101055138,"seq":800573247543},"cts":1787954759042}
{"topic":"orderbook.50.BTCUSDT","type":"delta","ts":1787954759068,"data":{"s":"BTCUSDT","b":[["77356.60","0.001"],["77354.90","0"],["77354.80","1.940"]],"a":[],"u":101055139,"seq":800573248515},"cts":1787954759062}
{"topic":"orderbook.50.BTCUSDT","type":"delta","ts":1787954759088,"data":{"s":"BTCUSDT","b":[["77356.60","0.007"],["77354.90","0.129"],["77354.80","0"]],"a":[],"u":101055140,"seq":800573249535},"cts":1787954759083}
{"topic":"orderbook.50.BTCUSDT","type":"delta","ts":1787954759108,"data":{"s":"BTCUSDT","b":[["77356.60","0.001"],["77354.90","0"],["77354.80","1.940"]],"a":[],"u":101055141,"seq":800573250554},"cts":1787954759105}
{"topic":"orderbook.50.BTCUSDT","type":"delta","ts":1787954759128,"data":{"s":"BTCUSDT","b":[["77364.60","0.435"],["77359.40","0.281"],["77356.60","0.007"],["77356.10","0.972"],["77354.90","0.129"],["77354.80","0"]],"a":[],"u":101055142,"seq":800573251553},"cts":1787954759125}
{"topic":"orderbook.50.BTCUSDT","type":"delta","ts":1787954759148,"data":{"s":"BTCUSDT","b":[["77356.60","0.001"],["77354.90","0"],["77354.80","1.940"]],"a":[],"u":101055143,"seq":800573252584},"cts":1787954759147}
{"topic":"orderbook.50.BTCUSDT","type":"delta","ts":1787954759168,"data":{"s":"BTCUSDT","b":[["77364.60","0.436"],["77356.60","0.007"],["77354.90","0.129"],["77354.80","0"]],"a":[],"u":101055144,"seq":800573253501},"cts":1787954759166}
{"topic":"orderbook.50.BTCUSDT","type":"delta","ts":1787954759188,"data":{"s":"BTCUSDT","b":[["77357.60","0.004"],["77356.60","0.001"],["77354.90","0"],["77354.80","1.940"]],"a":[["77364.70","8.209"],["77371.30","14.003"],["77371.40","0.005"]],"u":101055145,"seq":800573254552},"cts":1787954759186}
{"topic":"orderbook.50.BTCUSDT","type":"delta","ts":1787954759208,"data":{"s":"BTCUSDT","b":[["77358.60","0.082"],["77356.60","0.007"],["77354.90","0.129"],["77354.80","0"]],"a":[["77371.30","14.001"],["77371.40","0.007"]],"u":101055146,"seq":800573254770},"cts":1787954759207}
{"topic":"orderbook.50.BTCUSDT","type":"delta","ts":1787954759228,"data":{"s":"BTCUSDT","b":[["77356.60","0.001"],["77354.90","0"],["77354.80","1.940"]],"a":[],"u":101055147,"seq":800573254893},"cts":1787954759227}
{"topic":"orderbook.50.BTCUSDT","type":"delta","ts":1787954759248,"data":{"s":"BTCUSDT","b":[["77356.60","0.007"],["77354.90","0.129"],["77354.80","0"]],"a":[],"u":101055148,"seq":800573254960},"cts":1787954759240}
{"topic":"orderbook.50.BTCUSDT","type":"delta","ts":1787954759268,"data":{"s":"BTCUSDT","b":[["77356.60","0.001"],["77354.90","0"],["77354.80","1.940"]],"a":[],"u":101055149,"seq":800573255174},"cts":1787954759266}
{"topic":"orderbook.50.BTCUSDT","type":"delta","ts":1787954759288,"data":{"s":"BTCUSDT","b":[["77356.60","0.007"],["77354.90","0.129"],["77354.80","0"]],"a":[],"u":101055150,"seq":800573255293},"cts":1787954759286}
{"topic":"orderbook.50.BTCUSDT","type":"delta","ts":1787954759308,"data":{"s":"BTCUSDT","b":[["77356.60","0.001"],["77354.90","0"],["77354.80","1.940"]],"a":[],"u":101055151,"seq":800573255392},"cts":1787954759307}
{"topic":"orderbook.50.BTCUSDT","type":"delta","ts":1787954759328,"data":{"s":"BTCUSDT","b":[["77359.60","0.003"],["77356.60","0.007"],["77355.00","0.013"],["77354.90","0.129"],["77354.80","0"]],"a":[["77371.40","0.003"],["77371.70","0.004"],["77373.70","0"]],"u":101055152,"seq":800573255521},"cts":1787954759327}
{"topic":"orderbook.50.BTCUSDT","type":"delta","ts":1787954759349,"data":{"s":"BTCUSDT","b":[["77364.60","0.657"],["77361.30","0.002"],["77356.60","0.001"],["77355.50","0.002"],["77354.90","0"]],"a":[["77364.70","8.207"],["77365.40","0.002"],["77373.10","0"]],"u":101055153,"seq":800573255682},"cts":1787954759346}
{"topic":"orderbook.50.BTCUSDT","type":"delta","ts":1787954759368,"data":{"s":"BTCUSDT","b":[["77361.90","0.002"],["77356.10","0.970"],["77355.00","0"]],"a":[["77365.40","0"],["77366.10","0.002"],["77371.60","0.033"],["77371.70","0.002"]],"u":101055154,"seq":800573255823},"cts":1787954759364}
{"topic":"orderbook.50.BTCUSDT","type":"delta","ts":1787954759389,"data":{"s":"BTCUSDT","b":[["77364.60","0.678"]],"a":[],"u":101055155,"seq":800573255945},"cts":1787954759386}
{"topic":"orderbook.50.BTCUSDT","type":"delta","ts":1787954759408,"data":{"s":"BTCUSDT","b":[["77362.50","0.370"],["77355.10","0"]],"a":[["77366.80","0.001"]],"u":101055156,"seq":800573255984},"cts":1787954759406}
{"topic":"orderbook.50.BTCUSDT","type":"delta","ts":1787954759429,"data":{"s":"BTCUSDT","b":[["77364.30","0.232"],["77363.30","0.009"],["77357.60","0.002"]],"a":[["77366.10","0"],["77367.40","0.005"],["77371.60","0.031"],["77371.70","0.004"],["77373.10","0.005"]],"u":101055157,"seq":800573256128},"cts":1787954759425}
{"topic":"orderbook.50.BTCUSDT","type":"delta","ts":1787954759448,"data":{"s":"BTCUSDT","b":[["77363.30","0.007"],["77362.80","0.004"],["77358.60","0.083"]],"a":[["77371.60","0.035"],["77371.70","0"],["77373.70","0.007"]],"u":101055158,"seq":800573256271},"cts":1787954759447}
{"topic":"orderbook.50.BTCUSDT","type":"delta","ts":1787954759468,"data":{"s":"BTCUSDT","b":[],"a":[["77371.60","0.031"],["77371.70","0.004"],["77373.70","0"]],"u":101055159,"seq":800573256313},"cts":1787954759464}
{"topic":"orderbook.50.BTCUSDT","type":"delta","ts":1787954759488,"data":{"s":"BTCUSDT","b":[],"a":[["77368.00","14.001"],["77368.10","0.002"],["77373.10","0"]],"u":101055160,"seq":800573256377},"cts":1787954759484}
{"topic":"orderbook.50.BTCUSDT","type":"delta","ts":1787954759508,"data":{"s":"BTCUSDT","b":[],"a":[["77371.50","0.010"],["77371.60","0.033"],["77371.70","0"],["77373.10","0.005"]],"u":101055161,"seq":800573256454},"cts":1787954759507}
{"topic":"orderbook.50.BTCUSDT","type":"delta","ts":1787954759528,"data":{"s":"BTCUSDT","b":[],"a":[["77371.50","0.008"],["77371.60","0.031"],["77371.70","0.004"],["77373.10","0"]],"u":101055162,"seq":800573256569},"cts":1787954759526}
{"topic":"orderbook.50.BTCUSDT","type":"delta","ts":1787954759588,"data":{"s":"BTCUSDT","b":[["77363.50","0.002"],["77358.60","0.080"],["77355.20","0"]],"a":[["77367.40","0.003"]],"u":101055163,"seq":800573256724},"cts":1787954759580}
{"topic":"orderbook.50.BTCUSDT","type":"delta","ts":1787954759608,"data":{"s":"BTCUSDT","b":[],"a":[["77371.50","0.012"],["77371.70","0"],["77373.10","0.005"]],"u":101055164,"seq":800573256866},"cts":1787954759607}
{"topic":"orderbook.50.BTCUSDT","type":"delta","ts":1787954759668,"data":{"s":"BTCUSDT","b":[["77363.50","0"],["77360.80","0.012"]],"a":[["77367.30","0.004"],["77371.40","0.007"],["77371.50","0.008"]],"u":101055165,"seq":800573257051},"cts":1787954759666}
{"topic":"orderbook.50.BTCUSDT","type":"delta","ts":1787954759688,"data":{"s":"BTCUSDT","b":[["77364.60","0.657"]],"a":[],"u":101055166,"seq":800573257239},"cts":1787954759684}
{"topic":"orderbook.50.BTCUSDT","type":"delta","ts":1787954759708,"data":{"s":"BTCUSDT","b":[["77364.60","0.678"],["77363.80","0.008"],["77362.80","0.002"],["77362.50","0.372"]],"a":[["77364.70","8.206"],["77367.30","0.002"],["77368.40","0.002"],["77372.20","0"]],"u":101055167,"seq":800573257541},"cts":1787954759707}
{"topic":"orderbook.50.BTCUSDT","type":"delta","ts":1787954759728,"data":{"s":"BTCUSDT","b":[["77364.60","0.657"],["77363.80","0.006"],["77363.40","0.002"],["77355.30","0"]],"a":[["77364.70","8.204"]],"u":101055168,"seq":800573257685},"cts":1787954759725}
{"topic":"orderbook.50.BTCUSDT","type":"delta","ts":1787954759748,"data":{"s":"BTCUSDT","b":[],"a":[["77371.40","0.003"],["77371.50","0.012"]],"u":101055169,"seq":800573257833},"cts":1787954759742}
{"topic":"orderbook.50.BTCUSDT","type":"delta","ts":1787954759788,"data":{"s":"BTCUSDT","b":[["77364.60","0.436"],["77363.40","0"],["77355.30","0.005"]],"a":[["77364.70","8.203"],["77366.50","0.004"],["77367.30","0.004"],["77371.40","0.007"],["77371.50","0.006"]],"u":101055170,"seq":800573258130},"cts":1787954759787}
{"topic":"orderbook.50.BTCUSDT","type":"delta","ts":1787954759828,"data":{"s":"BTCUSDT","b":[["77362.40","0.010"],["77355.30","0"]],"a":[],"u":101055171,"seq":800573258382},"cts":1787954759827}
{"topic":"orderbook.50.BTCUSDT","type":"delta","ts":1787954759848,"data":{"s":"BTCUSDT","b":[["77364.30","0"],["77362.50","0.370"],["77361.80","0.004"],["77360.80","0.014"],["77355.30","0.005"]],"a":[["77366.80","0.371"],["77371.20","4.291"],["77371.40","0.003"],["77371.50","0.008"]],"u":101055172,"seq":800573258605},"cts":1787954759846}
{"topic":"orderbook.50.BTCUSDT","type":"delta","ts":1787954759868,"data":{"s":"BTCUSDT","b":[["77362.60","0.243"],["77361.90","0"],["77361.80","0.006"],["77355.20","0.013"]],"a":[["77366.00","0.002"],["77370.00","0.005"],["77371.20","4.289"],["77371.50","0.010"],["77373.10","0"]],"u":101055173,"seq":800573258856},"cts":1787954759868}
{"topic":"orderbook.50.BTCUSDT","type":"delta","ts":1787954759888,"data":{"s":"BTCUSDT","b":[["77362.40","0.012"]],"a":[["77366.00","0"],["77373.10","0.005"]],"u":101055174,"seq":800573259007},"cts":1787954759886}
{"topic":"orderbook.50.BTCUSDT","type":"delta","ts":1787954759928,"data":{"s":"BTCUSDT","b":[],"a":[["77364.70","8.201"]],"u":101055175,"seq":800573259269},"cts":1787954759926}
{"topic":"orderbook.50.BTCUSDT","type":"delta","ts":1787954759948,"data":{"s":"BTCUSDT","b":[["77364.60","0.678"],["77363.50","0.002"],["77359.60","0.001"],["77355.20","0"]],"a":[["77366.50","0.002"],["77366.80","0.001"],["77367.30","0.002"],["77368.90","0.058"],["77369.40","0.002"],["77373.10","0"]],"u":101055176,"seq":800573259495},"cts":1787954759945}
{"topic":"orderbook.50.BTCUSDT","type":"delta","ts":1787954760008,"data":{"s":"BTCUSDT","b":[["77364.10","0.002"],["77360.80","0.012"],["77355.30","0"]],"a":[["77367.90","4.188"],["77368.00","14.003"],["77368.10","0"],["77369.80","0.003"],["77371.50","0.006"],["77371.70","0.004"]],"u":101055177,"seq":800573259821},"cts":1787954760007}
{"topic":"orderbook.50.BTCUSDT","type":"delta","ts":1787954760028,"data":{"s":"BTCUSDT","b":[],"a":[["77367.80","0"],["77368.00","14.001"],["77368.10","0.002"],["77371.60","0.035"],["77371.70","0"],["77373.10","0.005"]],"u":101055178,"seq":800573259896},"cts":1787954760019}
{"topic":"orderbook.50.BTCUSDT","type":"delta","ts":1787954760048,"data":{"s":"BTCUSDT","b":[["77364.60","0.860"],["77364.50","0.004"],["77364.00","0.027"],["77361.30","0"]],"a":[["77368.40","0"],["77368.90","0.056"],["77370.30","0.003"],["77370.80","0.012"],["77371.60","0.031"],["77371.70","0.004"]],"u":101055179,"seq":800573260076},"cts":1787954760047}
{"topic":"orderbook.50.BTCUSDT","type":"delta","ts":1787954760068,"data":{"s":"BTCUSDT","b":[["77364.60","0.678"],["77364.50","0.002"],["77364.10","0"],["77363.00","0.002"]],"a":[["77367.90","4.190"],["77368.50","0.004"],["77370.80","0.010"],["77371.50","0.008"],["77371.70","0.002"]],"u":101055180,"seq":800573260392},"cts":1787954760067}
{"topic":"orderbook.50.BTCUSDT","type":"delta","ts":1787954760088,"data":{"s":"BTCUSDT","b":[["77364.10","0.002"],["77355.50","0"]],"a":[["77367.90","4.188"]],"u":101055181,"seq":800573260743},"cts":1787954760084}
{"topic":"orderbook.50.BTCUSDT","type":"delta","ts":1787954760108,"data":{"s":"BTCUSDT","b":[],"a":[["77371.50","0.006"],["77371.60","0.033"]],"u":101055182,"seq":800573260879},"cts":1787954760106}
{"topic":"orderbook.50.BTCUSDT","type":"delta","ts":1787954760148,"data":{"s":"BTCUSDT","b":[],"a":[["77371.50","0.010"],["77371.60","0.031"],["77371.70","0"],["77373.70","0.007"]],"u":101055183,"seq":800573260992},"cts":1787954760144}
{"topic":"orderbook.50.BTCUSDT","type":"delta","ts":1787954760168,"data":{"s":"BTCUSDT","b":[["77364.60","0.393"],["77364.10","0"],["77363.50","0"],["77363.00","0"],["77362.40","0.010"],["77362.00","0.002"],["77361.60","0"],["77360.90","0.001"],["77355.50","0.002"],["77355.30","0.005"],["77355.20","0.013"]],"a":[["77364.70","8.136"],["77366.00","0.002"],["77366.80","0.003"],["77367.80","0.370"],["77370.30","0.001"],["77373.10","0"],["77373.70","0"]],"u":101055184,"seq":800573261181},"cts":1787954760167}
{"topic":"orderbook.50.BTCUSDT","type":"delta","ts":1787954760188,"data":{"s":"BTCUSDT","b":[["77363.10","0.002"],["77362.60","0.245"],["77361.30","0.002"],["77355.30","0"],["77355.20","0"]],"a":[["77366.00","0"],["77366.80","0.001"],["77367.40","0.005"],["77373.10","0.005"]],"u":101055185,"seq":800573261791},"cts":1787954760176}
{"topic":"orderbook.50.BTCUSDT","type":"delta","ts":1787954760208,"data":{"s":"BTCUSDT","b":[["77364.60","0.810"],["77363.80","0.008"],["77361.60","0.001"],["77355.50","0"]],"a":[["77367.40","0.003"],["77370.30","0.003"],["77371.50","0.006"],["77371.70","0.004"],["77373.10","0"]],"u":101055186,"seq":800573262971},"cts":1787954760206}
{"topic":"orderbook.50.BTCUSDT","type":"delta","ts":1787954760228,"data":{"s":"BTCUSDT","b":[],"a":[["77367.90","4.190"],["77371.60","0.035"],["77371.70","0"],["77373.10","0.005"]],"u":101055187,"seq":800573263034},"cts":1787954760219}
{"topic":"orderbook.50.BTCUSDT","type":"delta","ts":1787954760248,"data":{"s":"BTCUSDT","b":[["77364.50","0.004"],["77361.30","0"],["77355.50","0.002"]],"a":[["77364.70","8.064"],["77367.90","4.188"],["77368.50","0.002"],["77370.30","0.061"],["77370.80","0.012"],["77371.60","0.031"],["77371.70","0.004"],["77373.10","0"]],"u":101055188,"seq":800573263159},"cts":1787954760247}
{"topic":"orderbook.50.BTCUSDT","type":"delta","ts":1787954760308,"data":{"s":"BTCUSDT","b":[],"a":[["77371.60","0.035"],["77371.70","0"],["77373.10","0.005"]],"u":101055189,"seq":800573263284},"cts":1787954760307}
{"topic":"orderbook.50.BTCUSDT","type":"delta","ts":1787954760328,"data":{"s":"BTCUSDT","b":[],"a":[["77371.60","0.031"],["77371.70","0.004"],["77373.10","0"]],"u":101055190,"seq":800573263337},"cts":1787954760319}
{"topic":"orderbook.50.BTCUSDT","type":"delta","ts":1787954760388,"data":{"s":"BTCUSDT","b":[["77364.60","0.805"]],"a":[],"u":101055191,"seq":800573263540},"cts":1787954760373}
{"topic":"orderbook.50.BTCUSDT","type":"delta","ts":1787954760408,"data":{"s":"BTCUSDT","b":[],"a":[["77371.60","0.035"],["77371.70","0"],["77373.10","0.005"]],"u":101055192,"seq":800573263632},"cts":1787954760407}
{"topic":"orderbook.50.BTCUSDT","type":"delta","ts":1787954760428,"data":{"s":"BTCUSDT","b":[],"a":[["77371.60","0.031"],["77371.70","0.004"],["77373.10","0"]],"u":101055193,"seq":800573263692},"cts":1787954760427}
{"topic":"orderbook.50.BTCUSDT","type":"delta","ts":1787954760448,"data":{"s":"BTCUSDT","b":[],"a":[["77369.40","0"],["77371.30","14.003"],["77373.10","0.005"]],"u":101055194,"seq":800573263750},"cts":1787954760445}
{"topic":"orderbook.50.BTCUSDT","type":"delta","ts":1787954760468,"data":{"s":"BTCUSDT","b":[],"a":[["77369.30","0.004"]],"u":101055195,"seq":800573263800},"cts":1787954760463}
{"topic":"orderbook.50.BTCUSDT","type":"delta","ts":1787954760508,"data":{"s":"BTCUSDT","b":[["77358.30","0.376"]],"a":[["77371.60","0.035"],["77371.70","0"],["77373.70","0.007"]],"u":101055196,"seq":800573263923},"cts":1787954760506}
{"topic":"orderbook.50.BTCUSDT","type":"delta","ts":1787954760528,"data":{"s":"BTCUSDT","b":[],"a":[["77371.60","0.031"],["77371.70","0.004"],["77373.70","0"]],"u":101055197,"seq":800573263948},"cts":1787954760517}
{"topic":"orderbook.50.BTCUSDT","type":"delta","ts":1787954760588,"data":{"s":"BTCUSDT","b":[["77356.60","0.002"]],"a":[],"u":101055198,"seq":800573264079},"cts":1787954760587}
{"topic":"orderbook.50.BTCUSDT","type":"delta","ts":1787954760609,"data":{"s":"BTCUSDT","b":[],"a":[["77371.60","0.035"],["77371.70","0"],["77373.70","0.007"]],"u":101055199,"seq":800573264156},"cts":1787954760607}
{"topic":"orderbook.50.BTCUSDT","type":"delta","ts":1787954760629,"data":{"s":"BTCUSDT","b":[],"a":[["77371.60","0.031"],["77371.70","0.004"],["77373.70","0"]],"u":101055200,"seq":800573264205},"cts":1787954760626}
{"topic":"orderbook.50.BTCUSDT","type":"delta","ts":1787954760648,"data":{"s":"BTCUSDT","b":[],"a":[["77371.00","0.031"],["77371.10","0.129"]],"u":101055201,"seq":800573264316},"cts":1787954760643}
{"topic":"orderbook.50.BTCUSDT","type":"delta","ts":1787954760708,"data":{"s":"BTCUSDT","b":[],"a":[["77371.60","0.035"],["77371.70","0"],["77373.70","0.007"]],"u":101055202,"seq":800573264486},"cts":1787954760706}
{"topic":"orderbook.50.BTCUSDT","type":"delta","ts":1787954760729,"data":{"s":"BTCUSDT","b":[["77356.60","0.001"]],"a":[["77364.70","7.852"],["77369.30","0.002"],["77371.60","0.031"],["77371.70","0.004"],["77373.70","0"]],"u":101055203,"seq":800573264545},"cts":1787954760725}
{"topic":"orderbook.50.BTCUSDT","type":"delta","ts":1787954760748,"data":{"s":"BTCUSDT","b":[["77364.50","0.002"]],"a":[["77364.70","8.065"],["77367.90","4.190"],["77373.10","0.002"]],"u":101055204,"seq":800573264614},"cts":1787954760747}
{"topic":"orderbook.50.BTCUSDT","type":"delta","ts":1787954760768,"data":{"s":"BTCUSDT","b":[["77364.60","0.870"]],"a":[],"u":101055205,"seq":800573264653},"cts":1787954760764}
{"topic":"orderbook.50.BTCUSDT","type":"delta","ts":1787954760788,"data":{"s":"BTCUSDT","b":[],"a":[["77367.50","0.004"]],"u":101055206,"seq":800573264699},"cts":1787954760787}
{"topic":"orderbook.50.BTCUSDT","type":"delta","ts":1787954760808,"data":{"s":"BTCUSDT","b":[],"a":[["77371.50","0.005"],["77371.60","0.035"],["77371.70","0"],["77373.70","0.007"]],"u":101055207,"seq":800573264741},"cts":1787954760806}
{"topic":"orderbook.50.BTCUSDT","type":"delta","ts":1787954760828,"data":{"s":"BTCUSDT","b":[],"a":[["77371.60","0.031"],["77371.70","0.004"],["77373.70","0"]],"u":101055208,"seq":800573264785},"cts":1787954760826}
{"topic":"orderbook.50.BTCUSDT","type":"delta","ts":1787954760888,"data":{"s":"BTCUSDT","b":[],"a":[["77367.50","0.002"],["77371.50","0.006"]],"u":101055209,"seq":800573264880},"cts":1787954760882}
{"topic":"orderbook.50.BTCUSDT","type":"delta","ts":1787954760908,"data":{"s":"BTCUSDT","b":[["77364.60","0.805"],["77364.50","0.004"]],"a":[["77364.70","8.016"],["77367.90","4.188"],["77369.00","0.002"],["77371.50","0.008"],["77371.70","0"]],"u":101055210,"seq":800573265009},"cts":1787954760905}
{"topic":"orderbook.50.BTCUSDT","type":"delta","ts":1787954760928,"data":{"s":"BTCUSDT","b":[["77363.80","0.006"],["77361.30","0.002"],["77355.50","0"]],"a":[["77371.30","14.001"],["77371.50","0.010"]],"u":101055211,"seq":800573265078},"cts":1787954760925}
{"topic":"orderbook.50.BTCUSDT","type":"delta","ts":1787954761008,"data":{"s":"BTCUSDT","b":[],"a":[["77367.50","0"],["77370.80","0.009"],["77373.70","0.007"]],"u":101055212,"seq":800573265205},"cts":1787954761005}
{"topic":"orderbook.50.BTCUSDT","type":"delta","ts":1787954761028,"data":{"s":"BTCUSDT","b":[],"a":[["77370.80","0.006"]],"u":101055213,"seq":800573265246},"cts":1787954761026}
{"topic":"orderbook.50.BTCUSDT","type":"delta","ts":1787954761089,"data":{"s":"BTCUSDT","b":[["77364.50","0.002"],["77364.00","0.029"]],"a":[["77368.10","0.004"]],"u":101055214,"seq":800573265410},"cts":1787954761078}
{"topic":"orderbook.50.BTCUSDT","type":"delta","ts":1787954761108,"data":{"s":"BTCUSDT","b":[],"a":[["77368.10","0.002"]],"u":101055215,"seq":800573265517},"cts":1787954761107}
{"topic":"orderbook.50.BTCUSDT","type":"delta","ts":1787954761129,"data":{"s":"BTCUSDT","b":[["77364.50","0.004"],["77361.30","0"],["77355.50","0.002"]],"a":[["77364.70","8.074"],["77369.00","0"],["77370.30","0.003"],["77371.30","14.003"],["77371.50","0.006"],["77371.70","0.004"]],"u":101055216,"seq":800573265587},"cts":1787954761126}
{"topic":"orderbook.50.BTCUSDT","type":"delta","ts":1787954761148,"data":{"s":"BTCUSDT","b":[],"a":[["77371.60","0.035"],["77371.70","0"],["77373.80","0.001"]],"u":101055217,"seq":800573265669},"cts":1787954761147}
{"topic":"orderbook.50.BTCUSDT","type":"delta","ts":1787954761168,"data":{"s":"BTCUSDT","b":[],"a":[["77367.80","0"],["77371.60","0.031"],["77371.70","0.004"],["77371.80","0.003"]],"u":101055218,"seq":800573265716},"cts":1787954761166}
{"topic":"orderbook.50.BTCUSDT","type":"delta","ts":1787954761188,"data":{"s":"BTCUSDT","b":[],"a":[["77369.80","0.001"],["77370.30","0.001"],["77372.30","0.004"]],"u":101055219,"seq":800573265797},"cts":1787954761187}
{"topic":"orderbook.50.BTCUSDT","type":"delta","ts":1787954761208,"data":{"s":"BTCUSDT","b":[],"a":[["77371.60","0.035"],["77371.70","0"],["77374.00","0.188"]],"u":101055220,"seq":800573265834},"cts":1787954761205}
{"topic":"orderbook.50.BTCUSDT","type":"delta","ts":1787954761228,"data":{"s":"BTCUSDT","b":[],"a":[["77369.70","0.002"],["77371.60","0.031"],["77371.70","0.004"],["77373.80","0"],["77374.00","0"]],"u":101055221,"seq":800573265913},"cts":1787954761224}
{"topic":"orderbook.50.BTCUSDT","type":"delta","ts":1787954761248,"data":{"s":"BTCUSDT","b":[["77364.60","2.523"]],"a":[["77364.70","8.016"],["77367.90","0.008"],["77369.70","0"],["77370.80","0.004"],["77371.10","0"],["77371.30","14.001"],["77371.50","0.005"],["77371.70","0"],["77371.80","0.001"],["77372.00","0.002"],["77372.20","0.001"],["77372.30","0.002"],["77372.90","0.004"],["77373.80","0.001"]],"u":101055222,"seq":800573266063},"cts":1787954761247}
{"topic":"orderbook.50.BTCUSDT","type":"delta","ts":1787954761268,"data":{"s":"BTCUSDT","b":[["77364.60","3.529"],["77358.40","1.936"],["77355.50","0"]],"a":[["77364.70","7.881"],["77371.20","0.002"],["77371.90","0.058"],["77372.00","0"],["77372.10","0.323"],["77372.90","0.002"]],"u":101055223,"seq":800573266276},"cts":1787954761267}
{"topic":"orderbook.50.BTCUSDT","type":"delta","ts":1787954761288,"data":{"s":"BTCUSDT","b":[["77364.60","3.635"],["77364.00","0.030"],["77363.50","0.001"],["77360.90","0"],["77359.70","0.892"],["77357.10","0.380"],["77355.80","0"]],"a":[["77364.70","7.845"],["77366.40","0.003"],["77367.90","0.002"],["77368.80","0"],["77371.20","0.008"],["77371.90","0"],["77373.70","0.003"],["77374.00","0.001"],["77374.10","0.051"]],"u":101055224,"seq":800573266607},"cts":1787954761287}
{"topic":"orderbook.50.BTCUSDT","type":"delta","ts":1787954761308,"data":{"s":"BTCUSDT","b":[["77364.60","3.638"],["77359.40","0.280"],["77356.60","0.384"]],"a":[["77364.90","0"],["77365.70","0"],["77368.00","14.000"],["77371.20","0.007"],["77372.90","0"],["77374.20","0.002"],["77374.50","0.002"],["77374.60","14.000"]],"u":101055225,"seq":800573267100},"cts":1787954761307}
{"topic":"orderbook.50.BTCUSDT","type":"delta","ts":1787954761328,"data":{"s":"BTCUSDT","b":[["77364.60","3.675"]],"a":[["77372.20","0"],["77374.50","2.769"],["77374.60","14.001"],["77374.70","0.001"]],"u":101055226,"seq":800573267311},"cts":1787954761327}
{"topic":"orderbook.50.BTCUSDT","type":"delta","ts":1787954761348,"data":{"s":"BTCUSDT","b":[["77364.60","3.912"],["77359.80","0.775"],["77356.00","0"]],"a":[["77371.40","0"],["77374.60","14.003"],["77374.70","0"],["77375.00","0.014"],["77375.10","0.001"]],"u":101055227,"seq":800573267372},"cts":1787954761347}
{"topic":"orderbook.50.BTCUSDT","type":"delta","ts":1787954761368,"data":{"s":"BTCUSDT","b":[["77356.20","0.260"]],"a":[["77374.50","3.836"]],"u":101055228,"seq":800573267416},"cts":1787954761364}
{"topic":"orderbook.50.BTCUSDT","type":"delta","ts":1787954761388,"data":{"s":"BTCUSDT","b":[["77364.60","3.867"]],"a":[["77375.10","0"],["77375.20","0.004"]],"u":101055229,"seq":800573267524},"cts":1787954761385}
{"topic":"orderbook.50.BTCUSDT","type":"delta","ts":1787954761408,"data":{"s":"BTCUSDT","b":[["77364.60","3.868"],["77362.40","0.013"]],"a":[],"u":101055230,"seq":800573267593},"cts":1787954761406}
{"topic":"orderbook.50.BTCUSDT","type":"delta","ts":1787954761428,"data":{"s":"BTCUSDT","b":[["77364.60","3.798"]],"a":[["77374.70","0.001"],["77375.20","0"]],"u":101055231,"seq":800573267671},"cts":1787954761426}
{"topic":"orderbook.50.BTCUSDT","type":"delta","ts":1787954761449,"data":{"s":"BTCUSDT","b":[["77364.60","3.802"],["77359.90","0.006"],["77356.10","0"]],"a":[["77366.40","0.001"]],"u":101055232,"seq":800573267718},"cts":1787954761445}
{"topic":"orderbook.50.BTCUSDT","type":"delta","ts":1787954761468,"data":{"s":"BTCUSDT","b":[["77359.90","0"],["77356.10","0.970"]],"a":[],"u":101055233,"seq":800573267768},"cts":1787954761461}
{"topic":"orderbook.50.BTCUSDT","type":"delta","ts":1787954761488,"data":{"s":"BTCUSDT","b":[["77359.90","0.006"],["77356.10","0"]],"a":[],"u":101055234,"seq":800573267806},"cts":1787954761480}
{"topic":"orderbook.50.BTCUSDT","type":"delta","ts":1787954761508,"data":{"s":"BTCUSDT","b":[["77359.90","0"],["77356.10","0.970"]],"a":[],"u":101055235,"seq":800573267856},"cts":1787954761507}
{"topic":"orderbook.50.BTCUSDT","type":"delta","ts":1787954761528,"data":{"s":"BTCUSDT","b":[["77359.90","0.006"],["77356.10","0"]],"a":[],"u":101055236,"seq":800573267914},"cts":1787954761526}
{"topic":"orderbook.50.BTCUSDT","type":"delta","ts":1787954761548,"data":{"s":"BTCUSDT","b":[["77359.90","0"],["77356.10","0.970"]],"a":[],"u":101055237,"seq":800573267955},"cts":1787954761544}
{"topic":"orderbook.50.BTCUSDT","type":"delta","ts":1787954761568,"data":{"s":"BTCUSDT","b":[["77359.90","0.006"],["77356.10","0"]],"a":[],"u":101055238,"seq":800573267991},"cts":1787954761562}
{"topic":"orderbook.50.BTCUSDT","type":"delta","ts":1787954761588,"data":{"s":"BTCUSDT","b":[["77359.90","0"],["77356.10","0.970"]],"a":[],"u":101055239,"seq":800573268036},"cts":1787954761582}
{"topic":"orderbook.50.BTCUSDT","type":"delta","ts":1787954761608,"data":{"s":"BTCUSDT","b":[["77359.90","0.006"],["77356.10","0"]],"a":[],"u":101055240,"seq":800573268078},"cts":1787954761605}
{"topic":"orderbook.50.BTCUSDT","type":"delta","ts":1787954761628,"data":{"s":"BTCUSDT","b":[["77359.90","0"],["77356.10","0.970"]],"a":[],"u":101055241,"seq":800573268102},"cts":1787954761616}
{"topic":"orderbook.50.BTCUSDT","type":"delta","ts":1787954761648,"data":{"s":"BTCUSDT","b":[["77359.90","0.006"],["77356.10","0"]],"a":[],"u":101055242,"seq":800573268132},"cts":1787954761639}
{"topic":"orderbook.50.BTCUSDT","type":"delta","ts":1787954761668,"data":{"s":"BTCUSDT","b":[["77359.90","0"],["77356.10","0.970"]],"a":[],"u":101055243,"seq":800573268179},"cts":1787954761659}
{"topic":"orderbook.50.BTCUSDT","type":"delta","ts":1787954761688,"data":{"s":"BTCUSDT","b":[["77359.90","0.006"],["77356.10","0"]],"a":[],"u":101055244,"seq":800573268220},"cts":1787954761687}
{"topic":"orderbook.50.BTCUSDT","type":"delta","ts":1787954761708,"data":{"s":"BTCUSDT","b":[["77359.90","0"],["77356.10","0.970"]],"a":[],"u":101055245,"seq":800573268264},"cts":1787954761706}
{"topic":"orderbook.50.BTCUSDT","type":"delta","ts":1787954761729,"data":{"s":"BTCUSDT","b":[["77359.90","0.006"],["77356.10","0"]],"a":[["77373.60","0.001"],["77375.00","0"]],"u":101055246,"seq":800573268308},"cts":1787954761726}
{"topic":"orderbook.50.BTCUSDT","type":"delta","ts":1787954761748,"data":{"s":"BTCUSDT","b":[["77359.90","0.135"],["77356.60","0.385"]],"a":[["77364.70","7.632"],["77370.80","0.001"]],"u":101055247,"seq":800573268364},"cts":1787954761746}
{"topic":"orderbook.50.BTCUSDT","type":"delta","ts":1787954761768,"data":{"s":"BTCUSDT","b":[],"a":[["77364.70","7.835"]],"u":101055248,"seq":800573268463},"cts":1787954761767}
{"topic":"orderbook.50.BTCUSDT","type":"delta","ts":1787954761788,"data":{"s":"BTCUSDT","b":[],"a":[["77364.70","7.831"]],"u":101055249,"seq":800573268506},"cts":1787954761782}
{"topic":"orderbook.50.BTCUSDT","type":"delta","ts":1787954761908,"data":{"s":"BTCUSDT","b":[["77356.60","0.384"]],"a":[["77371.60","0.001"]],"u":101055250,"seq":800573268750},"cts":1787954761906}
{"topic":"orderbook.50.BTCUSDT","type":"delta","ts":1787954761988,"data":{"s":"BTCUSDT","b":[],"a":[["77364.70","7.790"]],"u":101055251,"seq":800573268875},"cts":1787954761987}
{"topic":"orderbook.50.BTCUSDT","type":"delta","ts":1787954762129,"data":{"s":"BTCUSDT","b":[["77364.40","0.016"],["77356.20","0"]],"a":[],"u":101055252,"seq":800573269055},"cts":1787954762126}
{"topic":"orderbook.50.BTCUSDT","type":"delta","ts":1787954762208,"data":{"s":"BTCUSDT","b":[["77364.60","3.807"]],"a":[],"u":101055253,"seq":800573269186},"cts":1787954762207}
{"topic":"orderbook.50.BTCUSDT","type":"delta","ts":1787954762388,"data":{"s":"BTCUSDT","b":[["77358.50","0.130"],["77356.30","0"]],"a":[],"u":101055254,"seq":800573269349},"cts":1787954762385}
{"topic":"orderbook.50.BTCUSDT","type":"delta","ts":1787954762448,"data":{"s":"BTCUSDT","b":[],"a":[["77369.80","0.029"]],"u":101055255,"seq":800573269449},"cts":1787954762445}
{"topic":"orderbook.50.BTCUSDT","type":"delta","ts":1787954762588,"data":{"s":"BTCUSDT","b":[["77359.80","0"],["77356.30","0.001"]],"a":[["77374.00","0.189"]],"u":101055256,"seq":800573269556},"cts":1787954762587}
{"topic":"orderbook.50.BTCUSDT","type":"delta","ts":1787954762609,"data":{"s":"BTCUSDT","b":[["77364.60","3.769"],["77364.40","0"],["77359.90","0.006"],["77356.20","0.130"]],"a":[["77364.70","7.791"],["77367.90","0.008"],["77370.20","0.002"],["77371.20","4.281"],["77371.80","0.003"],["77372.90","0.002"],["77373.70","0.005"],["77374.30","0.002"],["77374.50","0"],["77374.60","0"],["77374.70","0"]],"u":101055257,"seq":800573269686},"cts":1787954762607}
{"topic":"orderbook.50.BTCUSDT","type":"delta","ts":1787954762629,"data":{"s":"BTCUSDT","b":[],"a":[["77369.70","0.002"],["77373.70","0.007"],["77374.30","0"]],"u":101055258,"seq":800573269764},"cts":1787954762627}
{"topic":"orderbook.50.BTCUSDT","type":"delta","ts":1787954762648,"data":{"s":"BTCUSDT","b":[["77364.60","2.927"],["77364.50","0.002"]],"a":[["77367.90","0.010"],["77371.20","4.282"],["77372.90","0"],["77374.10","0.055"],["77374.50","3.836"]],"u":101055259,"seq":800573269818},"cts":1787954762643}
{"topic":"orderbook.50.BTCUSDT","type":"delta","ts":1787954762668,"data":{"s":"BTCUSDT","b":[],"a":[["77367.90","0.008"],["77368.10","0.004"]],"u":101055260,"seq":800573269878},"cts":1787954762667}
{"topic":"orderbook.50.BTCUSDT","type":"delta","ts":1787954762688,"data":{"s":"BTCUSDT","b":[["77364.50","0.004"]],"a":[["77368.10","0.002"],["77371.40","0.003"],["77374.10","0.051"],["77374.50","0"]],"u":101055261,"seq":800573269937},"cts":1787954762683}
{"topic":"orderbook.50.BTCUSDT","type":"delta","ts":1787954762708,"data":{"s":"BTCUSDT","b":[],"a":[["77369.70","0"],["77370.20","0"],["77370.70","0.002"],["77372.30","0.004"],["77374.50","3.836"]],"u":101055262,"seq":800573269986},"cts":1787954762706}
{"topic":"orderbook.50.BTCUSDT","type":"delta","ts":1787954762728,"data":{"s":"BTCUSDT","b":[],"a":[["77374.40","0.004"],["77374.50","0"]],"u":101055263,"seq":800573270022},"cts":1787954762721}
{"topic":"orderbook.50.BTCUSDT","type":"delta","ts":1787954762748,"data":{"s":"BTCUSDT","b":[],"a":[["77370.70","0"],["77372.80","0.002"],["77374.30","0.004"],["77374.40","0"]],"u":101055264,"seq":800573270055},"cts":1787954762741}
{"topic":"orderbook.50.BTCUSDT","type":"delta","ts":1787954762769,"data":{"s":"BTCUSDT","b":[],"a":[["77374.30","0"],["77374.40","0.133"]],"u":101055265,"seq":800573270097},"cts":1787954762767}
{"topic":"orderbook.50.BTCUSDT","type":"delta","ts":1787954762788,"data":{"s":"BTCUSDT","b":[["77364.60","0.825"],["77364.50","0.002"],["77364.00","0.028"],["77363.10","0"],["77362.60","0.001"],["77362.50","0"],["77362.40","0.010"],["77361.80","0.004"],["77360.50","0.376"],["77360.40","0"],["77359.90","0"],["77358.60","0.082"],["77358.50","0.500"],["77358.40","0"],["77358.30","0.006"],["77358.10","0.005"],["77357.70","0.002"],["77357.20","0.002"],["77357.10","0"],["77356.70","0.369"],["77356.60","0.001"],["77356.50","0.001"],["77356.20","0"],["77356.10","0.970"],["77356.00","0.001"]],"a":[["77364.70","8.020"],["77365.00","0.006"],["77366.50","0.004"],["77366.80","0.371"],["77367.90","4.558"],["77368.50","0.004"],["77369.20","0.002"],["77370.70","0.002"],["77371.10","0.129"],["77371.20","4.280"],["77371.80","0.001"],["77372.00","0.002"],["77372.20","0.002"],["77372.30","0.002"],["77372.80","0"],["77374.00","0"],["77374.10","0"],["77374.20","0"],["77374.40","0"]],"u":101055266,"seq":800573270583},"cts":1787954762787}
{"topic":"orderbook.50.BTCUSDT","type":"delta","ts":1787954762808,"data":{"s":"BTCUSDT","b":[["77364.60","0.602"],["77363.50","0"],["77362.50","0.370"],["77362.30","0.017"],["77360.70","0.118"],["77359.70","0.370"],["77358.60","0.080"],["77358.50","0.370"],["77358.10","0.003"],["77357.70","0"],["77357.20","0"],["77356.10","0.985"],["77355.80","0.247"],["77355.50","0.002"]],"a":[["77368.80","0.001"],["77371.40","0.007"],["77372.00","0"],["77372.20","0"],["77374.00","0.189"]],"u":101055267,"seq":800573271008},"cts":1787954762806}
{"topic":"orderbook.50.BTCUSDT","type":"delta","ts":1787954762828,"data":{"s":"BTCUSDT","b":[["77364.60","1.026"],["77364.00","0.027"],["77360.50","0.370"],["77360.30","0.002"],["77359.60","0.003"],["77358.80","0.003"],["77357.10","0.002"],["77356.80","0.055"],["77355.80","0"],["77355.50","0"]],"a":[["77364.70","8.021"],["77366.80","0.001"],["77372.10","0.705"]],"u":101055268,"seq":800573271207},"cts":1787954762826}
{"topic":"orderbook.50.BTCUSDT","type":"delta","ts":1787954762848,"data":{"s":"BTCUSDT","b":[["77361.00","0.005"],["77356.80","0.049"]],"a":[["77367.90","4.188"],["77371.40","0.005"],["77371.50","0.007"]],"u":101055269,"seq":800573271334},"cts":1787954762847}
{"topic":"orderbook.50.BTCUSDT","type":"delta","ts":1787954762869,"data":{"s":"BTCUSDT","b":[["77362.60","0.242"],["77361.60","0.003"],["77360.70","0.002"],["77357.10","0"],["77355.80","0.245"]],"a":[["77364.70","8.020"],["77365.00","0.004"],["77365.60","0.003"],["77371.70","0.058"],["77374.00","0"]],"u":101055270,"seq":800573271424},"cts":1787954762862}
{"topic":"orderbook.50.BTCUSDT","type":"delta","ts":1787954762889,"data":{"s":"BTCUSDT","b":[],"a":[["77365.60","0.001"],["77366.00","0.002"],["77373.80","0"]],"u":101055271,"seq":800573271473},"cts":1787954762886}
{"topic":"orderbook.50.BTCUSDT","type":"delta","ts":1787954762908,"data":{"s":"BTCUSDT","b":[["77364.60","1.032"]],"a":[["77371.30","14.005"],["77371.40","0.003"],["77371.50","0.005"]],"u":101055272,"seq":800573271571},"cts":1787954762905}
{"topic":"orderbook.50.BTCUSDT","type":"delta","ts":1787954762928,"data":{"s":"BTCUSDT","b":[["77356.60","0.002"]],"a":[],"u":101055273,"seq":800573271613},"cts":1787954762924}
{"topic":"orderbook.50.BTCUSDT","type":"delta","ts":1787954762949,"data":{"s":"BTCUSDT","b":[["77362.60","0.244"],["77358.80","0.001"]],"a":[["77366.00","0"],["77372.20","0.001"]],"u":101055274,"seq":800573271637},"cts":1787954762937}
{"topic":"orderbook.50.BTCUSDT","type":"delta","ts":1787954762968,"data":{"s":"BTCUSDT","b":[["77364.60","1.011"],["77362.70","0.002"],["77362.60","0.242"],["77355.80","0"]],"a":[["77371.20","4.284"],["77371.30","14.001"]],"u":101055275,"seq":800573271931},"cts":1787954762966}
{"topic":"orderbook.50.BTCUSDT","type":"delta","ts":1787954762988,"data":{"s":"BTCUSDT","b":[],"a":[["77366.50","0.002"],["77366.70","0.003"]],"u":101055276,"seq":800573272003},"cts":1787954762987}
{"topic":"orderbook.50.BTCUSDT","type":"delta","ts":1787954763028,"data":{"s":"BTCUSDT","b":[["77356.60","0.001"]],"a":[],"u":101055277,"seq":800573272071},"cts":1787954763021}
{"topic":"orderbook.50.BTCUSDT","type":"delta","ts":1787954763089,"data":{"s":"BTCUSDT","b":[],"a":[["77371.10","0.133"],["77371.20","4.280"]],"u":101055278,"seq":800573272141},"cts":1787954763084}
{"topic":"orderbook.50.BTCUSDT","type":"delta","ts":1787954763208,"data":{"s":"BTCUSDT","b":[],"a":[["77366.70","0.001"],["77366.90","0.002"],["77373.70","0"]],"u":101055279,"seq":800573272342},"cts":1787954763205}
{"topic":"orderbook.50.BTCUSDT","type":"delta","ts":1787954763228,"data":{"s":"BTCUSDT","b":[["77363.20","0.002"],["77359.60","0.001"],["77356.00","0"]],"a":[["77366.90","0"],["77367.20","0.032"],["77373.70","0.007"]],"u":101055280,"seq":800573272378},"cts":1787954763219}
{"topic":"orderbook.50.BTCUSDT","type":"delta","ts":1787954763328,"data":{"s":"BTCUSDT","b":[["77363.20","0"],["77356.00","0.001"]],"a":[],"u":101055281,"seq":800573272524},"cts":1787954763327}
{"topic":"orderbook.50.BTCUSDT","type":"delta","ts":1787954763448,"data":{"s":"BTCUSDT","b":[["77363.30","0.009"]],"a":[],"u":101055282,"seq":800573272647},"cts":1787954763440}
{"topic":"orderbook.50.BTCUSDT","type":"delta","ts":1787954763509,"data":{"s":"BTCUSDT","b":[],"a":[["77371.10","0.129"],["77371.30","14.005"]],"u":101055283,"seq":800573272741},"cts":1787954763507}
{"topic":"orderbook.50.BTCUSDT","type":"delta","ts":1787954763568,"data":{"s":"BTCUSDT","b":[],"a":[["77367.20","0.030"],["77367.40","0.005"]],"u":101055284,"seq":800573272782},"cts":1787954763562}
{"topic":"orderbook.50.BTCUSDT","type":"delta","ts":1787954763608,"data":{"s":"BTCUSDT","b":[],"a":[["77367.40","0.003"],["77367.70","0.003"],["77371.30","14.001"],["77371.40","0.007"]],"u":101055285,"seq":800573272845},"cts":1787954763607}
{"topic":"orderbook.50.BTCUSDT","type":"delta","ts":1787954763748,"data":{"s":"BTCUSDT","b":[["77363.90","0.002"],["77360.30","0"]],"a":[["77364.70","8.061"],["77367.70","0.001"],["77367.90","4.190"],["77368.50","0.002"],["77369.70","0.002"],["77373.70","0"]],"u":101055286,"seq":800573273038},"cts":1787954763742}
{"topic":"orderbook.50.BTCUSDT","type":"delta","ts":1787954763809,"data":{"s":"BTCUSDT","b":[["77364.50","0.004"],["77361.00","0.003"]],"a":[["77367.90","4.188"],["77368.50","0.004"]],"u":101055287,"seq":800573273135},"cts":1787954763805}
{"topic":"orderbook.50.BTCUSDT","type":"delta","ts":1787954763829,"data":{"s":"BTCUSDT","b":[["77364.50","0.002"],["77363.90","0"],["77363.30","0.007"],["77362.20","0.002"],["77361.10","0.002"],["77356.00","0"]],"a":[["77366.70","0.003"],["77367.60","0.002"],["77370.70","0"]],"u":101055288,"seq":800573273181},"cts":1787954763825}
{"topic":"orderbook.50.BTCUSDT","type":"delta","ts":1787954763968,"data":{"s":"BTCUSDT","b":[["77363.40","0.002"],["77356.10","0"]],"a":[["77364.70","8.032"],["77366.70","0.001"]],"u":101055289,"seq":800573273335},"cts":1787954763959}
{"topic":"orderbook.50.BTCUSDT","type":"delta","ts":1787954763989,"data":{"s":"BTCUSDT","b":[["77361.10","0"],["77356.10","0.985"]],"a":[["77367.60","0"],["77367.90","4.190"],["77373.70","0.007"]],"u":101055290,"seq":800573273465},"cts":1787954763979}
{"topic":"orderbook.50.BTCUSDT","type":"delta","ts":1787954764028,"data":{"s":"BTCUSDT","b":[["77356.60","0.002"]],"a":[],"u":101055291,"seq":800573273505},"cts":1787954764027}
{"topic":"orderbook.50.BTCUSDT","type":"delta","ts":1787954764108,"data":{"s":"BTCUSDT","b":[["77356.10","0.970"]],"a":[],"u":101055292,"seq":800573273567},"cts":1787954764107}
{"topic":"orderbook.50.BTCUSDT","type":"delta","ts":1787954764128,"data":{"s":"BTCUSDT","b":[["77364.60","1.784"],["77364.50","0.004"]],"a":[["77367.90","4.188"],["77371.30","14.005"],["77371.40","0.003"]],"u":101055293,"seq":800573273626},"cts":1787954764127}
{"topic":"orderbook.50.BTCUSDT","type":"delta","ts":1787954764148,"data":{"s":"BTCUSDT","b":[["77356.60","0.001"]],"a":[["77370.10","0.002"],["77371.30","14.001"],["77371.40","0.007"],["77373.70","0"]],"u":101055294,"seq":800573273713},"cts":1787954764138}
{"topic":"orderbook.50.BTCUSDT","type":"delta","ts":1787954764209,"data":{"s":"BTCUSDT","b":[],"a":[["77371.30","14.005"],["77371.40","0.003"]],"u":101055295,"seq":800573273841},"cts":1787954764206}
{"topic":"orderbook.50.BTCUSDT","type":"delta","ts":1787954764229,"data":{"s":"BTCUSDT","b":[["77356.20","0.001"],["77356.10","0"]],"a":[],"u":101055296,"seq":800573273903},"cts":1787954764226}
{"topic":"orderbook.50.BTCUSDT","type":"delta","ts":1787954764308,"data":{"s":"BTCUSDT","b":[],"a":[["77368.50","0.002"],["77368.60","0.004"],["77369.20","0"],["77369.70","0"],["77370.60","0.006"],["77373.70","0.007"],["77373.80","0.001"]],"u":101055297,"seq":800573274013},"cts":1787954764307}
{"topic":"orderbook.50.BTCUSDT","type":"delta","ts":1787954764328,"data":{"s":"BTCUSDT","b":[["77356.20","0"],["77356.10","0.970"]],"a":[["77368.60","0.002"],["77371.10","0.131"],["77371.30","14.001"],["77371.40","0.007"],["77371.60","0.003"]],"u":101055298,"seq":800573274066},"cts":1787954764326}
{"topic":"orderbook.50.BTCUSDT","type":"delta","ts":1787954764368,"data":{"s":"BTCUSDT","b":[],"a":[["77370.10","0"],["77372.10","0.707"],["77374.00","0.189"]],"u":101055299,"seq":800573274134},"cts":1787954764363}
{"topic":"orderbook.50.BTCUSDT","type":"delta","ts":1787954764408,"data":{"s":"BTCUSDT","b":[["77364.60","2.496"],["77356.10","0.986"]],"a":[["77364.70","7.966"],["77370.60","0.004"],["77371.10","0"],["77371.40","0.003"],["77371.60","0.001"],["77372.10","0.323"],["77372.90","0.004"]],"u":101055300,"seq":800573274329},"cts":1787954764407}
{"topic":"orderbook.50.BTCUSDT","type":"delta","ts":1787954764428,"data":{"s":"BTCUSDT","b":[["77364.60","2.799"],["77357.10","0.382"],["77356.10","0"]],"a":[["77367.90","0.008"],["77372.90","0"],["77373.50","0.004"]],"u":101055301,"seq":800573274411},"cts":1787954764427}
{"topic":"orderbook.50.BTCUSDT","type":"delta","ts":1787954764468,"data":{"s":"BTCUSDT","b":[["77364.00","0.028"],["77357.20","0.006"],["77356.30","0"]],"a":[["77371.20","0.002"],["77373.50","0"],["77374.10","0.051"]],"u":101055302,"seq":800573274517},"cts":1787954764467}
{"topic":"orderbook.50.BTCUSDT","type":"delta","ts":1787954764489,"data":{"s":"BTCUSDT","b":[["77357.20","0.135"]],"a":[["77372.20","0"],["77374.20","0.003"]],"u":101055303,"seq":800573274552},"cts":1787954764486}
{"topic":"orderbook.50.BTCUSDT","type":"delta","ts":1787954764508,"data":{"s":"BTCUSDT","b":[["77364.60","2.801"],["77356.70","0.499"]],"a":[["77374.20","0.002"]],"u":101055304,"seq":800573274614},"cts":1787954764506}
{"topic":"orderbook.50.BTCUSDT","type":"delta","ts":1787954764528,"data":{"s":"BTCUSDT","b":[],"a":[["77368.80","0"],["77374.40","0.129"]],"u":101055305,"seq":800573274663},"cts":1787954764522}
{"topic":"orderbook.50.BTCUSDT","type":"delta","ts":1787954764548,"data":{"s":"BTCUSDT","b":[],"a":[["77371.20","3.034"],["77371.40","0"],["77374.50","3.893"]],"u":101055306,"seq":800573274707},"cts":1787954764546}
{"topic":"orderbook.50.BTCUSDT","type":"delta","ts":1787954764629,"data":{"s":"BTCUSDT","b":[],"a":[["77371.40","0.003"],["77374.50","0"]],"u":101055307,"seq":800573274793},"cts":1787954764625}
{"topic":"orderbook.50.BTCUSDT","type":"delta","ts":1787954764648,"data":{"s":"BTCUSDT","b":[["77364.60","2.867"]],"a":[["77364.70","7.962"]],"u":101055308,"seq":800573274843},"cts":1787954764646}
{"topic":"orderbook.50.BTCUSDT","type":"delta","ts":1787954764788,"data":{"s":"BTCUSDT","b":[["77358.60","0.074"]],"a":[],"u":101055309,"seq":800573274966},"cts":1787954764787}
{"topic":"orderbook.50.BTCUSDT","type":"delta","ts":1787954764808,"data":{"s":"BTCUSDT","b":[["77358.00","0.008"]],"a":[],"u":101055310,"seq":800573274996},"cts":1787954764807}
{"topic":"orderbook.50.BTCUSDT","type":"delta","ts":1787954764828,"data":{"s":"BTCUSDT","b":[["77364.60","2.881"],["77358.90","0.001"],["77356.90","0.001"]],"a":[],"u":101055311,"seq":800573275026},"cts":1787954764826}
{"topic":"orderbook.50.BTCUSDT","type":"delta","ts":1787954764889,"data":{"s":"BTCUSDT","b":[["77364.30","0.003"],["77364.20","0.005"],["77363.90","0.005"],["77360.90","0.001"],["77356.70","0"],["77356.60","0"],["77356.50","0"],["77356.40","0"]],"a":[],"u":101055312,"seq":800573275103},"cts":1787954764886}
{"topic":"orderbook.50.BTCUSDT","type":"delta","ts":1787954764908,"data":{"s":"BTCUSDT","b":[["77357.20","0"],["77356.70","0.499"]],"a":[],"u":101055313,"seq":800573275133},"cts":1787954764905}
{"topic":"orderbook.50.BTCUSDT","type":"delta","ts":1787954764929,"data":{"s":"BTCUSDT","b":[["77364.60","4.468"]],"a":[["77374.40","0"],["77374.50","4.022"]],"u":101055314,"seq":800573275172},"cts":1787954764922}
{"topic":"orderbook.50.BTCUSDT","type":"delta","ts":1787954765008,"data":{"s":"BTCUSDT","b":[],"a":[["77374.40","0.129"],["77374.50","0"]],"u":101055315,"seq":800573275244},"cts":1787954765006}
{"topic":"orderbook.50.BTCUSDT","type":"delta","ts":1787954765028,"data":{"s":"BTCUSDT","b":[["77363.30","0.014"]],"a":[["77374.40","0"],["77374.50","4.022"]],"u":101055316,"seq":800573275275},"cts":1787954765024}
{"topic":"orderbook.50.BTCUSDT","type":"delta","ts":1787954765048,"data":{"s":"BTCUSDT","b":[],"a":[["77374.40","0.129"],["77374.50","0"]],"u":101055317,"seq":800573275304},"cts":1787954765040}
{"topic":"orderbook.50.BTCUSDT","type":"delta","ts":1787954765068,"data":{"s":"BTCUSDT","b":[],"a":[["77374.40","0"],["77374.50","4.022"]],"u":101055318,"seq":800573275323},"cts":1787954765058}
{"topic":"orderbook.50.BTCUSDT","type":"delta","ts":1787954765088,"data":{"s":"BTCUSDT","b":[],"a":[["77374.40","0.129"],["77374.50","0"]],"u":101055319,"seq":800573275347},"cts":1787954765082}
{"topic":"orderbook.50.BTCUSDT","type":"delta","ts":1787954765108,"data":{"s":"BTCUSDT","b":[],"a":[["77374.40","0"],["77374.50","4.022"]],"u":101055320,"seq":800573275375},"cts":1787954765107}
{"topic":"orderbook.50.BTCUSDT","type":"delta","ts":1787954765128,"data":{"s":"BTCUSDT","b":[],"a":[["77371.70","0"],["77374.40","0.129"],["77374.50","3.893"]],"u":101055321,"seq":800573275400},"cts":1787954765127}
{"topic":"orderbook.50.BTCUSDT","type":"delta","ts":1787954765248,"data":{"s":"BTCUSDT","b":[],"a":[["77364.70","7.938"]],"u":101055322,"seq":800573275523},"cts":1787954765237}
{"topic":"orderbook.50.BTCUSDT","type":"delta","ts":1787954765268,"data":{"s":"BTCUSDT","b":[["77364.60","4.573"]],"a":[],"u":101055323,"seq":800573275551},"cts":1787954765266}
{"topic":"orderbook.50.BTCUSDT","type":"delta","ts":1787954765468,"data":{"s":"BTCUSDT","b":[["77364.60","4.643"]],"a":[],"u":101055324,"seq":800573275698},"cts":1787954765457}
{"topic":"orderbook.50.BTCUSDT","type":"delta","ts":1787954765708,"data":{"s":"BTCUSDT","b":[["77364.60","4.270"]],"a":[["77374.00","0.191"]],"u":101055325,"seq":800573275958},"cts":1787954765706}
{"topic":"orderbook.50.BTCUSDT","type":"delta","ts":1787954765768,"data":{"s":"BTCUSDT","b":[],"a":[["77374.40","0"],["77374.60","14.002"]],"u":101055326,"seq":800573276021},"cts":1787954765767}
{"topic":"orderbook.50.BTCUSDT","type":"delta","ts":1787954765789,"data":{"s":"BTCUSDT","b":[["77364.60","5.114"]],"a":[["77373.70","0.005"],["77374.00","0.189"],["77374.60","14.000"]],"u":101055327,"seq":800573276102},"cts":1787954765785}
{"topic":"orderbook.50.BTCUSDT","type":"delta","ts":1787954765808,"data":{"s":"BTCUSDT","b":[],"a":[["77374.50","4.022"]],"u":101055328,"seq":800573276127},"cts":1787954765806}
{"topic":"orderbook.50.BTCUSDT","type":"delta","ts":1787954765868,"data":{"s":"BTCUSDT","b":[],"a":[["77374.40","0.129"],["77374.50","3.893"],["77374.60","0"]],"u":101055329,"seq":800573276199},"cts":1787954765862}
{"topic":"orderbook.50.BTCUSDT","type":"delta","ts":1787954765888,"data":{"s":"BTCUSDT","b":[],"a":[["77374.40","0"],["77374.60","14.000"]],"u":101055330,"seq":800573276227},"cts":1787954765886}
{"topic":"orderbook.50.BTCUSDT","type":"delta","ts":1787954765909,"data":{"s":"BTCUSDT","b":[],"a":[["77374.40","0.129"],["77374.60","0"]],"u":101055331,"seq":800573276259},"cts":1787954765907}
{"topic":"orderbook.50.BTCUSDT","type":"delta","ts":1787954765929,"data":{"s":"BTCUSDT","b":[],"a":[["77374.40","0"],["77374.60","14.000"]],"u":101055332,"seq":800573276280},"cts":1787954765922}
{"topic":"orderbook.50.BTCUSDT","type":"delta","ts":1787954765948,"data":{"s":"BTCUSDT","b":[],"a":[["77374.40","0.129"],["77374.60","0"]],"u":101055333,"seq":800573276310},"cts":1787954765942}
{"topic":"orderbook.50.BTCUSDT","type":"delta","ts":1787954765969,"data":{"s":"BTCUSDT","b":[],"a":[["77374.40","0"],["77374.60","14.000"]],"u":101055334,"seq":800573276331},"cts":1787954765967}
{"topic":"orderbook.50.BTCUSDT","type":"delta","ts":1787954765989,"data":{"s":"BTCUSDT","b":[],"a":[["77374.40","0.129"],["77374.60","0"]],"u":101055335,"seq":800573276352},"cts":1787954765985}
{"topic":"orderbook.50.BTCUSDT","type":"delta","ts":1787954766008,"data":{"s":"BTCUSDT","b":[["77364.00","0.001"],["77362.30","0.011"]],"a":[["77374.40","0"],["77374.60","14.000"]],"u":101055336,"seq":800573276378},"cts":1787954766006}
{"topic":"orderbook.50.BTCUSDT","type":"delta","ts":1787954766028,"data":{"s":"BTCUSDT","b":[],"a":[["77374.40","0.129"],["77374.60","0"]],"u":101055337,"seq":800573276401},"cts":1787954766021}
{"topic":"orderbook.50.BTCUSDT","type":"delta","ts":1787954766048,"data":{"s":"BTCUSDT","b":[],"a":[["77374.40","0"],["77374.60","14.000"]],"u":101055338,"seq":800573276434},"cts":1787954766048}
{"topic":"orderbook.50.BTCUSDT","type":"delta","ts":1787954766068,"data":{"s":"BTCUSDT","b":[],"a":[["77374.40","0.129"],["77374.60","0"]],"u":101055339,"seq":800573276462},"cts":1787954766067}
{"topic":"orderbook.50.BTCUSDT","type":"delta","ts":1787954766089,"data":{"s":"BTCUSDT","b":[],"a":[["77374.40","0"],["77374.60","14.000"]],"u":101055340,"seq":800573276486},"cts":1787954766084}
{"topic":"orderbook.50.BTCUSDT","type":"delta","ts":1787954766109,"data":{"s":"BTCUSDT","b":[],"a":[["77374.40","0.129"],["77374.60","0"]],"u":101055341,"seq":800573276512},"cts":1787954766106}
{"topic":"orderbook.50.BTCUSDT","type":"delta","ts":1787954766129,"data":{"s":"BTCUSDT","b":[],"a":[["77374.40","0"],["77374.60","14.000"]],"u":101055342,"seq":800573276542},"cts":1787954766123}
{"topic":"orderbook.50.BTCUSDT","type":"delta","ts":1787954766148,"data":{"s":"BTCUSDT","b":[],"a":[["77374.40","0.129"],["77374.60","0"]],"u":101055343,"seq":800573276580},"cts":1787954766143}
{"topic":"orderbook.50.BTCUSDT","type":"delta","ts":1787954766168,"data":{"s":"BTCUSDT","b":[],"a":[["77374.40","0"],["77374.60","14.000"]],"u":101055344,"seq":800573276618},"cts":1787954766165}
{"topic":"orderbook.50.BTCUSDT","type":"delta","ts":1787954766189,"data":{"s":"BTCUSDT","b":[],"a":[["77374.40","0.129"],["77374.60","0"]],"u":101055345,"seq":800573276638},"cts":1787954766181}
{"topic":"orderbook.50.BTCUSDT","type":"delta","ts":1787954766208,"data":{"s":"BTCUSDT","b":[],"a":[["77374.40","0"],["77374.60","14.000"]],"u":101055346,"seq":800573276668},"cts":1787954766205}
{"topic":"orderbook.50.BTCUSDT","type":"delta","ts":1787954766229,"data":{"s":"BTCUSDT","b":[],"a":[["77374.40","0.129"],["77374.60","0"]],"u":101055347,"seq":800573276709},"cts":1787954766221}
{"topic":"orderbook.50.BTCUSDT","type":"delta","ts":1787954766249,"data":{"s":"BTCUSDT","b":[["77359.70","0.376"]],"a":[],"u":101055348,"seq":800573276743},"cts":1787954766246}
{"topic":"orderbook.50.BTCUSDT","type":"delta","ts":1787954766309,"data":{"s":"BTCUSDT","b":[["77364.60","5.245"]],"a":[],"u":101055349,"seq":800573276810},"cts":1787954766305}
{"topic":"orderbook.50.BTCUSDT","type":"delta","ts":1787954766328,"data":{"s":"BTCUSDT","b":[["77359.70","0.408"]],"a":[],"u":101055350,"seq":800573276832},"cts":1787954766319}
{"topic":"orderbook.50.BTCUSDT","type":"delta","ts":1787954767029,"data":{"s":"BTCUSDT","b":[["77364.60","5.115"]],"a":[],"u":101055351,"seq":800573277405},"cts":1787954767022}
{"topic":"orderbook.50.BTCUSDT","type":"delta","ts":1787954767088,"data":{"s":"BTCUSDT","b":[["77359.40","0.273"]],"a":[],"u":101055352,"seq":800573277461},"cts":1787954767087}
{"topic":"orderbook.50.BTCUSDT","type":"delta","ts":1787954767269,"data":{"s":"BTCUSDT","b":[],"a":[["77373.70","0.007"]],"u":101055353,"seq":800573277626},"cts":1787954767266}
{"topic":"orderbook.50.BTCUSDT","type":"delta","ts":1787954767308,"data":{"s":"BTCUSDT","b":[["77356.80","0.179"]],"a":[],"u":101055354,"seq":800573277660},"cts":1787954767306}
{"success":true,"ret_msg":"pong","conn_id":"da7tn48ppdl4sp3gt52g-iavr","req_id":"","op":"ping"}
{"topic":"orderbook.50.BTCUSDT","type":"delta","ts":1787954767588,"data":{"s":"BTCUSDT","b":[],"a":[["77374.30","0.002"],["77374.50","0"]],"u":101055355,"seq":800573277849},"cts":1787954767581}
{"topic":"orderbook.50.BTCUSDT","type":"delta","ts":1787954767609,"data":{"s":"BTCUSDT","b":[["77364.60","5.122"]],"a":[["77374.40","0"],["77374.50","4.022"]],"u":101055356,"seq":800573277896},"cts":1787954767605}
{"topic":"orderbook.50.BTCUSDT","type":"delta","ts":1787954767628,"data":{"s":"BTCUSDT","b":[],"a":[["77374.40","0.129"],["77374.50","0"]],"u":101055357,"seq":800573277914},"cts":1787954767618}
{"topic":"orderbook.50.BTCUSDT","type":"delta","ts":1787954767648,"data":{"s":"BTCUSDT","b":[],"a":[["77364.70","7.709"],["77374.30","0"],["77374.40","0"],["77374.50","3.893"],["77374.60","14.000"]],"u":101055358,"seq":800573277984},"cts":1787954767641}
{"topic":"orderbook.50.BTCUSDT","type":"delta","ts":1787954767688,"data":{"s":"BTCUSDT","b":[],"a":[["77371.20","0.002"],["77374.40","0.129"],["77374.60","0"]],"u":101055359,"seq":800573278054},"cts":1787954767684}
{"topic":"orderbook.50.BTCUSDT","type":"delta","ts":1787954767709,"data":{"s":"BTCUSDT","b":[["77364.60","5.127"]],"a":[["77374.40","0"],["77374.60","14.000"]],"u":101055360,"seq":800573278117},"cts":1787954767706}
{"topic":"orderbook.50.BTCUSDT","type":"delta","ts":1787954767728,"data":{"s":"BTCUSDT","b":[["77364.60","5.161"]],"a":[["77374.40","0.129"],["77374.60","0"]],"u":101055361,"seq":800573278167},"cts":1787954767727}
{"topic":"orderbook.50.BTCUSDT","type":"delta","ts":1787954767748,"data":{"s":"BTCUSDT","b":[],"a":[["77374.40","0"],["77374.60","14.000"]],"u":101055362,"seq":800573278199},"cts":1787954767742}
{"topic":"orderbook.50.BTCUSDT","type":"delta","ts":1787954767768,"data":{"s":"BTCUSDT","b":[],"a":[["77371.40","0"],["77374.40","0.129"],["77374.60","14.003"]],"u":101055363,"seq":800573278247},"cts":1787954767766}
{"topic":"orderbook.50.BTCUSDT","type":"delta","ts":1787954767929,"data":{"s":"BTCUSDT","b":[],"a":[["77374.40","0"],["77374.50","4.022"],["77374.70","0.001"]],"u":101055364,"seq":800573278428},"cts":1787954767922}
{"topic":"orderbook.50.BTCUSDT","type":"delta","ts":1787954767948,"data":{"s":"BTCUSDT","b":[["77357.20","0.006"],["77356.70","0"]],"a":[["77371.20","4.280"]],"u":101055365,"seq":800573278451},"cts":1787954767940}
{"topic":"orderbook.50.BTCUSDT","type":"delta","ts":1787954767968,"data":{"s":"BTCUSDT","b":[["77357.20","0"],["77356.70","0.499"]],"a":[],"u":101055366,"seq":800573278478},"cts":1787954767967}
{"topic":"orderbook.50.BTCUSDT","type":"delta","ts":1787954767989,"data":{"s":"BTCUSDT","b":[["77357.20","0.006"],["77356.70","0"]],"a":[["77374.40","0.129"],["77374.50","3.893"],["77374.70","0"]],"u":101055367,"seq":800573278500},"cts":1787954767980}
{"topic":"orderbook.50.BTCUSDT","type":"delta","ts":1787954768009,"data":{"s":"BTCUSDT","b":[["77357.20","0"],["77356.70","0.499"]],"a":[],"u":101055368,"seq":800573278522},"cts":1787954768004}
{"topic":"orderbook.50.BTCUSDT","type":"delta","ts":1787954768029,"data":{"s":"BTCUSDT","b":[],"a":[["77371.40","0.003"],["77374.60","0"]],"u":101055369,"seq":800573278551},"cts":1787954768023}
{"topic":"orderbook.50.BTCUSDT","type":"delta","ts":1787954768088,"data":{"s":"BTCUSDT","b":[],"a":[["77371.20","0.002"]],"u":101055370,"seq":800573278640},"cts":1787954768087}
{"topic":"orderbook.50.BTCUSDT","type":"delta","ts":1787954768169,"data":{"s":"BTCUSDT","b":[],"a":[["77371.40","0"],["77374.40","0"],["77374.60","14.003"],["77374.70","0.001"]],"u":101055371,"seq":800573278770},"cts":1787954768164}
{"topic":"orderbook.50.BTCUSDT","type":"delta","ts":1787954768208,"data":{"s":"BTCUSDT","b":[["77364.60","5.231"]],"a":[],"u":101055372,"seq":800573278807},"cts":1787954768207}
{"topic":"orderbook.50.BTCUSDT","type":"delta","ts":1787954768248,"data":{"s":"BTCUSDT","b":[["77357.20","0.006"],["77356.70","0"]],"a":[["77364.70","7.719"]],"u":101055373,"seq":800573278894},"cts":1787954768247}
{"topic":"orderbook.50.BTCUSDT","type":"delta","ts":1787954768268,"data":{"s":"BTCUSDT","b":[["77357.20","0"],["77356.70","0.499"]],"a":[],"u":101055374,"seq":800573278922},"cts":1787954768266}
{"topic":"orderbook.50.BTCUSDT","type":"delta","ts":1787954768288,"data":{"s":"BTCUSDT","b":[["77357.20","0.006"],["77356.70","0"]],"a":[],"u":101055375,"seq":800573278962},"cts":1787954768286}
{"topic":"orderbook.50.BTCUSDT","type":"delta","ts":1787954768308,"data":{"s":"BTCUSDT","b":[["77357.20","0"],["77356.70","0.499"]],"a":[],"u":101055376,"seq":800573278997},"cts":1787954768307}
{"topic":"orderbook.50.BTCUSDT","type":"delta","ts":1787954768328,"data":{"s":"BTCUSDT","b":[["77357.20","0.006"],["77356.70","0"]],"a":[["77364.70","7.718"]],"u":101055377,"seq":800573279046},"cts":1787954768327}
{"topic":"orderbook.50.BTCUSDT","type":"delta","ts":1787954768348,"data":{"s":"BTCUSDT","b":[["77357.20","0"],["77356.70","0.499"]],"a":[],"u":101055378,"seq":800573279081},"cts":1787954768346}
{"topic":"orderbook.50.BTCUSDT","type":"delta","ts":1787954768368,"data":{"s":"BTCUSDT","b":[["77357.20","0.006"],["77356.70","0"]],"a":[],"u":101055379,"seq":800573279105},"cts":1787954768363}
{"topic":"orderbook.50.BTCUSDT","type":"delta","ts":1787954768388,"data":{"s":"BTCUSDT","b":[["77357.20","0"],["77356.70","0.499"]],"a":[],"u":101055380,"seq":800573279128},"cts":1787954768386}
{"topic":"orderbook.50.BTCUSDT","type":"delta","ts":1787954768408,"data":{"s":"BTCUSDT","b":[["77357.20","0.006"],["77356.70","0"]],"a":[],"u":101055381,"seq":800573279178},"cts":1787954768407}
{"topic":"orderbook.50.BTCUSDT","type":"delta","ts":1787954768428,"data":{"s":"BTCUSDT","b":[["77357.20","0"],["77356.70","0.499"]],"a":[],"u":101055382,"seq":800573279219},"cts":1787954768427}
{"topic":"orderbook.50.BTCUSDT","type":"delta","ts":1787954768448,"data":{"s":"BTCUSDT","b":[["77357.20","0.006"],["77356.70","0"]],"a":[],"u":101055383,"seq":800573279259},"cts":1787954768445}
{"topic":"orderbook.50.BTCUSDT","type":"delta","ts":1787954768468,"data":{"s":"BTCUSDT","b":[["77359.40","0.224"],["77357.20","0"],["77356.70","0.499"]],"a":[],"u":101055384,"seq":800573279296},"cts":1787954768463}
{"topic":"orderbook.50.BTCUSDT","type":"delta","ts":1787954768508,"data":{"s":"BTCUSDT","b":[["77357.20","0.006"],["77356.70","0"]],"a":[],"u":101055385,"seq":800573279359},"cts":1787954768506}
{"topic":"orderbook.50.BTCUSDT","type":"delta","ts":1787954768529,"data":{"s":"BTCUSDT","b":[["77362.70","1.938"],["77359.80","1.936"],["77357.40","1.936"],["77357.20","0"],["77356.80","0"]],"a":[],"u":101055386,"seq":800573279394},"cts":1787954768522}
{"topic":"orderbook.50.BTCUSDT","type":"delta","ts":1787954768549,"data":{"s":"BTCUSDT","b":[["77363.80","0.009"],["77362.80","0.821"],["77362.60","0.001"],["77359.90","1.696"],["77359.70","0.038"],["77359.40","0.354"],["77358.10","0"],["77357.50","0.775"],["77356.90","0"]],"a":[],"u":101055387,"seq":800573279439},"cts":1787954768542}
{"topic":"orderbook.50.BTCUSDT","type":"delta","ts":1787954768568,"data":{"s":"BTCUSDT","b":[["77362.90","0.007"],["77362.80","1.204"]],"a":[],"u":101055388,"seq":800573279476},"cts":1787954768565}
{"topic":"orderbook.50.BTCUSDT","type":"delta","ts":1787954768588,"data":{"s":"BTCUSDT","b":[["77360.00","0.142"]],"a":[["77367.90","0.002"],["77371.20","0.008"],["77373.70","0.005"],["77374.50","0.002"]],"u":101055389,"seq":800573279570},"cts":1787954768587}
{"topic":"orderbook.50.BTCUSDT","type":"delta","ts":1787954768608,"data":{"s":"BTCUSDT","b":[["77364.60","5.236"],["77357.30","0.002"]],"a":[],"u":101055390,"seq":800573279631},"cts":1787954768607}
{"topic":"orderbook.50.BTCUSDT","type":"delta","ts":1787954768628,"data":{"s":"BTCUSDT","b":[["77358.50","0.371"],["77357.30","0.001"]],"a":[],"u":101055391,"seq":800573279668},"cts":1787954768625}
{"topic":"orderbook.50.BTCUSDT","type":"delta","ts":1787954768648,"data":{"s":"BTCUSDT","b":[["77359.90","1.826"],["77359.40","0.224"],["77359.30","0.001"],["77358.50","0.370"],["77357.00","0"]],"a":[],"u":101055392,"seq":800573279709},"cts":1787954768643}
{"topic":"orderbook.50.BTCUSDT","type":"delta","ts":1787954768668,"data":{"s":"BTCUSDT","b":[],"a":[["77374.60","14.002"]],"u":101055393,"seq":800573279742},"cts":1787954768662}
{"topic":"orderbook.50.BTCUSDT","type":"delta","ts":1787954768708,"data":{"s":"BTCUSDT","b":[["77359.70","0.039"],["77359.30","0"],["77357.00","0.012"]],"a":[["77374.60","14.000"],["77374.70","0.003"]],"u":101055394,"seq":800573279821},"cts":1787954768706}
{"topic":"orderbook.50.BTCUSDT","type":"delta","ts":1787954768728,"data":{"s":"BTCUSDT","b":[],"a":[["77374.50","4.189"]],"u":101055395,"seq":800573279861},"cts":1787954768719}
{"topic":"orderbook.50.BTCUSDT","type":"delta","ts":1787954768808,"data":{"s":"BTCUSDT","b":[],"a":[["77374.60","14.003"],["77374.70","0"],["77374.80","0.001"]],"u":101055396,"seq":800573279940},"cts":1787954768807}
{"topic":"orderbook.50.BTCUSDT","type":"delta","ts":1787954768889,"data":{"s":"BTCUSDT","b":[],"a":[["77374.70","0.001"],["77374.80","0"]],"u":101055397,"seq":800573280034},"cts":1787954768882}
{"topic":"orderbook.50.BTCUSDT","type":"delta","ts":1787954769028,"data":{"s":"BTCUSDT","b":[["77364.60","5.286"]],"a":[],"u":101055398,"seq":800573280268},"cts":1787954769027}
{"topic":"orderbook.50.BTCUSDT","type":"delta","ts":1787954769048,"data":{"s":"BTCUSDT","b":[],"a":[["77364.70","7.704"]],"u":101055399,"seq":800573280359},"cts":1787954769047}
{"topic":"orderbook.50.BTCUSDT","type":"delta","ts":1787954769148,"data":{"s":"BTCUSDT","b":[["77364.40","0.001"],["77357.00","0"]],"a":[],"u":101055400,"seq":800573280484},"cts":1787954769147}
{"topic":"orderbook.50.BTCUSDT","type":"delta","ts":1787954769188,"data":{"s":"BTCUSDT","b":[["77364.40","0"],["77357.00","0.012"]],"a":[["77364.70","7.714"],["77374.40","0.002"],["77374.70","0"]],"u":101055401,"seq":800573280575},"cts":1787954769187}
{"topic":"orderbook.50.BTCUSDT","type":"delta","ts":1787954769208,"data":{"s":"BTCUSDT","b":[["77364.60","5.216"]],"a":[["77372.70","0.002"],["77373.20","0.002"],["77374.50","0"],["77374.60","0"]],"u":101055402,"seq":800573280663},"cts":1787954769207}
{"topic":"orderbook.50.BTCUSDT","type":"delta","ts":1787954769228,"data":{"s":"BTCUSDT","b":[["77364.40","0.001"],["77357.00","0"]],"a":[["77372.70","0"],["77373.20","0"],["77373.40","0.002"],["77374.50","4.189"]],"u":101055403,"seq":800573280724},"cts":1787954769227}
{"topic":"orderbook.50.BTCUSDT","type":"delta","ts":1787954769248,"data":{"s":"BTCUSDT","b":[],"a":[["77373.40","0"],["77373.60","0.003"],["77374.60","14.003"]],"u":101055404,"seq":800573280765},"cts":1787954769242}
{"topic":"orderbook.50.BTCUSDT","type":"delta","ts":1787954769269,"data":{"s":"BTCUSDT","b":[],"a":[["77373.10","0.004"]],"u":101055405,"seq":800573280807},"cts":1787954769266}
{"topic":"orderbook.50.BTCUSDT","type":"delta","ts":1787954769288,"data":{"s":"BTCUSDT","b":[],"a":[["77374.60","14.000"]],"u":101055406,"seq":800573280835},"cts":1787954769286}
{"topic":"orderbook.50.BTCUSDT","type":"delta","ts":1787954769309,"data":{"s":"BTCUSDT","b":[],"a":[["77374.60","14.002"]],"u":101055407,"seq":800573280868},"cts":1787954769305}
{"topic":"orderbook.50.BTCUSDT","type":"delta","ts":1787954769348,"data":{"s":"BTCUSDT","b":[["77364.60","5.217"],["77364.40","0"],["77357.00","0.012"]],"a":[],"u":101055408,"seq":800573280938},"cts":1787954769347}
{"topic":"orderbook.50.BTCUSDT","type":"delta","ts":1787954769369,"data":{"s":"BTCUSDT","b":[["77364.60","5.216"]],"a":[],"u":101055409,"seq":800573280992},"cts":1787954769364}
{"topic":"orderbook.50.BTCUSDT","type":"delta","ts":1787954769388,"data":{"s":"BTCUSDT","b":[["77364.60","5.287"],["77362.50","0.372"]],"a":[["77373.10","0.002"],["77373.60","0.001"],["77373.70","0.003"],["77374.00","0.001"],["77374.40","0"],["77374.60","14.003"],["77374.70","0.001"]],"u":101055410,"seq":800573281127},"cts":1787954769387}
{"topic":"orderbook.50.BTCUSDT","type":"delta","ts":1787954769408,"data":{"s":"BTCUSDT","b":[["77364.60","5.286"],["77364.50","0.005"],["77362.90","0.009"],["77362.50","0.370"],["77362.30","0.010"]],"a":[["77364.70","7.669"]],"u":101055411,"seq":800573281249},"cts":1787954769407}
{"topic":"orderbook.50.BTCUSDT","type":"delta","ts":1787954769429,"data":{"s":"BTCUSDT","b":[],"a":[["77371.20","0.007"]],"u":101055412,"seq":800573281317},"cts":1787954769427}
{"topic":"orderbook.50.BTCUSDT","type":"delta","ts":1787954769449,"data":{"s":"BTCUSDT","b":[["77364.60","5.287"]],"a":[],"u":101055413,"seq":800573281366},"cts":1787954769447}
{"topic":"orderbook.50.BTCUSDT","type":"delta","ts":1787954769468,"data":{"s":"BTCUSDT","b":[["77364.60","5.286"]],"a":[],"u":101055414,"seq":800573281419},"cts":1787954769467}
{"topic":"orderbook.50.BTCUSDT","type":"delta","ts":1787954769608,"data":{"s":"BTCUSDT","b":[["77357.00","0.270"]],"a":[],"u":101055415,"seq":800573281667},"cts":1787954769606}
{"topic":"orderbook.50.BTCUSDT","type":"delta","ts":1787954769728,"data":{"s":"BTCUSDT","b":[["77357.00","0.012"]],"a":[],"u":101055416,"seq":800573281816},"cts":1787954769726}
{"topic":"orderbook.50.BTCUSDT","type":"delta","ts":1787954769789,"data":{"s":"BTCUSDT","b":[["77357.00","0.270"]],"a":[],"u":101055417,"seq":800573281908},"cts":1787954769786}
{"topic":"orderbook.50.BTCUSDT","type":"delta","ts":1787954769808,"data":{"s":"BTCUSDT","b":[["77357.00","0.012"]],"a":[],"u":101055418,"seq":800573281969},"cts":1787954769807}
{"topic":"orderbook.50.BTCUSDT","type":"delta","ts":1787954769948,"data":{"s":"BTCUSDT","b":[["77357.20","0.258"],["77357.00","0"]],"a":[],"u":101055419,"seq":800573282169},"cts":1787954769941}
{"topic":"orderbook.50.BTCUSDT","type":"delta","ts":1787954769968,"data":{"s":"BTCUSDT","b":[["77363.30","0.007"]],"a":[],"u":101055420,"seq":800573282197},"cts":1787954769965}
{"topic":"orderbook.50.BTCUSDT","type":"delta","ts":1787954769988,"data":{"s":"BTCUSDT","b":[["77364.60","5.287"],["77363.30","0"],["77362.40","0"],["77357.00","0.012"],["77356.90","0.001"]],"a":[],"u":101055421,"seq":800573282234},"cts":1787954769984}
{"topic":"orderbook.50.BTCUSDT","type":"delta","ts":1787954770008,"data":{"s":"BTCUSDT","b":[["77364.60","5.286"],["77363.80","0.003"],["77360.10","1.039"]],"a":[],"u":101055422,"seq":800573282290},"cts":1787954770006}
{"topic":"orderbook.50.BTCUSDT","type":"delta","ts":1787954770029,"data":{"s":"BTCUSDT","b":[["77360.20","0.129"],["77360.00","0.013"],["77358.00","0.001"],["77357.20","0"],["77357.10","0.640"]],"a":[],"u":101055423,"seq":800573282319},"cts":1787954770016}
{"topic":"orderbook.50.BTCUSDT","type":"delta","ts":1787954770048,"data":{"s":"BTCUSDT","b":[["77360.60","0"],["77358.60","0.069"],["77356.80","0.179"]],"a":[["77364.70","7.662"]],"u":101055424,"seq":800573282403},"cts":1787954770046}
{"topic":"orderbook.50.BTCUSDT","type":"delta","ts":1787954770068,"data":{"s":"BTCUSDT","b":[["77363.90","0"],["77356.70","0.369"]],"a":[["77364.70","7.645"]],"u":101055425,"seq":800573282462},"cts":1787954770066}
{"topic":"orderbook.50.BTCUSDT","type":"delta","ts":1787954770088,"data":{"s":"BTCUSDT","b":[["77362.30","0"],["77356.60","0.001"]],"a":[["77364.70","7.632"]],"u":101055426,"seq":800573282504},"cts":1787954770084}
{"topic":"orderbook.50.BTCUSDT","type":"delta","ts":1787954770128,"data":{"s":"BTCUSDT","b":[["77360.70","0"],["77356.50","0.001"]],"a":[["77364.70","7.627"]],"u":101055427,"seq":800573282568},"cts":1787954770120}
{"topic":"orderbook.50.BTCUSDT","type":"delta","ts":1787954770148,"data":{"s":"BTCUSDT","b":[["77361.00","0.017"]],"a":[["77364.70","7.622"],["77372.50","0.048"],["77374.70","0"]],"u":101055428,"seq":800573282629},"cts":1787954770143}
{"topic":"orderbook.50.BTCUSDT","type":"delta","ts":1787954770169,"data":{"s":"BTCUSDT","b":[["77364.60","5.277"]],"a":[["77364.70","7.602"]],"u":101055429,"seq":800573282693},"cts":1787954770162}
{"topic":"orderbook.50.BTCUSDT","type":"delta","ts":1787954770188,"data":{"s":"BTCUSDT","b":[],"a":[["77364.70","7.600"]],"u":101055430,"seq":800573282706},"cts":1787954770178}
{"topic":"orderbook.50.BTCUSDT","type":"delta","ts":1787954770208,"data":{"s":"BTCUSDT","b":[["77362.90","0.138"],["77360.20","0"],["77357.20","0.258"],["77357.10","0.382"]],"a":[["77364.70","7.588"]],"u":101055431,"seq":800573282774},"cts":1787954770205}
{"topic":"orderbook.50.BTCUSDT","type":"delta","ts":1787954770228,"data":{"s":"BTCUSDT","b":[["77362.90","0.009"],["77360.20","0.129"],["77358.00","0"],["77357.00","0.001"]],"a":[],"u":101055432,"seq":800573282816},"cts":1787954770226}
{"topic":"orderbook.50.BTCUSDT","type":"delta","ts":1787954770249,"data":{"s":"BTCUSDT","b":[],"a":[["77364.70","7.581"]],"u":101055433,"seq":800573282853},"cts":1787954770246}
{"topic":"orderbook.50.BTCUSDT","type":"delta","ts":1787954770309,"data":{"s":"BTCUSDT","b":[["77357.20","0"],["77357.10","0.640"],["77356.40","0.397"]],"a":[["77364.70","7.564"]],"u":101055434,"seq":800573282923},"cts":1787954770305}
{"topic":"orderbook.50.BTCUSDT","type":"delta","ts":1787954770328,"data":{"s":"BTCUSDT","b":[["77357.10","0.382"],["77357.00","0.259"]],"a":[],"u":101055435,"seq":800573282976},"cts":1787954770326}
{"topic":"orderbook.50.BTCUSDT","type":"delta","ts":1787954770348,"data":{"s":"BTCUSDT","b":[],"a":[["77364.70","7.562"]],"u":101055436,"seq":800573283032},"cts":1787954770346}
{"topic":"orderbook.50.BTCUSDT","type":"delta","ts":1787954770408,"data":{"s":"BTCUSDT","b":[["77357.00","0.001"],["77356.90","0.259"]],"a":[],"u":101055437,"seq":800573283076},"cts":1787954770405}
{"topic":"orderbook.50.BTCUSDT","type":"delta","ts":1787954770449,"data":{"s":"BTCUSDT","b":[["77362.90","0.138"],["77360.20","0"],["77356.30","0.001"]],"a":[],"u":101055438,"seq":800573283187},"cts":1787954770447}
{"topic":"orderbook.50.BTCUSDT","type":"delta","ts":1787954770469,"data":{"s":"BTCUSDT","b":[],"a":[["77364.70","7.561"]],"u":101055439,"seq":800573283230},"cts":1787954770463}
{"topic":"orderbook.50.BTCUSDT","type":"delta","ts":1787954770488,"data":{"s":"BTCUSDT","b":[["77362.90","0.009"]],"a":[],"u":101055440,"seq":800573283297},"cts":1787954770487}
{"topic":"orderbook.50.BTCUSDT","type":"delta","ts":1787954770508,"data":{"s":"BTCUSDT","b":[["77362.90","0.138"],["77357.20","0.258"],["77356.90","0.001"],["77356.30","0"]],"a":[],"u":101055441,"seq":800573283362},"cts":1787954770507}
{"topic":"orderbook.50.BTCUSDT","type":"delta","ts":1787954770528,"data":{"s":"BTCUSDT","b":[["77362.90","0.009"],["77360.20","0.129"],["77357.20","0"],["77357.00","0.259"]],"a":[],"u":101055442,"seq":800573283417},"cts":1787954770525}
{"topic":"orderbook.50.BTCUSDT","type":"delta","ts":1787954770568,"data":{"s":"BTCUSDT","b":[["77357.00","0.001"],["77356.70","0.627"]],"a":[],"u":101055443,"seq":800573283483},"cts":1787954770563}
{"topic":"orderbook.50.BTCUSDT","type":"delta","ts":1787954770649,"data":{"s":"BTCUSDT","b":[["77362.90","0.138"],["77360.20","0"],["77358.00","0.258"],["77356.70","0.369"]],"a":[["77371.20","0.001"],["77374.40","0.006"],["77374.60","0"]],"u":101055444,"seq":800573283654},"cts":1787954770646}
{"topic":"orderbook.50.BTCUSDT","type":"delta","ts":1787954770668,"data":{"s":"BTCUSDT","b":[],"a":[["77374.40","0"],["77374.60","14.003"]],"u":101055445,"seq":800573283683},"cts":1787954770661}
{"topic":"orderbook.50.BTCUSDT","type":"delta","ts":1787954770688,"data":{"s":"BTCUSDT","b":[["77362.90","0.009"],["77360.20","0.129"],["77358.00","0"],["77357.20","0.258"],["77356.40","0"]],"a":[["77371.20","0.007"]],"u":101055446,"seq":800573283737},"cts":1787954770687}
{"topic":"orderbook.50.BTCUSDT","type":"delta","ts":1787954770788,"data":{"s":"BTCUSDT","b":[["77364.60","5.272"],["77357.20","0"],["77357.00","0.259"],["77356.40","0.397"]],"a":[],"u":101055447,"seq":800573283857},"cts":1787954770787}
{"topic":"orderbook.50.BTCUSDT","type":"delta","ts":1787954770808,"data":{"s":"BTCUSDT","b":[["77364.60","5.403"],["77357.10","0.640"],["77357.00","0.001"]],"a":[],"u":101055448,"seq":800573283938},"cts":1787954770805}
{"topic":"orderbook.50.BTCUSDT","type":"delta","ts":1787954770828,"data":{"s":"BTCUSDT","b":[["77364.60","5.408"]],"a":[],"u":101055449,"seq":800573283976},"cts":1787954770825}
{"topic":"orderbook.50.BTCUSDT","type":"delta","ts":1787954770908,"data":{"s":"BTCUSDT","b":[["77357.10","0.382"],["77357.00","0.259"]],"a":[],"u":101055450,"seq":800573284037},"cts":1787954770907}
{"topic":"orderbook.50.BTCUSDT","type":"delta","ts":1787954771068,"data":{"s":"BTCUSDT","b":[],"a":[["77365.00","0.034"]],"u":101055451,"seq":800573284240},"cts":1787954771066}
{"topic":"orderbook.50.BTCUSDT","type":"delta","ts":1787954771088,"data":{"s":"BTCUSDT","b":[["77364.60","5.508"]],"a":[["77364.70","7.558"]],"u":101055452,"seq":800573284264},"cts":1787954771087}
{"topic":"orderbook.50.BTCUSDT","type":"delta","ts":1787954771108,"data":{"s":"BTCUSDT","b":[["77364.60","5.509"],["77357.00","0.001"],["77356.90","0.259"]],"a":[],"u":101055453,"seq":800573284295},"cts":1787954771107}
{"topic":"orderbook.50.BTCUSDT","type":"delta","ts":1787954771209,"data":{"s":"BTCUSDT","b":[["77357.10","0.640"],["77356.90","0.001"]],"a":[],"u":101055454,"seq":800573284372},"cts":1787954771205}
{"topic":"orderbook.50.BTCUSDT","type":"delta","ts":1787954771248,"data":{"s":"BTCUSDT","b":[["77364.60","5.409"],["77357.10","0.382"],["77356.90","0.259"]],"a":[],"u":101055455,"seq":800573284481},"cts":1787954771242}
{"topic":"orderbook.50.BTCUSDT","type":"delta","ts":1787954771308,"data":{"s":"BTCUSDT","b":[["77356.90","0.001"],["77356.70","0.627"]],"a":[],"u":101055456,"seq":800573284561},"cts":1787954771308}
{"topic":"orderbook.50.BTCUSDT","type":"delta","ts":1787954771328,"data":{"s":"BTCUSDT","b":[["77364.60","5.410"]],"a":[],"u":101055457,"seq":800573284598},"cts":1787954771327}
{"topic":"orderbook.50.BTCUSDT","type":"delta","ts":1787954771409,"data":{"s":"BTCUSDT","b":[["77357.10","0.640"],["77356.70","0.369"]],"a":[],"u":101055458,"seq":800573284691},"cts":1787954771405}
{"topic":"orderbook.50.BTCUSDT","type":"delta","ts":1787954771448,"data":{"s":"BTCUSDT","b":[["77364.60","5.409"]],"a":[],"u":101055459,"seq":800573284773},"cts":1787954771444}
{"topic":"orderbook.50.BTCUSDT","type":"delta","ts":1787954771468,"data":{"s":"BTCUSDT","b":[["77357.10","0.382"],["77357.00","0.259"]],"a":[],"u":101055460,"seq":800573284791},"cts":1787954771467}
{"topic":"orderbook.50.BTCUSDT","type":"delta","ts":1787954771508,"data":{"s":"BTCUSDT","b":[["77357.10","0.640"],["77357.00","0.001"]],"a":[],"u":101055461,"seq":800573284834},"cts":1787954771507}
{"topic":"orderbook.50.BTCUSDT","type":"delta","ts":1787954771529,"data":{"s":"BTCUSDT","b":[["77357.10","0.382"],["77357.00","0.259"]],"a":[],"u":101055462,"seq":800573284870},"cts":1787954771526}
{"topic":"orderbook.50.BTCUSDT","type":"delta","ts":1787954771568,"data":{"s":"BTCUSDT","b":[["77357.50","1.033"],["77357.00","0.001"]],"a":[],"u":101055463,"seq":800573284977},"cts":1787954771567}
{"topic":"orderbook.50.BTCUSDT","type":"delta","ts":1787954771588,"data":{"s":"BTCUSDT","b":[["77362.90","0.138"],["77360.20","0"],["77356.30","0.001"]],"a":[],"u":101055464,"seq":800573285019},"cts":1787954771582}
{"topic":"orderbook.50.BTCUSDT","type":"delta","ts":1787954771609,"data":{"s":"BTCUSDT","b":[["77364.60","5.415"],["77357.50","0.775"],["77357.40","2.194"]],"a":[],"u":101055465,"seq":800573285069},"cts":1787954771606}
{"topic":"orderbook.50.BTCUSDT","type":"delta","ts":1787954771668,"data":{"s":"BTCUSDT","b":[["77364.60","5.409"],["77362.90","0.009"],["77360.20","0.129"],["77357.60","0.372"],["77357.40","1.936"],["77357.20","0.258"],["77356.70","0"],["77356.30","0"]],"a":[],"u":101055466,"seq":800573285153},"cts":1787954771666}
{"topic":"orderbook.50.BTCUSDT","type":"delta","ts":1787954771768,"data":{"s":"BTCUSDT","b":[["77357.20","0"],["77357.00","0.259"],["77356.30","0.001"]],"a":[],"u":101055467,"seq":800573285292},"cts":1787954771765}
{"topic":"orderbook.50.BTCUSDT","type":"delta","ts":1787954771808,"data":{"s":"BTCUSDT","b":[["77357.10","0.640"],["77357.00","0.001"]],"a":[],"u":101055468,"seq":800573285336},"cts":1787954771805}
{"topic":"orderbook.50.BTCUSDT","type":"delta","ts":1787954771908,"data":{"s":"BTCUSDT","b":[["77357.10","0.382"],["77356.70","0.258"],["77356.30","0"]],"a":[],"u":101055469,"seq":800573285497},"cts":1787954771905}
{"topic":"orderbook.50.BTCUSDT","type":"delta","ts":1787954772048,"data":{"s":"BTCUSDT","b":[["77356.70","0"],["77356.60","0.259"],["77356.30","0.001"]],"a":[],"u":101055470,"seq":800573285710},"cts":1787954772047}
{"topic":"orderbook.50.BTCUSDT","type":"delta","ts":1787954772129,"data":{"s":"BTCUSDT","b":[["77362.90","0.379"],["77362.50","0"],["77358.50","0"],["77357.60","0.002"],["77356.60","0.001"],["77356.10","1.533"],["77356.00","0.001"]],"a":[["77371.20","0.008"],["77372.90","0.002"],["77373.70","0.005"],["77374.60","0"]],"u":101055471,"seq":800573285895},"cts":1787954772128}
{"topic":"orderbook.50.BTCUSDT","type":"delta","ts":1787954772149,"data":{"s":"BTCUSDT","b":[["77364.60","5.539"],["77360.20","0"],["77355.80","0.245"]],"a":[["77367.90","0.008"],["77371.20","3.732"]],"u":101055472,"seq":800573285950},"cts":1787954772146}
{"topic":"orderbook.50.BTCUSDT","type":"delta","ts":1787954772168,"data":{"s":"BTCUSDT","b":[["77364.60","5.534"],["77360.20","0.370"],["77355.80","0"]],"a":[["77372.90","0"],["77374.60","14.003"]],"u":101055473,"seq":800573286013},"cts":1787954772166}
{"topic":"orderbook.50.BTCUSDT","type":"delta","ts":1787954772189,"data":{"s":"BTCUSDT","b":[],"a":[["77373.70","0.007"]],"u":101055474,"seq":800573286034},"cts":1787954772184}
{"topic":"orderbook.50.BTCUSDT","type":"delta","ts":1787954772209,"data":{"s":"BTCUSDT","b":[],"a":[["77367.90","0.002"],["77371.10","0.006"],["77374.60","0"]],"u":101055475,"seq":800573286074},"cts":1787954772206}
{"topic":"orderbook.50.BTCUSDT","type":"delta","ts":1787954772229,"data":{"s":"BTCUSDT","b":[["77360.30","0.129"],["77356.00","0"]],"a":[["77371.40","0.003"],["77374.50","0"]],"u":101055476,"seq":800573286115},"cts":1787954772223}
{"topic":"orderbook.50.BTCUSDT","type":"delta","ts":1787954772348,"data":{"s":"BTCUSDT","b":[["77360.30","0"],["77356.00","0.001"]],"a":[],"u":101055477,"seq":800573286253},"cts":1787954772343}
{"topic":"orderbook.50.BTCUSDT","type":"delta","ts":1787954772429,"data":{"s":"BTCUSDT","b":[["77356.20","0.251"],["77356.00","0"]],"a":[],"u":101055478,"seq":800573286351},"cts":1787954772427}
{"topic":"orderbook.50.BTCUSDT","type":"delta","ts":1787954772448,"data":{"s":"BTCUSDT","b":[["77364.60","5.533"]],"a":[],"u":101055479,"seq":800573286399},"cts":1787954772445}
{"topic":"orderbook.50.BTCUSDT","type":"delta","ts":1787954772468,"data":{"s":"BTCUSDT","b":[["77364.60","5.534"]],"a":[],"u":101055480,"seq":800573286443},"cts":1787954772464}
{"topic":"orderbook.50.BTCUSDT","type":"delta","ts":1787954772489,"data":{"s":"BTCUSDT","b":[["77364.60","5.539"]],"a":[],"u":101055481,"seq":800573286478},"cts":1787954772486}
{"topic":"orderbook.50.BTCUSDT","type":"delta","ts":1787954772508,"data":{"s":"BTCUSDT","b":[["77364.60","5.540"]],"a":[],"u":101055482,"seq":800573286520},"cts":1787954772506}
{"topic":"orderbook.50.BTCUSDT","type":"delta","ts":1787954772528,"data":{"s":"BTCUSDT","b":[["77364.60","5.539"]],"a":[["77364.70","7.564"],["77374.00","0.003"]],"u":101055483,"seq":800573286558},"cts":1787954772524}
{"topic":"orderbook.50.BTCUSDT","type":"delta","ts":1787954772569,"data":{"s":"BTCUSDT","b":[["77364.60","5.538"]],"a":[],"u":101055484,"seq":800573286663},"cts":1787954772565}
{"topic":"orderbook.50.BTCUSDT","type":"delta","ts":1787954772629,"data":{"s":"BTCUSDT","b":[["77364.60","5.539"]],"a":[["77374.00","0.001"]],"u":101055485,"seq":800573286805},"cts":1787954772626}
{"topic":"orderbook.50.BTCUSDT","type":"delta","ts":1787954772649,"data":{"s":"BTCUSDT","b":[],"a":[["77374.20","0.004"]],"u":101055486,"seq":800573286837},"cts":1787954772644}
{"topic":"orderbook.50.BTCUSDT","type":"delta","ts":1787954772688,"data":{"s":"BTCUSDT","b":[],"a":[["77373.50","0.002"],["77374.20","0"]],"u":101055487,"seq":800573286877},"cts":1787954772686}
{"topic":"orderbook.50.BTCUSDT","type":"delta","ts":1787954772768,"data":{"s":"BTCUSDT","b":[],"a":[["77364.70","7.352"],["77373.50","0"],["77374.20","0.002"]],"u":101055488,"seq":800573286989},"cts":1787954772767}
{"topic":"orderbook.50.BTCUSDT","type":"delta","ts":1787954772788,"data":{"s":"BTCUSDT","b":[],"a":[["77364.70","7.565"],["77373.20","0.002"],["77374.20","0"]],"u":101055489,"seq":800573287037},"cts":1787954772787}
{"topic":"orderbook.50.BTCUSDT","type":"delta","ts":1787954772808,"data":{"s":"BTCUSDT","b":[["77364.60","5.538"]],"a":[],"u":101055490,"seq":800573287086},"cts":1787954772805}
{"topic":"orderbook.50.BTCUSDT","type":"delta","ts":1787954772828,"data":{"s":"BTCUSDT","b":[],"a":[["77373.20","0"],["77373.40","0.002"]],"u":101055491,"seq":800573287127},"cts":1787954772825}
{"topic":"orderbook.50.BTCUSDT","type":"delta","ts":1787954772909,"data":{"s":"BTCUSDT","b":[["77364.60","5.539"],["77364.50","0.004"]],"a":[["77364.70","7.540"]],"u":101055492,"seq":800573287204},"cts":1787954772901}
{"topic":"orderbook.50.BTCUSDT","type":"delta","ts":1787954772928,"data":{"s":"BTCUSDT","b":[],"a":[["77372.90","0.002"],["77374.10","0"]],"u":101055493,"seq":800573287246},"cts":1787954772925}
{"topic":"orderbook.50.BTCUSDT","type":"delta","ts":1787954772948,"data":{"s":"BTCUSDT","b":[["77359.40","0.211"]],"a":[["77367.90","0.008"],["77371.10","0"],["77372.90","0"],["77374.10","0.051"],["77374.20","0.002"]],"u":101055494,"seq":800573287293},"cts":1787954772944}
{"topic":"orderbook.50.BTCUSDT","type":"delta","ts":1787954772968,"data":{"s":"BTCUSDT","b":[],"a":[["77367.90","0.002"],["77371.10","0.006"],["77373.40","0"],["77373.90","0.002"],["77374.20","0"]],"u":101055495,"seq":800573287331},"cts":1787954772967}
{"topic":"orderbook.50.BTCUSDT","type":"delta","ts":1787954772989,"data":{"s":"BTCUSDT","b":[["77360.20","0.499"]],"a":[],"u":101055496,"seq":800573287363},"cts":1787954772985}
{"topic":"orderbook.50.BTCUSDT","type":"delta","ts":1787954773029,"data":{"s":"BTCUSDT","b":[["77360.20","0.370"]],"a":[["77367.90","0.008"],["77371.10","0"],["77373.40","0.002"]],"u":101055497,"seq":800573287435},"cts":1787954773026}
{"topic":"orderbook.50.BTCUSDT","type":"delta","ts":1787954773048,"data":{"s":"BTCUSDT","b":[["77364.60","5.625"]],"a":[["77373.40","0"],["77373.90","0"],["77374.20","0.002"],["77374.30","0.002"]],"u":101055498,"seq":800573287481},"cts":1787954773044}
{"topic":"orderbook.50.BTCUSDT","type":"delta","ts":1787954773068,"data":{"s":"BTCUSDT","b":[["77359.40","0.209"]],"a":[["77374.30","0"],["77374.50","4.189"]],"u":101055499,"seq":800573287500},"cts":1787954773066}
{"topic":"orderbook.50.BTCUSDT","type":"delta","ts":1787954773108,"data":{"s":"BTCUSDT","b":[["77360.30","0.129"],["77356.10","0"]],"a":[["77367.90","0.002"],["77371.10","0.006"],["77374.50","0"]],"u":101055500,"seq":800573287543},"cts":1787954773105}
{"topic":"orderbook.50.BTCUSDT","type":"delta","ts":1787954773128,"data":{"s":"BTCUSDT","b":[["77360.30","0"],["77356.10","1.533"]],"a":[],"u":101055501,"seq":800573287575},"cts":1787954773125}
{"topic":"orderbook.50.BTCUSDT","type":"delta","ts":1787954773169,"data":{"s":"BTCUSDT","b":[["77364.60","5.649"]],"a":[],"u":101055502,"seq":800573287640},"cts":1787954773165}
{"topic":"orderbook.50.BTCUSDT","type":"delta","ts":1787954773189,"data":{"s":"BTCUSDT","b":[],"a":[["77367.90","0.008"],["77371.10","0"],["77374.50","4.189"]],"u":101055503,"seq":800573287659},"cts":1787954773183}
{"topic":"orderbook.50.BTCUSDT","type":"delta","ts":1787954773208,"data":{"s":"BTCUSDT","b":[["77357.60","0.372"]],"a":[],"u":101055504,"seq":800573287700},"cts":1787954773207}
{"topic":"orderbook.50.BTCUSDT","type":"delta","ts":1787954773228,"data":{"s":"BTCUSDT","b":[["77360.30","0.129"],["77356.10","0"]],"a":[["77367.90","0.002"],["77371.10","0.006"],["77371.20","0.002"],["77374.50","0"]],"u":101055505,"seq":800573287772},"cts":1787954773219}
{"topic":"orderbook.50.BTCUSDT","type":"delta","ts":1787954773248,"data":{"s":"BTCUSDT","b":[["77360.60","0.129"],["77360.30","0"]],"a":[],"u":101055506,"seq":800573287836},"cts":1787954773243}
{"topic":"orderbook.50.BTCUSDT","type":"delta","ts":1787954773268,"data":{"s":"BTCUSDT","b":[["77360.60","0"],["77360.30","0.129"]],"a":[],"u":101055507,"seq":800573287894},"cts":1787954773266}
{"topic":"orderbook.50.BTCUSDT","type":"delta","ts":1787954773308,"data":{"s":"BTCUSDT","b":[],"a":[["77371.10","0"],["77371.20","0.008"],["77371.40","0"],["77374.50","4.189"],["77374.60","14.043"]],"u":101055508,"seq":800573287952},"cts":1787954773306}
{"topic":"orderbook.50.BTCUSDT","type":"delta","ts":1787954773328,"data":{"s":"BTCUSDT","b":[["77364.60","5.650"]],"a":[],"u":101055509,"seq":800573288013},"cts":1787954773327}
{"topic":"orderbook.50.BTCUSDT","type":"delta","ts":1787954773389,"data":{"s":"BTCUSDT","b":[],"a":[["77374.60","14.044"]],"u":101055510,"seq":800573288078},"cts":1787954773382}
{"topic":"orderbook.50.BTCUSDT","type":"delta","ts":1787954773508,"data":{"s":"BTCUSDT","b":[["77359.80","1.937"],["77359.70","0.038"]],"a":[["77374.60","14.046"]],"u":101055511,"seq":800573288210},"cts":1787954773507}
{"topic":"orderbook.50.BTCUSDT","type":"delta","ts":1787954773528,"data":{"s":"BTCUSDT","b":[["77364.60","5.663"]],"a":[],"u":101055512,"seq":800573288253},"cts":1787954773526}
{"topic":"orderbook.50.BTCUSDT","type":"delta","ts":1787954773628,"data":{"s":"BTCUSDT","b":[["77364.60","5.667"]],"a":[],"u":101055513,"seq":800573288409},"cts":1787954773623}
{"topic":"orderbook.50.BTCUSDT","type":"delta","ts":1787954773649,"data":{"s":"BTCUSDT","b":[["77364.60","5.666"],["77360.30","0"],["77356.10","1.533"]],"a":[],"u":101055514,"seq":800573288463},"cts":1787954773644}
{"topic":"orderbook.50.BTCUSDT","type":"delta","ts":1787954773669,"data":{"s":"BTCUSDT","b":[["77360.30","0.129"],["77356.10","0"]],"a":[],"u":101055515,"seq":800573288514},"cts":1787954773666}
{"topic":"orderbook.50.BTCUSDT","type":"delta","ts":1787954773688,"data":{"s":"BTCUSDT","b":[["77364.60","5.644"],["77360.30","0"],["77356.10","1.533"]],"a":[],"u":101055516,"seq":800573288564},"cts":1787954773683}
{"topic":"orderbook.50.BTCUSDT","type":"delta","ts":1787954773708,"data":{"s":"BTCUSDT","b":[["77364.60","5.643"],["77360.30","0.129"],["77356.10","0"]],"a":[],"u":101055517,"seq":800573288628},"cts":1787954773706}
{"topic":"orderbook.50.BTCUSDT","type":"delta","ts":1787954773728,"data":{"s":"BTCUSDT","b":[["77360.30","0"],["77356.10","1.533"]],"a":[],"u":101055518,"seq":800573288686},"cts":1787954773724}
{"topic":"orderbook.50.BTCUSDT","type":"delta","ts":1787954773748,"data":{"s":"BTCUSDT","b":[["77360.30","0.129"],["77356.10","0"]],"a":[],"u":101055519,"seq":800573288741},"cts":1787954773742}
{"topic":"orderbook.50.BTCUSDT","type":"delta","ts":1787954773768,"data":{"s":"BTCUSDT","b":[["77360.30","0"],["77356.10","1.533"]],"a":[],"u":101055520,"seq":800573288817},"cts":1787954773767}
{"topic":"orderbook.50.BTCUSDT","type":"delta","ts":1787954773788,"data":{"s":"BTCUSDT","b":[["77360.30","0.129"],["77356.10","0"]],"a":[],"u":101055521,"seq":800573288853},"cts":1787954773782}
{"topic":"orderbook.50.BTCUSDT","type":"delta","ts":1787954773808,"data":{"s":"BTCUSDT","b":[["77360.30","0"],["77359.80","1.936"],["77359.70","0.039"],["77356.10","1.533"]],"a":[],"u":101055522,"seq":800573288911},"cts":1787954773805}
{"topic":"orderbook.50.BTCUSDT","type":"delta","ts":1787954773828,"data":{"s":"BTCUSDT","b":[["77364.60","5.642"],["77360.30","0.129"],["77356.10","0"]],"a":[["77373.90","0.002"],["77374.60","0"]],"u":101055523,"seq":800573288962},"cts":1787954773827}
{"topic":"orderbook.50.BTCUSDT","type":"delta","ts":1787954773849,"data":{"s":"BTCUSDT","b":[["77360.30","0"],["77356.10","1.533"]],"a":[],"u":101055524,"seq":800573289013},"cts":1787954773843}
{"topic":"orderbook.50.BTCUSDT","type":"delta","ts":1787954773868,"data":{"s":"BTCUSDT","b":[["77360.30","0.129"],["77356.10","0"]],"a":[],"u":101055525,"seq":800573289066},"cts":1787954773863}
{"topic":"orderbook.50.BTCUSDT","type":"delta","ts":1787954773889,"data":{"s":"BTCUSDT","b":[["77360.60","0.129"],["77360.30","0"]],"a":[["77373.90","0"],["77374.10","0.053"],["77374.60","14.046"]],"u":101055526,"seq":800573289151},"cts":1787954773888}
{"topic":"orderbook.50.BTCUSDT","type":"delta","ts":1787954773908,"data":{"s":"BTCUSDT","b":[["77364.60","5.643"],["77360.60","0"],["77360.30","0.129"],["77359.80","1.937"],["77359.70","0.038"]],"a":[["77374.10","0.051"]],"u":101055527,"seq":800573289235},"cts":1787954773906}
{"topic":"orderbook.50.BTCUSDT","type":"delta","ts":1787954773928,"data":{"s":"BTCUSDT","b":[["77364.60","5.642"]],"a":[],"u":101055528,"seq":800573289272},"cts":1787954773923}
{"topic":"orderbook.50.BTCUSDT","type":"delta","ts":1787954774029,"data":{"s":"BTCUSDT","b":[["77360.60","0.129"],["77360.30","0"]],"a":[],"u":101055529,"seq":800573289378},"cts":1787954774021}
{"topic":"orderbook.50.BTCUSDT","type":"delta","ts":1787954774048,"data":{"s":"BTCUSDT","b":[["77360.60","0"],["77356.10","1.533"]],"a":[],"u":101055530,"seq":800573289441},"cts":1787954774046}
{"topic":"orderbook.50.BTCUSDT","type":"delta","ts":1787954774069,"data":{"s":"BTCUSDT","b":[["77360.30","0.129"],["77356.10","0"]],"a":[],"u":101055531,"seq":800573289473},"cts":1787954774066}
{"topic":"orderbook.50.BTCUSDT","type":"delta","ts":1787954774089,"data":{"s":"BTCUSDT","b":[["77360.60","0.129"],["77360.30","0"]],"a":[],"u":101055532,"seq":800573289515},"cts":1787954774084}
{"topic":"orderbook.50.BTCUSDT","type":"delta","ts":1787954774108,"data":{"s":"BTCUSDT","b":[["77360.60","0"],["77356.10","1.533"]],"a":[],"u":101055533,"seq":800573289558},"cts":1787954774107}
{"topic":"orderbook.50.BTCUSDT","type":"delta","ts":1787954774128,"data":{"s":"BTCUSDT","b":[["77360.30","0.129"],["77359.80","1.936"],["77359.70","0.039"],["77356.10","0"]],"a":[],"u":101055534,"seq":800573289591},"cts":1787954774120}
{"topic":"orderbook.50.BTCUSDT","type":"delta","ts":1787954774148,"data":{"s":"BTCUSDT","b":[["77360.30","0"],["77359.80","1.937"],["77359.70","0.038"],["77356.10","1.533"]],"a":[],"u":101055535,"seq":800573289644},"cts":1787954774140}
{"topic":"orderbook.50.BTCUSDT","type":"delta","ts":1787954774169,"data":{"s":"BTCUSDT","b":[["77360.30","0.129"],["77356.10","0"]],"a":[],"u":101055536,"seq":800573289688},"cts":1787954774161}
{"topic":"orderbook.50.BTCUSDT","type":"delta","ts":1787954774189,"data":{"s":"BTCUSDT","b":[["77360.60","0.129"],["77360.30","0"],["77359.80","1.936"],["77359.70","0.039"]],"a":[],"u":101055537,"seq":800573289724},"cts":1787954774184}
{"topic":"orderbook.50.BTCUSDT","type":"delta","ts":1787954774208,"data":{"s":"BTCUSDT","b":[["77360.60","0"],["77359.80","1.937"],["77359.70","0.038"],["77356.10","1.533"]],"a":[],"u":101055538,"seq":800573289797},"cts":1787954774207}
{"topic":"orderbook.50.BTCUSDT","type":"delta","ts":1787954774228,"data":{"s":"BTCUSDT","b":[["77360.30","0.129"],["77359.80","1.936"],["77359.70","0.039"],["77356.10","0"]],"a":[],"u":101055539,"seq":800573289850},"cts":1787954774223}
{"topic":"orderbook.50.BTCUSDT","type":"delta","ts":1787954774248,"data":{"s":"BTCUSDT","b":[["77360.60","0.129"],["77360.30","0"]],"a":[],"u":101055540,"seq":800573289915},"cts":1787954774246}
{"topic":"orderbook.50.BTCUSDT","type":"delta","ts":1787954774268,"data":{"s":"BTCUSDT","b":[["77360.60","0"],["77356.10","1.533"]],"a":[],"u":101055541,"seq":800573289952},"cts":1787954774266}
{"topic":"orderbook.50.BTCUSDT","type":"delta","ts":1787954774288,"data":{"s":"BTCUSDT","b":[["77360.20","0.499"]],"a":[],"u":101055542,"seq":800573290000},"cts":1787954774286}
{"topic":"orderbook.50.BTCUSDT","type":"delta","ts":1787954774309,"data":{"s":"BTCUSDT","b":[["77360.30","0.129"],["77360.20","0.370"],["77359.80","1.937"],["77359.70","0.038"],["77356.10","0"]],"a":[],"u":101055543,"seq":800573290020},"cts":1787954774305}
{"topic":"orderbook.50.BTCUSDT","type":"delta","ts":1787954774328,"data":{"s":"BTCUSDT","b":[["77360.30","0"],["77356.10","1.533"]],"a":[],"u":101055544,"seq":800573290052},"cts":1787954774318}
{"topic":"orderbook.50.BTCUSDT","type":"delta","ts":1787954774348,"data":{"s":"BTCUSDT","b":[["77360.30","0.129"],["77356.10","0"]],"a":[],"u":101055545,"seq":800573290081},"cts":1787954774343}
{"topic":"orderbook.50.BTCUSDT","type":"delta","ts":1787954774368,"data":{"s":"BTCUSDT","b":[["77360.30","0"],["77356.10","1.533"]],"a":[],"u":101055546,"seq":800573290118},"cts":1787954774363}
{"topic":"orderbook.50.BTCUSDT","type":"delta","ts":1787954774389,"data":{"s":"BTCUSDT","b":[["77360.30","0.129"],["77356.10","0"]],"a":[],"u":101055547,"seq":800573290147},"cts":1787954774383}
{"topic":"orderbook.50.BTCUSDT","type":"delta","ts":1787954774408,"data":{"s":"BTCUSDT","b":[["77364.60","5.643"],["77360.30","0"],["77359.80","1.936"],["77359.70","0.039"],["77356.10","1.533"]],"a":[],"u":101055548,"seq":800573290194},"cts":1787954774408}
{"topic":"orderbook.50.BTCUSDT","type":"delta","ts":1787954774429,"data":{"s":"BTCUSDT","b":[["77364.60","5.642"],["77360.30","0.129"],["77359.80","1.937"],["77359.70","0.038"],["77356.10","0"]],"a":[["77364.70","7.530"]],"u":101055549,"seq":800573290250},"cts":1787954774427}
{"topic":"orderbook.50.BTCUSDT","type":"delta","ts":1787954774449,"data":{"s":"BTCUSDT","b":[["77360.30","0"],["77359.80","1.936"],["77359.70","0.039"],["77356.10","1.533"]],"a":[["77364.70","7.225"]],"u":101055550,"seq":800573290317},"cts":1787954774445}
{"topic":"orderbook.50.BTCUSDT","type":"delta","ts":1787954774468,"data":{"s":"BTCUSDT","b":[["77360.30","0.129"],["77356.10","0"]],"a":[],"u":101055551,"seq":800573290344},"cts":1787954774463}
{"topic":"orderbook.50.BTCUSDT","type":"delta","ts":1787954774488,"data":{"s":"BTCUSDT","b":[["77364.60","5.643"],["77360.30","0"],["77356.10","1.533"]],"a":[],"u":101055552,"seq":800573290374},"cts":1787954774482}
{"topic":"orderbook.50.BTCUSDT","type":"delta","ts":1787954774508,"data":{"s":"BTCUSDT","b":[["77364.60","5.642"],["77360.30","0.129"],["77359.80","1.937"],["77359.70","0.038"],["77356.10","0"]],"a":[],"u":101055553,"seq":800573290426},"cts":1787954774507}
{"topic":"orderbook.50.BTCUSDT","type":"delta","ts":1787954774528,"data":{"s":"BTCUSDT","b":[["77360.60","0.129"],["77360.30","0"],["77359.80","1.936"],["77359.70","0.039"]],"a":[],"u":101055554,"seq":800573290481},"cts":1787954774526}
{"topic":"orderbook.50.BTCUSDT","type":"delta","ts":1787954774548,"data":{"s":"BTCUSDT","b":[["77360.60","0"],["77360.30","0.129"]],"a":[],"u":101055555,"seq":800573290526},"cts":1787954774543}
{"topic":"orderbook.50.BTCUSDT","type":"delta","ts":1787954774709,"data":{"s":"BTCUSDT","b":[["77359.80","1.937"],["77359.70","0.038"]],"a":[],"u":101055556,"seq":800573290720},"cts":1787954774706}
{"topic":"orderbook.50.BTCUSDT","type":"delta","ts":1787954774769,"data":{"s":"BTCUSDT","b":[["77364.60","5.643"]],"a":[],"u":101055557,"seq":800573290766},"cts":1787954774763}
{"topic":"orderbook.50.BTCUSDT","type":"delta","ts":1787954774868,"data":{"s":"BTCUSDT","b":[["77364.60","5.600"]],"a":[],"u":101055558,"seq":800573290863},"cts":1787954774867}
{"topic":"orderbook.50.BTCUSDT","type":"delta","ts":1787954774889,"data":{"s":"BTCUSDT","b":[["77364.60","5.605"]],"a":[["77373.40","0.002"],["77374.60","0"]],"u":101055559,"seq":800573290920},"cts":1787954774882}
{"topic":"orderbook.50.BTCUSDT","type":"delta","ts":1787954774909,"data":{"s":"BTCUSDT","b":[],"a":[["77373.40","0"],["77374.00","0.003"],["77374.60","14.046"]],"u":101055560,"seq":800573290954},"cts":1787954774905}
{"topic":"orderbook.50.BTCUSDT","type":"delta","ts":1787954774928,"data":{"s":"BTCUSDT","b":[],"a":[["77373.30","0.002"],["77374.60","0"]],"u":101055561,"seq":800573290983},"cts":1787954774927}
{"topic":"orderbook.50.BTCUSDT","type":"delta","ts":1787954774948,"data":{"s":"BTCUSDT","b":[["77359.80","1.936"],["77359.70","0.039"]],"a":[],"u":101055562,"seq":800573291009},"cts":1787954774941}
{"topic":"orderbook.50.BTCUSDT","type":"delta","ts":1787954775008,"data":{"s":"BTCUSDT","b":[["77364.60","4.763"],["77360.30","0"],["77356.10","1.533"]],"a":[["77371.00","0.033"],["77372.40","0.002"],["77373.30","0"]],"u":101055563,"seq":800573291096},"cts":1787954775006}
{"topic":"orderbook.50.BTCUSDT","type":"delta","ts":1787954775068,"data":{"s":"BTCUSDT","b":[["77364.50","0.005"]],"a":[],"u":101055564,"seq":800573291218},"cts":1787954775065}
{"topic":"orderbook.50.BTCUSDT","type":"delta","ts":1787954775089,"data":{"s":"BTCUSDT","b":[],"a":[["77371.00","0.031"],["77371.20","0.010"]],"u":101055565,"seq":800573291263},"cts":1787954775082}
{"topic":"orderbook.50.BTCUSDT","type":"delta","ts":1787954775188,"data":{"s":"BTCUSDT","b":[["77364.60","5.127"]],"a":[["77371.20","0.008"],["77372.40","0"],["77374.00","0.001"],["77374.60","14.046"]],"u":101055566,"seq":800573291397},"cts":1787954775187}
{"topic":"orderbook.50.BTCUSDT","type":"delta","ts":1787954775209,"data":{"s":"BTCUSDT","b":[["77360.30","0.129"],["77356.10","0"]],"a":[],"u":101055567,"seq":800573291441},"cts":1787954775205}
{"topic":"orderbook.50.BTCUSDT","type":"delta","ts":1787954775228,"data":{"s":"BTCUSDT","b":[["77360.30","0"],["77356.10","1.533"]],"a":[],"u":101055568,"seq":800573291479},"cts":1787954775225}
{"topic":"orderbook.50.BTCUSDT","type":"delta","ts":1787954775248,"data":{"s":"BTCUSDT","b":[["77360.30","0.129"],["77356.10","0"]],"a":[],"u":101055569,"seq":800573291514},"cts":1787954775245}
{"topic":"orderbook.50.BTCUSDT","type":"delta","ts":1787954775268,"data":{"s":"BTCUSDT","b":[["77360.30","0"],["77356.10","1.533"]],"a":[],"u":101055570,"seq":800573291552},"cts":1787954775266}
{"topic":"orderbook.50.BTCUSDT","type":"delta","ts":1787954775288,"data":{"s":"BTCUSDT","b":[["77364.50","0.004"],["77360.30","0.129"],["77356.10","0"]],"a":[["77374.20","0.004"]],"u":101055571,"seq":800573291601},"cts":1787954775287}
{"topic":"orderbook.50.BTCUSDT","type":"delta","ts":1787954775308,"data":{"s":"BTCUSDT","b":[["77364.60","5.128"],["77360.30","0"],["77356.10","1.533"]],"a":[],"u":101055572,"seq":800573291637},"cts":1787954775303}
{"topic":"orderbook.50.BTCUSDT","type":"delta","ts":1787954775328,"data":{"s":"BTCUSDT","b":[["77364.60","5.127"],["77360.30","0.129"],["77356.10","0"]],"a":[],"u":101055573,"seq":800573291695},"cts":1787954775327}
{"topic":"orderbook.50.BTCUSDT","type":"delta","ts":1787954775368,"data":{"s":"BTCUSDT","b":[["77364.60","5.128"]],"a":[],"u":101055574,"seq":800573291795},"cts":1787954775364}
{"topic":"orderbook.50.BTCUSDT","type":"delta","ts":1787954775408,"data":{"s":"BTCUSDT","b":[["77364.60","5.127"]],"a":[],"u":101055575,"seq":800573291873},"cts":1787954775404}
{"topic":"orderbook.50.BTCUSDT","type":"delta","ts":1787954775428,"data":{"s":"BTCUSDT","b":[["77364.60","5.128"]],"a":[],"u":101055576,"seq":800573291921},"cts":1787954775427}
{"topic":"orderbook.50.BTCUSDT","type":"delta","ts":1787954775448,"data":{"s":"BTCUSDT","b":[["77364.60","5.127"]],"a":[],"u":101055577,"seq":800573291978},"cts":1787954775447}
{"topic":"orderbook.50.BTCUSDT","type":"delta","ts":1787954775468,"data":{"s":"BTCUSDT","b":[],"a":[["77374.00","0.003"],["77374.20","0.002"]],"u":101055578,"seq":800573292026},"cts":1787954775462}
{"topic":"orderbook.50.BTCUSDT","type":"delta","ts":1787954775508,"data":{"s":"BTCUSDT","b":[["77361.10","0.106"],["77356.20","0"]],"a":[["77364.70","7.083"],["77374.00","0.001"]],"u":101055579,"seq":800573292112},"cts":1787954775507}
{"topic":"orderbook.50.BTCUSDT","type":"delta","ts":1787954775868,"data":{"s":"BTCUSDT","b":[["77364.50","0.005"]],"a":[],"u":101055580,"seq":800573292562},"cts":1787954775863}
{"topic":"orderbook.50.BTCUSDT","type":"delta","ts":1787954775968,"data":{"s":"BTCUSDT","b":[["77364.50","0.004"]],"a":[],"u":101055581,"seq":800573292675},"cts":1787954775964}
{"topic":"orderbook.50.BTCUSDT","type":"delta","ts":1787954776009,"data":{"s":"BTCUSDT","b":[],"a":[["77364.70","7.062"]],"u":101055582,"seq":800573292716},"cts":1787954776007}
{"topic":"orderbook.50.BTCUSDT","type":"delta","ts":1787954776288,"data":{"s":"BTCUSDT","b":[["77364.50","0.005"]],"a":[],"u":101055583,"seq":800573292973},"cts":1787954776287}
{"topic":"orderbook.50.BTCUSDT","type":"delta","ts":1787954776488,"data":{"s":"BTCUSDT","b":[["77364.60","5.128"],["77364.50","0.004"]],"a":[],"u":101055584,"seq":800573293228},"cts":1787954776487}
{"topic":"orderbook.50.BTCUSDT","type":"delta","ts":1787954776508,"data":{"s":"BTCUSDT","b":[["77364.60","5.127"]],"a":[],"u":101055585,"seq":800573293279},"cts":1787954776505}
{"topic":"orderbook.50.BTCUSDT","type":"delta","ts":1787954776549,"data":{"s":"BTCUSDT","b":[["77364.60","5.128"]],"a":[],"u":101055586,"seq":800573293371},"cts":1787954776542}
{"topic":"orderbook.50.BTCUSDT","type":"delta","ts":1787954776568,"data":{"s":"BTCUSDT","b":[["77364.60","5.127"],["77360.30","0"],["77356.20","0.251"]],"a":[["77367.90","0.008"],["77371.20","0.002"]],"u":101055587,"seq":800573293433},"cts":1787954776564}
{"topic":"orderbook.50.BTCUSDT","type":"delta","ts":1787954776588,"data":{"s":"BTCUSDT","b":[],"a":[["77367.90","0.002"],["77371.20","0.008"]],"u":101055588,"seq":800573293460},"cts":1787954776584}
{"topic":"orderbook.50.BTCUSDT","type":"delta","ts":1787954776609,"data":{"s":"BTCUSDT","b":[["77364.60","5.128"],["77360.30","0.129"],["77356.20","0"]],"a":[],"u":101055589,"seq":800573293516},"cts":1787954776607}
{"topic":"orderbook.50.BTCUSDT","type":"delta","ts":1787954776628,"data":{"s":"BTCUSDT","b":[["77364.60","5.127"],["77360.30","0"],["77356.20","0.251"]],"a":[],"u":101055590,"seq":800573293590},"cts":1787954776627}
{"topic":"orderbook.50.BTCUSDT","type":"delta","ts":1787954776648,"data":{"s":"BTCUSDT","b":[["77364.60","4.763"],["77360.20","0.499"]],"a":[["77373.40","0.002"],["77374.60","0"]],"u":101055591,"seq":800573293644},"cts":1787954776643}
{"topic":"orderbook.50.BTCUSDT","type":"delta","ts":1787954776669,"data":{"s":"BTCUSDT","b":[["77364.60","5.123"]],"a":[["77373.40","0"],["77374.60","14.046"]],"u":101055592,"seq":800573293715},"cts":1787954776667}
{"topic":"orderbook.50.BTCUSDT","type":"delta","ts":1787954776708,"data":{"s":"BTCUSDT","b":[["77360.20","0.370"]],"a":[],"u":101055593,"seq":800573293774},"cts":1787954776707}
{"topic":"orderbook.50.BTCUSDT","type":"delta","ts":1787954776728,"data":{"s":"BTCUSDT","b":[["77360.30","0.129"],["77356.20","0"]],"a":[],"u":101055594,"seq":800573293820},"cts":1787954776721}
{"topic":"orderbook.50.BTCUSDT","type":"delta","ts":1787954776788,"data":{"s":"BTCUSDT","b":[],"a":[["77374.50","4.191"]],"u":101055595,"seq":800573293873},"cts":1787954776787}
{"topic":"orderbook.50.BTCUSDT","type":"delta","ts":1787954776929,"data":{"s":"BTCUSDT","b":[],"a":[["77374.00","0.003"]],"u":101055596,"seq":800573294027},"cts":1787954776921}
{"topic":"orderbook.50.BTCUSDT","type":"delta","ts":1787954776968,"data":{"s":"BTCUSDT","b":[["77364.50","0.005"]],"a":[],"u":101055597,"seq":800573294097},"cts":1787954776967}
{"topic":"orderbook.50.BTCUSDT","type":"delta","ts":1787954777089,"data":{"s":"BTCUSDT","b":[["77364.50","0.004"]],"a":[],"u":101055598,"seq":800573294243},"cts":1787954777087}
{"topic":"orderbook.50.BTCUSDT","type":"delta","ts":1787954777229,"data":{"s":"BTCUSDT","b":[["77360.30","0"],["77360.20","0.499"],["77356.20","0.251"]],"a":[["77374.00","0.001"]],"u":101055599,"seq":800573294367},"cts":1787954777225}
{"topic":"orderbook.50.BTCUSDT","type":"delta","ts":1787954777288,"data":{"s":"BTCUSDT","b":[["77360.30","0.129"],["77360.20","0.370"],["77356.20","0"]],"a":[["77374.50","4.189"]],"u":101055600,"seq":800573294425},"cts":1787954777287}
{"topic":"orderbook.50.BTCUSDT","type":"delta","ts":1787954777308,"data":{"s":"BTCUSDT","b":[["77360.30","0"],["77360.20","0.499"],["77356.20","0.251"]],"a":[],"u":101055601,"seq":800573294486},"cts":1787954777307}
{"topic":"orderbook.50.BTCUSDT","type":"delta","ts":1787954777328,"data":{"s":"BTCUSDT","b":[["77360.20","0.370"]],"a":[["77367.90","0.008"],["77371.20","0.002"]],"u":101055602,"seq":800573294533},"cts":1787954777327}
{"topic":"orderbook.50.BTCUSDT","type":"delta","ts":1787954777448,"data":{"s":"BTCUSDT","b":[["77360.30","0.129"],["77356.20","0"]],"a":[["77367.90","0.002"],["77371.20","0.008"]],"u":101055603,"seq":800573294675},"cts":1787954777441}
{"topic":"orderbook.50.BTCUSDT","type":"delta","ts":1787954777549,"data":{"s":"BTCUSDT","b":[["77360.30","0"],["77360.20","0.499"],["77356.20","0.251"]],"a":[],"u":101055604,"seq":800573294796},"cts":1787954777544}
{"topic":"orderbook.50.BTCUSDT","type":"delta","ts":1787954777628,"data":{"s":"BTCUSDT","b":[["77360.20","0.370"]],"a":[["77367.90","0.008"],["77371.20","0.002"]],"u":101055605,"seq":800573294883},"cts":1787954777625}
{"topic":"orderbook.50.BTCUSDT","type":"delta","ts":1787954777688,"data":{"s":"BTCUSDT","b":[["77360.20","0.499"]],"a":[["77367.90","0.002"],["77371.20","0.008"],["77374.10","0.053"]],"u":101055606,"seq":800573294953},"cts":1787954777687}
{"topic":"orderbook.50.BTCUSDT","type":"delta","ts":1787954777708,"data":{"s":"BTCUSDT","b":[["77364.60","5.124"],["77360.30","0.129"],["77360.20","0.370"],["77356.20","0"]],"a":[["77374.10","0.051"]],"u":101055607,"seq":800573295003},"cts":1787954777707}
{"topic":"orderbook.50.BTCUSDT","type":"delta","ts":1787954777728,"data":{"s":"BTCUSDT","b":[["77364.60","5.123"]],"a":[],"u":101055608,"seq":800573295049},"cts":1787954777724}
{"topic":"orderbook.50.BTCUSDT","type":"delta","ts":1787954777769,"data":{"s":"BTCUSDT","b":[["77364.60","5.124"]],"a":[],"u":101055609,"seq":800573295175},"cts":1787954777761}
{"topic":"orderbook.50.BTCUSDT","type":"delta","ts":1787954777788,"data":{"s":"BTCUSDT","b":[["77364.60","5.123"]],"a":[],"u":101055610,"seq":800573295221},"cts":1787954777785}
{"topic":"orderbook.50.BTCUSDT","type":"delta","ts":1787954777828,"data":{"s":"BTCUSDT","b":[["77364.60","5.124"]],"a":[],"u":101055611,"seq":800573295348},"cts":1787954777825}
{"topic":"orderbook.50.BTCUSDT","type":"delta","ts":1787954777848,"data":{"s":"BTCUSDT","b":[["77364.60","5.123"],["77360.30","0"],["77360.20","0.499"],["77356.20","0.251"]],"a":[],"u":101055612,"seq":800573295393},"cts":1787954777843}
{"topic":"orderbook.50.BTCUSDT","type":"delta","ts":1787954777888,"data":{"s":"BTCUSDT","b":[["77364.60","5.124"]],"a":[],"u":101055613,"seq":800573295481},"cts":1787954777886}
{"topic":"orderbook.50.BTCUSDT","type":"delta","ts":1787954777908,"data":{"s":"BTCUSDT","b":[["77364.60","5.123"]],"a":[],"u":101055614,"seq":800573295531},"cts":1787954777904}
{"topic":"orderbook.50.BTCUSDT","type":"delta","ts":1787954777948,"data":{"s":"BTCUSDT","b":[],"a":[["77374.60","14.048"]],"u":101055615,"seq":800573295627},"cts":1787954777946}
{"topic":"orderbook.50.BTCUSDT","type":"delta","ts":1787954777969,"data":{"s":"BTCUSDT","b":[],"a":[["77374.60","14.046"]],"u":101055616,"seq":800573295676},"cts":1787954777965}
{"topic":"orderbook.50.BTCUSDT","type":"delta","ts":1787954777988,"data":{"s":"BTCUSDT","b":[["77364.60","5.124"],["77360.20","0.370"]],"a":[],"u":101055617,"seq":800573295737},"cts":1787954777987}
{"topic":"orderbook.50.BTCUSDT","type":"delta","ts":1787954778008,"data":{"s":"BTCUSDT","b":[],"a":[["77367.90","0.008"],["77371.20","0.002"]],"u":101055618,"seq":800573295793},"cts":1787954778006}
{"topic":"orderbook.50.BTCUSDT","type":"delta","ts":1787954778088,"data":{"s":"BTCUSDT","b":[["77364.60","5.123"],["77360.30","0.129"],["77356.20","0"]],"a":[],"u":101055619,"seq":800573296000},"cts":1787954778086}
{"topic":"orderbook.50.BTCUSDT","type":"delta","ts":1787954778109,"data":{"s":"BTCUSDT","b":[["77360.30","0"],["77356.20","0.251"]],"a":[["77374.20","0.004"]],"u":101055620,"seq":800573296083},"cts":1787954778106}
{"topic":"orderbook.50.BTCUSDT","type":"delta","ts":1787954778148,"data":{"s":"BTCUSDT","b":[],"a":[["77373.30","0.002"],["77374.60","0"]],"u":101055621,"seq":800573296165},"cts":1787954778146}
{"topic":"orderbook.50.BTCUSDT","type":"delta","ts":1787954778209,"data":{"s":"BTCUSDT","b":[["77364.60","5.124"]],"a":[],"u":101055622,"seq":800573296225},"cts":1787954778205}
{"topic":"orderbook.50.BTCUSDT","type":"delta","ts":1787954778228,"data":{"s":"BTCUSDT","b":[["77364.60","5.123"]],"a":[],"u":101055623,"seq":800573296274},"cts":1787954778221}
{"topic":"orderbook.50.BTCUSDT","type":"delta","ts":1787954778248,"data":{"s":"BTCUSDT","b":[["77360.30","0.129"],["77356.20","0"]],"a":[["77367.90","0.002"],["77371.20","0.008"],["77373.30","0"],["77374.60","14.046"]],"u":101055624,"seq":800573296329},"cts":1787954778246}
{"topic":"orderbook.50.BTCUSDT","type":"delta","ts":1787954778268,"data":{"s":"BTCUSDT","b":[],"a":[["77373.20","0.002"],["77374.60","0"]],"u":101055625,"seq":800573296366},"cts":1787954778266}
{"topic":"orderbook.50.BTCUSDT","type":"delta","ts":1787954778308,"data":{"s":"BTCUSDT","b":[["77360.30","0"],["77360.20","0.499"],["77356.20","0.251"]],"a":[],"u":101055626,"seq":800573296412},"cts":1787954778306}
{"topic":"orderbook.50.BTCUSDT","type":"delta","ts":1787954778368,"data":{"s":"BTCUSDT","b":[["77360.30","0.129"],["77360.20","0.370"],["77356.20","0"]],"a":[["77373.20","0"],["77374.60","14.046"]],"u":101055627,"seq":800573296476},"cts":1787954778367}
{"topic":"orderbook.50.BTCUSDT","type":"delta","ts":1787954778388,"data":{"s":"BTCUSDT","b":[["77360.30","0"],["77360.20","0.499"],["77356.20","0.251"]],"a":[],"u":101055628,"seq":800573296519},"cts":1787954778385}
{"topic":"orderbook.50.BTCUSDT","type":"delta","ts":1787954778408,"data":{"s":"BTCUSDT","b":[["77360.30","0.129"],["77360.20","0.370"],["77356.20","0"]],"a":[["77374.20","0.002"]],"u":101055629,"seq":800573296587},"cts":1787954778403}
{"topic":"orderbook.50.BTCUSDT","type":"delta","ts":1787954778428,"data":{"s":"BTCUSDT","b":[["77360.30","0"],["77360.20","0.499"],["77356.20","0.251"]],"a":[["77373.80","0.003"]],"u":101055630,"seq":800573296637},"cts":1787954778426}
{"topic":"orderbook.50.BTCUSDT","type":"delta","ts":1787954778448,"data":{"s":"BTCUSDT","b":[],"a":[["77373.80","0.001"],["77374.10","0.053"]],"u":101055631,"seq":800573296689},"cts":1787954778446}
{"topic":"orderbook.50.BTCUSDT","type":"delta","ts":1787954778489,"data":{"s":"BTCUSDT","b":[["77360.20","0.370"]],"a":[],"u":101055632,"seq":800573296745},"cts":1787954778481}
{"topic":"orderbook.50.BTCUSDT","type":"delta","ts":1787954778548,"data":{"s":"BTCUSDT","b":[["77360.20","0.499"]],"a":[["77374.10","0.051"]],"u":101055633,"seq":800573296828},"cts":1787954778547}
{"topic":"orderbook.50.BTCUSDT","type":"delta","ts":1787954778569,"data":{"s":"BTCUSDT","b":[],"a":[["77374.20","0.004"]],"u":101055634,"seq":800573296849},"cts":1787954778553}
{"topic":"orderbook.50.BTCUSDT","type":"delta","ts":1787954778648,"data":{"s":"BTCUSDT","b":[],"a":[["77373.20","0.002"],["77374.60","0"]],"u":101055635,"seq":800573296945},"cts":1787954778646}
{"topic":"orderbook.50.BTCUSDT","type":"delta","ts":1787954778668,"data":{"s":"BTCUSDT","b":[["77359.50","0.650"],["77356.20","0"]],"a":[],"u":101055636,"seq":800573296980},"cts":1787954778661}
{"topic":"orderbook.50.BTCUSDT","type":"delta","ts":1787954778708,"data":{"s":"BTCUSDT","b":[["77364.60","5.124"],["77360.30","0.129"],["77360.20","0.370"],["77356.30","0"]],"a":[],"u":101055637,"seq":800573297026},"cts":1787954778707}
{"topic":"orderbook.50.BTCUSDT","type":"delta","ts":1787954778729,"data":{"s":"BTCUSDT","b":[["77364.60","5.123"]],"a":[],"u":101055638,"seq":800573297088},"cts":1787954778723}
{"topic":"orderbook.50.BTCUSDT","type":"delta","ts":1787954778749,"data":{"s":"BTCUSDT","b":[["77364.60","5.124"]],"a":[],"u":101055639,"seq":800573297130},"cts":1787954778743}
{"topic":"orderbook.50.BTCUSDT","type":"delta","ts":1787954778808,"data":{"s":"BTCUSDT","b":[["77364.60","5.123"]],"a":[["77364.70","7.063"],["77373.20","0"],["77374.20","0.002"],["77374.60","14.046"]],"u":101055640,"seq":800573297285},"cts":1787954778806}
{"topic":"orderbook.50.BTCUSDT","type":"delta","ts":1787954778828,"data":{"s":"BTCUSDT","b":[["77364.60","5.124"]],"a":[["77372.90","0.002"],["77374.60","0"]],"u":101055641,"seq":800573297350},"cts":1787954778825}
{"topic":"orderbook.50.BTCUSDT","type":"delta","ts":1787954779068,"data":{"s":"BTCUSDT","b":[["77364.60","5.123"]],"a":[],"u":101055642,"seq":800573297906},"cts":1787954779066}
{"topic":"orderbook.50.BTCUSDT","type":"delta","ts":1787954779088,"data":{"s":"BTCUSDT","b":[["77364.60","5.124"],["77360.30","0"],["77360.20","0.499"],["77356.30","0.001"]],"a":[],"u":101055643,"seq":800573297951},"cts":1787954779081}
{"topic":"orderbook.50.BTCUSDT","type":"delta","ts":1787954779108,"data":{"s":"BTCUSDT","b":[["77364.60","5.123"]],"a":[],"u":101055644,"seq":800573298015},"cts":1787954779106}
{"topic":"orderbook.50.BTCUSDT","type":"delta","ts":1787954779148,"data":{"s":"BTCUSDT","b":[["77364.60","5.124"]],"a":[["77372.30","0.004"]],"u":101055645,"seq":800573298140},"cts":1787954779147}
{"topic":"orderbook.50.BTCUSDT","type":"delta","ts":1787954779168,"data":{"s":"BTCUSDT","b":[["77364.60","5.123"]],"a":[],"u":101055646,"seq":800573298198},"cts":1787954779165}
{"topic":"orderbook.50.BTCUSDT","type":"delta","ts":1787954779189,"data":{"s":"BTCUSDT","b":[],"a":[["77371.90","0.002"],["77374.50","0"]],"u":101055647,"seq":800573298222},"cts":1787954779183}
{"topic":"orderbook.50.BTCUSDT","type":"delta","ts":1787954779269,"data":{"s":"BTCUSDT","b":[["77360.20","0.370"],["77360.00","0.142"],["77359.50","0"],["77358.70","0.708"],["77356.20","0.251"]],"a":[["77367.90","0.008"],["77371.20","0.002"],["77371.90","0"],["77374.50","4.189"]],"u":101055648,"seq":800573298398},"cts":1787954779266}
{"topic":"orderbook.50.BTCUSDT","type":"delta","ts":1787954779308,"data":{"s":"BTCUSDT","b":[],"a":[["77367.90","0.002"],["77371.20","0.008"],["77374.00","0.192"]],"u":101055649,"seq":800573298443},"cts":1787954779305}
{"topic":"orderbook.50.BTCUSDT","type":"delta","ts":1787954779389,"data":{"s":"BTCUSDT","b":[["77360.20","0.499"],["77360.00","0.013"]],"a":[],"u":101055650,"seq":800573298521},"cts":1787954779387}
{"topic":"orderbook.50.BTCUSDT","type":"delta","ts":1787954779408,"data":{"s":"BTCUSDT","b":[],"a":[["77371.70","0.002"],["77374.50","0"]],"u":101055651,"seq":800573298558},"cts":1787954779406}
{"topic":"orderbook.50.BTCUSDT","type":"delta","ts":1787954779428,"data":{"s":"BTCUSDT","b":[["77359.50","0.646"],["77358.70","0.002"],["77356.20","0"]],"a":[["77371.70","0"],["77371.80","0.003"],["77374.50","4.189"]],"u":101055652,"seq":800573298586},"cts":1787954779425}
{"topic":"orderbook.50.BTCUSDT","type":"delta","ts":1787954779568,"data":{"s":"BTCUSDT","b":[["77360.20","0.370"],["77359.50","0"],["77358.70","0.693"],["77357.60","0.002"],["77356.20","0.251"]],"a":[["77367.90","0.008"],["77371.20","0.002"]],"u":101055653,"seq":800573298770},"cts":1787954779565}
{"topic":"orderbook.50.BTCUSDT","type":"delta","ts":1787954779589,"data":{"s":"BTCUSDT","b":[],"a":[["77371.10","0.002"],["77374.50","0"]],"u":101055654,"seq":800573298810},"cts":1787954779580}
{"topic":"orderbook.50.BTCUSDT","type":"delta","ts":1787954779628,"data":{"s":"BTCUSDT","b":[["77360.20","0.499"]],"a":[["77367.90","0.002"],["77371.10","0"],["77371.20","0.008"],["77371.30","14.003"],["77374.50","4.189"]],"u":101055655,"seq":800573298889},"cts":1787954779625}
{"topic":"orderbook.50.BTCUSDT","type":"delta","ts":1787954779649,"data":{"s":"BTCUSDT","b":[["77362.80","0.821"]],"a":[["77371.30","14.001"],["77371.80","0.001"],["77371.90","0.002"],["77372.30","0.002"],["77373.40","0.002"],["77373.80","0.003"],["77374.20","0"],["77374.50","0"]],"u":101055656,"seq":800573298941},"cts":1787954779645}
{"topic":"orderbook.50.BTCUSDT","type":"delta","ts":1787954779688,"data":{"s":"BTCUSDT","b":[["77360.30","0.129"],["77360.20","0.370"],["77359.50","0.655"],["77358.70","0.002"],["77357.60","0.325"],["77356.30","0"],["77356.20","0"]],"a":[["77371.90","0"],["77372.50","0.050"],["77372.90","0"],["77374.20","0.002"],["77374.30","0.002"]],"u":101055657,"seq":800573299006},"cts":1787954779687}
{"topic":"orderbook.50.BTCUSDT","type":"delta","ts":1787954779708,"data":{"s":"BTCUSDT","b":[["77364.60","5.124"]],"a":[["77372.50","0.048"]],"u":101055658,"seq":800573299040},"cts":1787954779707}
{"topic":"orderbook.50.BTCUSDT","type":"delta","ts":1787954779728,"data":{"s":"BTCUSDT","b":[["77364.60","5.123"]],"a":[],"u":101055659,"seq":800573299085},"cts":1787954779724}
{"topic":"orderbook.50.BTCUSDT","type":"delta","ts":1787954779788,"data":{"s":"BTCUSDT","b":[["77364.60","5.124"]],"a":[],"u":101055660,"seq":800573299202},"cts":1787954779783}
{"topic":"orderbook.50.BTCUSDT","type":"delta","ts":1787954779808,"data":{"s":"BTCUSDT","b":[["77364.60","5.123"]],"a":[],"u":101055661,"seq":800573299250},"cts":1787954779805}
{"topic":"orderbook.50.BTCUSDT","type":"delta","ts":1787954779848,"data":{"s":"BTCUSDT","b":[["77364.60","4.763"],["77360.30","0"],["77359.50","0"],["77358.70","0.684"],["77356.30","0.001"],["77356.20","0.251"]],"a":[["77367.90","0.008"],["77370.10","0.002"],["77371.20","0.002"],["77372.10","0.325"],["77374.30","0"]],"u":101055662,"seq":800573299357},"cts":1787954779844}
{"topic":"orderbook.50.BTCUSDT","type":"delta","ts":1787954779868,"data":{"s":"BTCUSDT","b":[["77364.60","4.764"]],"a":[],"u":101055663,"seq":800573299399},"cts":1787954779867}
{"topic":"orderbook.50.BTCUSDT","type":"delta","ts":1787954779889,"data":{"s":"BTCUSDT","b":[["77364.60","4.763"]],"a":[],"u":101055664,"seq":800573299439},"cts":1787954779886}
{"topic":"orderbook.50.BTCUSDT","type":"delta","ts":1787954779908,"data":{"s":"BTCUSDT","b":[["77364.60","4.764"]],"a":[],"u":101055665,"seq":800573299470},"cts":1787954779904}
{"topic":"orderbook.50.BTCUSDT","type":"delta","ts":1787954779928,"data":{"s":"BTCUSDT","b":[["77364.60","4.763"]],"a":[],"u":101055666,"seq":800573299514},"cts":1787954779926}
{"topic":"orderbook.50.BTCUSDT","type":"delta","ts":1787954779948,"data":{"s":"BTCUSDT","b":[],"a":[["77370.10","0"],["77370.40","0.002"]],"u":101055667,"seq":800573299559},"cts":1787954779946}
{"topic":"orderbook.50.BTCUSDT","type":"delta","ts":1787954780068,"data":{"s":"BTCUSDT","b":[["77364.60","4.764"]],"a":[],"u":101055668,"seq":800573299722},"cts":1787954780066}
{"topic":"orderbook.50.BTCUSDT","type":"delta","ts":1787954780088,"data":{"s":"BTCUSDT","b":[["77364.60","4.763"]],"a":[],"u":101055669,"seq":800573299783},"cts":1787954780085}
{"topic":"orderbook.50.BTCUSDT","type":"delta","ts":1787954780108,"data":{"s":"BTCUSDT","b":[["77364.60","4.764"]],"a":[["77370.40","0"],["77370.80","0.003"],["77374.30","0.002"]],"u":101055670,"seq":800573299805},"cts":1787954780105}
{"topic":"orderbook.50.BTCUSDT","type":"delta","ts":1787954780128,"data":{"s":"BTCUSDT","b":[["77364.60","5.021"],["77362.90","0.762"],["77360.00","0.142"],["77358.80","0.686"],["77358.70","0.002"]],"a":[["77367.90","0.002"],["77370.80","0.001"],["77371.20","0.008"],["77372.10","0.323"],["77373.40","0"],["77373.80","0.001"],["77374.30","0"],["77374.50","4.189"],["77374.60","14.043"]],"u":101055671,"seq":800573299910},"cts":1787954780126}
{"topic":"orderbook.50.BTCUSDT","type":"delta","ts":1787954780149,"data":{"s":"BTCUSDT","b":[],"a":[["77367.90","0.008"],["77371.20","0.002"]],"u":101055672,"seq":800573299947},"cts":1787954780143}
{"topic":"orderbook.50.BTCUSDT","type":"delta","ts":1787954780188,"data":{"s":"BTCUSDT","b":[["77360.30","0.129"],["77360.00","0.013"],["77359.50","0.648"],["77358.80","0.001"],["77356.30","0"],["77356.20","0"]],"a":[["77367.90","0.002"],["77371.20","0.008"]],"u":101055673,"seq":800573300021},"cts":1787954780187}
{"topic":"orderbook.50.BTCUSDT","type":"delta","ts":1787954780208,"data":{"s":"BTCUSDT","b":[],"a":[["77374.60","14.046"]],"u":101055674,"seq":800573300051},"cts":1787954780206}
{"topic":"orderbook.50.BTCUSDT","type":"delta","ts":1787954780268,"data":{"s":"BTCUSDT","b":[],"a":[["77374.50","4.191"]],"u":101055675,"seq":800573300104},"cts":1787954780266}
{"topic":"orderbook.50.BTCUSDT","type":"delta","ts":1787954780328,"data":{"s":"BTCUSDT","b":[],"a":[["77374.50","4.189"]],"u":101055676,"seq":800573300163},"cts":1787954780324}
{"topic":"orderbook.50.BTCUSDT","type":"delta","ts":1787954780348,"data":{"s":"BTCUSDT","b":[["77364.60","5.019"]],"a":[["77374.50","4.191"]],"u":101055677,"seq":800573300214},"cts":1787954780343}
{"topic":"orderbook.50.BTCUSDT","type":"delta","ts":1787954780428,"data":{"s":"BTCUSDT","b":[],"a":[["77374.50","4.189"]],"u":101055678,"seq":800573300297},"cts":1787954780427}
{"topic":"orderbook.50.BTCUSDT","type":"delta","ts":1787954780569,"data":{"s":"BTCUSDT","b":[["77360.30","0"],["77360.20","0.499"],["77356.30","0.001"]],"a":[],"u":101055679,"seq":800573300393},"cts":1787954780559}
{"topic":"orderbook.50.BTCUSDT","type":"delta","ts":1787954780688,"data":{"s":"BTCUSDT","b":[],"a":[["77364.70","7.038"]],"u":101055680,"seq":800573300520},"cts":1787954780687}
{"topic":"orderbook.50.BTCUSDT","type":"delta","ts":1787954780728,"data":{"s":"BTCUSDT","b":[["77363.00","1.292"],["77356.30","0"]],"a":[],"u":101055681,"seq":800573300587},"cts":1787954780723}
{"topic":"orderbook.50.BTCUSDT","type":"delta","ts":1787954780748,"data":{"s":"BTCUSDT","b":[["77363.10","1.347"],["77362.80","0.002"],["77356.40","0"]],"a":[],"u":101055682,"seq":800573300637},"cts":1787954780740}
{"topic":"orderbook.50.BTCUSDT","type":"delta","ts":1787954780769,"data":{"s":"BTCUSDT","b":[["77363.20","1.298"],["77363.00","0"],["77362.90","0.756"],["77360.20","0.370"],["77359.50","0"],["77358.70","0.707"],["77357.60","0.002"],["77356.40","0.397"]],"a":[["77367.90","0.008"],["77371.20","0.002"],["77372.80","0.002"],["77374.60","0"]],"u":101055683,"seq":800573300731},"cts":1787954780764}
{"topic":"orderbook.50.BTCUSDT","type":"delta","ts":1787954780788,"data":{"s":"BTCUSDT","b":[["77363.10","0.960"]],"a":[],"u":101055684,"seq":800573300766},"cts":1787954780787}
{"topic":"orderbook.50.BTCUSDT","type":"delta","ts":1787954780809,"data":{"s":"BTCUSDT","b":[],"a":[["77372.80","0"],["77373.00","0.004"],["77374.60","14.048"]],"u":101055685,"seq":800573300830},"cts":1787954780806}
{"topic":"orderbook.50.BTCUSDT","type":"delta","ts":1787954780828,"data":{"s":"BTCUSDT","b":[["77364.60","5.020"]],"a":[],"u":101055686,"seq":800573300853},"cts":1787954780825}
{"topic":"orderbook.50.BTCUSDT","type":"delta","ts":1787954780848,"data":{"s":"BTCUSDT","b":[["77364.60","5.019"]],"a":[],"u":101055687,"seq":800573300920},"cts":1787954780842}
{"topic":"orderbook.50.BTCUSDT","type":"delta","ts":1787954781009,"data":{"s":"BTCUSDT","b":[],"a":[["77374.60","14.005"]],"u":101055688,"seq":800573301338},"cts":1787954781005}
{"topic":"orderbook.50.BTCUSDT","type":"delta","ts":1787954781028,"data":{"s":"BTCUSDT","b":[],"a":[["77373.00","0.002"],["77373.20","0.002"],["77374.60","0"]],"u":101055689,"seq":800573301383},"cts":1787954781026}
{"topic":"orderbook.50.BTCUSDT","type":"delta","ts":1787954781048,"data":{"s":"BTCUSDT","b":[],"a":[["77373.20","0"],["77373.60","0.003"],["77374.60","14.005"]],"u":101055690,"seq":800573301446},"cts":1787954781047}
{"topic":"orderbook.50.BTCUSDT","type":"delta","ts":1787954781069,"data":{"s":"BTCUSDT","b":[["77357.60","0.334"]],"a":[],"u":101055691,"seq":800573301486},"cts":1787954781062}
{"topic":"orderbook.50.BTCUSDT","type":"delta","ts":1787954781089,"data":{"s":"BTCUSDT","b":[["77360.00","0.142"]],"a":[],"u":101055692,"seq":800573301532},"cts":1787954781083}
{"topic":"orderbook.50.BTCUSDT","type":"delta","ts":1787954781108,"data":{"s":"BTCUSDT","b":[["77359.80","1.937"],["77359.70","0.038"]],"a":[],"u":101055693,"seq":800573301605},"cts":1787954781106}
{"topic":"orderbook.50.BTCUSDT","type":"delta","ts":1787954781128,"data":{"s":"BTCUSDT","b":[["77364.60","5.020"],["77360.00","0.013"],["77359.50","0.656"],["77358.70","0.002"],["77356.40","0"]],"a":[["77367.90","0.002"],["77371.20","0.008"],["77373.60","0.001"],["77374.60","14.003"]],"u":101055694,"seq":800573301724},"cts":1787954781127}
{"topic":"orderbook.50.BTCUSDT","type":"delta","ts":1787954781148,"data":{"s":"BTCUSDT","b":[["77360.30","0.129"],["77356.50","0"]],"a":[],"u":101055695,"seq":800573301805},"cts":1787954781146}
{"topic":"orderbook.50.BTCUSDT","type":"delta","ts":1787954781208,"data":{"s":"BTCUSDT","b":[["77364.60","5.019"]],"a":[],"u":101055696,"seq":800573301941},"cts":1787954781207}
{"topic":"orderbook.50.BTCUSDT","type":"delta","ts":1787954781249,"data":{"s":"BTCUSDT","b":[["77364.20","0.006"]],"a":[],"u":101055697,"seq":800573301980},"cts":1787954781239}
{"topic":"orderbook.50.BTCUSDT","type":"delta","ts":1787954781428,"data":{"s":"BTCUSDT","b":[["77364.60","5.065"],["77361.20","0.656"],["77359.50","0"]],"a":[["77373.70","0.003"],["77374.00","0.001"]],"u":101055698,"seq":800573302278},"cts":1787954781427}
{"topic":"orderbook.50.BTCUSDT","type":"delta","ts":1787954781449,"data":{"s":"BTCUSDT","b":[["77364.60","5.165"],["77363.30","1.543"],["77363.10","0"],["77357.40","2.194"]],"a":[["77374.50","0.002"]],"u":101055699,"seq":800573302374},"cts":1787954781447}
{"topic":"orderbook.50.BTCUSDT","type":"delta","ts":1787954781468,"data":{"s":"BTCUSDT","b":[["77360.00","0.016"]],"a":[],"u":101055700,"seq":800573302408},"cts":1787954781465}
{"topic":"orderbook.50.BTCUSDT","type":"delta","ts":1787954781488,"data":{"s":"BTCUSDT","b":[["77364.60","5.171"]],"a":[],"u":101055701,"seq":800573302462},"cts":1787954781486}
{"topic":"orderbook.50.BTCUSDT","type":"delta","ts":1787954781508,"data":{"s":"BTCUSDT","b":[["77364.60","5.165"],["77363.40","1.294"],["77363.20","0.006"],["77360.00","0.017"],["77357.40","1.936"],["77357.20","0.258"],["77356.60","0"]],"a":[],"u":101055702,"seq":800573302519},"cts":1787954781508}
{"topic":"orderbook.50.BTCUSDT","type":"delta","ts":1787954781529,"data":{"s":"BTCUSDT","b":[["77360.00","0.018"],["77359.80","1.936"]],"a":[["77374.60","14.000"]],"u":101055703,"seq":800573302568},"cts":1787954781526}
{"topic":"orderbook.50.BTCUSDT","type":"delta","ts":1787954781549,"data":{"s":"BTCUSDT","b":[],"a":[["77374.50","2.983"]],"u":101055704,"seq":800573302616},"cts":1787954781546}
{"topic":"orderbook.50.BTCUSDT","type":"delta","ts":1787954781588,"data":{"s":"BTCUSDT","b":[["77364.60","5.171"]],"a":[],"u":101055705,"seq":800573302660},"cts":1787954781586}
{"topic":"orderbook.50.BTCUSDT","type":"delta","ts":1787954781648,"data":{"s":"BTCUSDT","b":[["77364.60","5.146"]],"a":[],"u":101055706,"seq":800573302797},"cts":1787954781647}
{"topic":"orderbook.50.BTCUSDT","type":"delta","ts":1787954781668,"data":{"s":"BTCUSDT","b":[["77364.60","5.106"]],"a":[],"u":101055707,"seq":800573302852},"cts":1787954781667}
{"topic":"orderbook.50.BTCUSDT","type":"delta","ts":1787954781688,"data":{"s":"BTCUSDT","b":[["77364.60","5.126"]],"a":[],"u":101055708,"seq":800573302909},"cts":1787954781687}
{"topic":"orderbook.50.BTCUSDT","type":"delta","ts":1787954781709,"data":{"s":"BTCUSDT","b":[["77357.20","0"],["77357.10","0.640"],["77356.60","0.001"]],"a":[],"u":101055709,"seq":800573302941},"cts":1787954781707}
{"topic":"orderbook.50.BTCUSDT","type":"delta","ts":1787954781728,"data":{"s":"BTCUSDT","b":[["77364.60","5.127"]],"a":[],"u":101055710,"seq":800573302988},"cts":1787954781724}
{"topic":"orderbook.50.BTCUSDT","type":"delta","ts":1787954781748,"data":{"s":"BTCUSDT","b":[["77364.60","5.126"]],"a":[],"u":101055711,"seq":800573303036},"cts":1787954781743}
{"topic":"orderbook.50.BTCUSDT","type":"delta","ts":1787954781829,"data":{"s":"BTCUSDT","b":[["77364.60","5.127"]],"a":[],"u":101055712,"seq":800573303239},"cts":1787954781825}
{"topic":"orderbook.50.BTCUSDT","type":"delta","ts":1787954781848,"data":{"s":"BTCUSDT","b":[["77364.60","5.126"],["77364.20","0.005"]],"a":[],"u":101055713,"seq":800573303280},"cts":1787954781843}
{"topic":"orderbook.50.BTCUSDT","type":"delta","ts":1787954781889,"data":{"s":"BTCUSDT","b":[["77364.60","5.026"]],"a":[["77373.70","0.005"]],"u":101055714,"seq":800573303382},"cts":1787954781886}
{"topic":"orderbook.50.BTCUSDT","type":"delta","ts":1787954781908,"data":{"s":"BTCUSDT","b":[["77357.10","0.382"],["77357.00","0.259"]],"a":[],"u":101055715,"seq":800573303436},"cts":1787954781906}
{"topic":"orderbook.50.BTCUSDT","type":"delta","ts":1787954781928,"data":{"s":"BTCUSDT","b":[["77364.60","5.027"]],"a":[],"u":101055716,"seq":800573303461},"cts":1787954781923}
{"topic":"orderbook.50.BTCUSDT","type":"delta","ts":1787954781989,"data":{"s":"BTCUSDT","b":[["77364.60","5.016"]],"a":[],"u":101055717,"seq":800573303603},"cts":1787954781983}
{"topic":"orderbook.50.BTCUSDT","type":"delta","ts":1787954782008,"data":{"s":"BTCUSDT","b":[["77357.00","0.001"],["77356.90","0.259"]],"a":[],"u":101055718,"seq":800573303662},"cts":1787954782007}
{"topic":"orderbook.50.BTCUSDT","type":"delta","ts":1787954782088,"data":{"s":"BTCUSDT","b":[["77364.60","5.156"]],"a":[["77364.70","6.876"],["77373.70","0.001"],["77374.50","0.002"]],"u":101055719,"seq":800573303858},"cts":1787954782087}
{"topic":"orderbook.50.BTCUSDT","type":"delta","ts":1787954782108,"data":{"s":"BTCUSDT","b":[["77364.60","5.163"],["77361.20","0"],["77360.60","0.670"],["77357.20","0.258"],["77356.90","0.001"],["77356.60","0"]],"a":[["77364.70","6.645"]],"u":101055720,"seq":800573304059},"cts":1787954782107}
{"topic":"orderbook.50.BTCUSDT","type":"delta","ts":1787954782128,"data":{"s":"BTCUSDT","b":[["77367.90","1.659"],["77367.80","0.717"],["77367.60","3.529"],["77367.50","1.620"],["77367.40","1.263"],["77367.30","0.274"],["77367.20","0.240"],["77367.10","2.310"],["77366.90","0.393"],["77366.70","0.022"],["77366.60","0.019"],["77366.50","0.038"],["77366.40","1.976"],["77366.30","0.202"],["77365.80","0.400"],["77365.70","0.076"],["77365.50","0.844"],["77365.00","0.709"],["77364.90","1.103"],["77364.70","1.510"],["77364.60","4.580"],["77364.50","0.003"],["77364.00","0.002"],["77363.50","0.788"],["77363.30","1.544"],["77362.50","0.001"],["77361.60","0.001"],["77361.50","0"],["77360.60","0"],["77360.30","0"],["77360.20","0"],["77359.40","0"],["77359.20","0"],["77358.90","0"],["77358.80","0"],["77358.70","0"],["77358.60","0"],["77358.30","0"],["77358.20","0"],["77357.90","0"],["77357.60","0"],["77357.50","0"],["77357.40","0"],["77357.30","0"],["77357.20","0"],["77357.10","0"],["77357.00","0"],["77356.90","0"],["77356.80","0"]],"a":[["77364.70","0"],["77364.80","0"],["77365.00","0"],["77365.60","0"],["77365.80","0"],["77365.90","0"],["77366.40","0"],["77366.50","0"],["77366.60","0"],["77366.70","0"],["77366.80","0"],["77367.00","0"],["77367.20","0"],["77367.30","0"],["77367.40","0"],["77367.70","0"],["77367.90","0"],["77371.20","0.001"],["77372.10","0.001"],["77372.50","0"],["77374.50","0.008"],["77374.70","0.003"],["77374.80","0.001"],["77375.00","0.015"],["77375.20","0.002"],["77375.90","0.002"],["77376.00","0.004"],["77376.20","0.001"],["77376.60","0.003"],["77376.90","0.001"],["77377.00","0.001"],["77377.10","0.002"],["77377.20","0.001"],["77377.50","0.034"],["77377.60","0.001"],["77377.70","0.001"],["77377.90","14.001"],["77378.00","0.001"],["77378.20","0.001"]],"u":101055721,"seq":800573305330},"cts":1787954782125}
{"topic":"orderbook.50.BTCUSDT","type":"delta","ts":1787954782148,"data":{"s":"BTCUSDT","b":[["77367.90","8.059"],["77367.80","5.710"],["77367.70","1.975"],["77367.60","1.319"],["77367.50","0.176"],["77367.40","0.070"],["77367.30","0.438"],["77367.20","0"],["77367.10","0.440"],["77366.90","0"],["77366.70","0.019"],["77366.50","0.019"],["77366.40","1.957"],["77366.30","0"],["77366.20","0.002"],["77365.80","0"],["77365.70","0"],["77365.50","0.454"],["77365.00","0"],["77364.90","0"],["77364.70","0.221"],["77364.60","3.216"],["77364.00","0.050"],["77363.80","0"],["77363.60","0.684"],["77363.50","0"],["77363.40","0.002"],["77363.30","0.962"],["77363.20","0"],["77362.90","0.131"],["77362.20","0.004"],["77360.50","0"],["77360.10","1.426"],["77359.80","1.937"],["77359.40","0.209"],["77359.20","0.001"],["77359.00","0.258"],["77358.90","0.001"],["77358.80","0.001"],["77358.70","0.002"],["77358.60","0.069"],["77358.30","0.006"]],"a":[["77368.00","14.002"],["77368.10","0.004"],["77368.60","0"],["77371.00","0"],["77375.80","0.370"],["77376.00","0.003"],["77376.90","0"],["77378.40","0.002"],["77378.50","0.009"]],"u":101055722,"seq":800573307004},"cts":1787954782146}
{"topic":"orderbook.50.BTCUSDT","type":"delta","ts":1787954782168,"data":{"s":"BTCUSDT","b":[["77367.90","8.072"],["77367.80","4.100"],["77367.70","0.070"],["77367.60","0"],["77367.30","0.199"],["77366.70","0"],["77366.60","0"],["77366.50","0"],["77366.10","0.001"],["77365.50","0.455"],["77364.60","3.201"],["77363.30","0.664"],["77358.20","0.002"],["77357.90","0.001"],["77357.60","0.002"]],"a":[["77368.00","13.372"],["77375.00","0.014"],["77376.50","0.001"],["77378.50","0"]],"u":101055723,"seq":800573307318},"cts":1787954782167}
{"topic":"orderbook.50.BTCUSDT","type":"delta","ts":1787954782188,"data":{"s":"BTCUSDT","b":[["77367.90","8.215"],["77367.80","2.147"],["77366.40","1.938"],["77366.10","0.002"],["77365.50","0.456"],["77360.20","1.427"],["77357.60","0"]],"a":[],"u":101055724,"seq":800573307481},"cts":1787954782186}
{"topic":"orderbook.50.BTCUSDT","type":"delta","ts":1787954782208,"data":{"s":"BTCUSDT","b":[["77367.90","8.273"],["77366.50","0.331"],["77366.30","0.001"],["77364.80","0.337"],["77364.60","2.680"],["77360.30","0.129"],["77360.20","1.298"],["77359.80","2.195"],["77359.70","0.039"],["77359.00","0"],["77358.30","0"],["77358.20","0"],["77357.90","0"]],"a":[["77373.60","0"],["77374.80","0"],["77376.50","0"],["77378.00","0"],["77378.50","0.009"],["77378.70","0.001"],["77378.80","0.002"],["77379.10","0.001"]],"u":101055725,"seq":800573307643},"cts":1787954782207}
{"topic":"orderbook.50.BTCUSDT","type":"delta","ts":1787954782228,"data":{"s":"BTCUSDT","b":[["77364.10","0.688"],["77363.60","0"],["77363.40","0.003"],["77359.70","0.038"]],"a":[],"u":101055726,"seq":800573307746},"cts":1787954782227}
{"topic":"orderbook.50.BTCUSDT","type":"delta","ts":1787954782248,"data":{"s":"BTCUSDT","b":[["77366.50","1.368"],["77362.80","0.777"],["77360.60","0.001"],["77358.60","0"]],"a":[["77368.10","0.003"],["77368.50","0.003"]],"u":101055727,"seq":800573307844},"cts":1787954782246}
{"topic":"orderbook.50.BTCUSDT","type":"delta","ts":1787954782268,"data":{"s":"BTCUSDT","b":[["77366.60","1.298"],["77364.00","0.180"],["77360.20","0"],["77359.90","1.696"],["77358.70","0.003"]],"a":[["77378.00","0.001"],["77379.10","0"]],"u":101055728,"seq":800573307918},"cts":1787954782266}
{"topic":"orderbook.50.BTCUSDT","type":"delta","ts":1787954782288,"data":{"s":"BTCUSDT","b":[["77360.60","0.002"],["77360.30","0"],["77360.20","0.129"]],"a":[["77378.30","0.001"],["77378.80","0"]],"u":101055729,"seq":800573307987},"cts":1787954782286}
{"topic":"orderbook.50.BTCUSDT","type":"delta","ts":1787954782308,"data":{"s":"BTCUSDT","b":[["77367.90","8.384"],["77364.60","2.674"],["77360.00","0.276"],["77359.80","1.937"]],"a":[],"u":101055730,"seq":800573308068},"cts":1787954782306}
{"topic":"orderbook.50.BTCUSDT","type":"delta","ts":1787954782328,"data":{"s":"BTCUSDT","b":[["77360.20","0"],["77358.60","0.069"]],"a":[],"u":101055731,"seq":800573308117},"cts":1787954782325}
{"topic":"orderbook.50.BTCUSDT","type":"delta","ts":1787954782368,"data":{"s":"BTCUSDT","b":[["77367.90","8.398"]],"a":[],"u":101055732,"seq":800573308249},"cts":1787954782365}
{"topic":"orderbook.50.BTCUSDT","type":"delta","ts":1787954782408,"data":{"s":"BTCUSDT","b":[["77367.90","8.298"],["77364.80","0"],["77358.50","0.253"]],"a":[],"u":101055733,"seq":800573308369},"cts":1787954782407}
{"topic":"orderbook.50.BTCUSDT","type":"delta","ts":1787954782448,"data":{"s":"BTCUSDT","b":[["77367.10","0.209"]],"a":[],"u":101055734,"seq":800573308482},"cts":1787954782447}
{"topic":"orderbook.50.BTCUSDT","type":"delta","ts":1787954782468,"data":{"s":"BTCUSDT","b":[["77366.50","1.498"],["77362.90","0.001"]],"a":[],"u":101055735,"seq":800573308542},"cts":1787954782466}
{"topic":"orderbook.50.BTCUSDT","type":"delta","ts":1787954782508,"data":{"s":"BTCUSDT","b":[["77360.10","1.684"],["77360.00","0.018"]],"a":[],"u":101055736,"seq":800573308629},"cts":1787954782507}
{"topic":"orderbook.50.BTCUSDT","type":"delta","ts":1787954782528,"data":{"s":"BTCUSDT","b":[["77367.90","8.302"],["77367.70","0"],["77364.70","0.150"],["77364.60","2.608"],["77360.10","1.426"],["77360.00","0.276"],["77358.30","0.006"]],"a":[],"u":101055737,"seq":800573308696},"cts":1787954782526}
{"topic":"orderbook.50.BTCUSDT","type":"delta","ts":1787954782608,"data":{"s":"BTCUSDT","b":[["77364.60","2.583"]],"a":[],"u":101055738,"seq":800573308874},"cts":1787954782607}
{"topic":"orderbook.50.BTCUSDT","type":"delta","ts":1787954782629,"data":{"s":"BTCUSDT","b":[["77365.90","0.002"],["77364.60","2.565"],["77358.30","0"]],"a":[],"u":101055739,"seq":800573308933},"cts":1787954782625}
{"topic":"orderbook.50.BTCUSDT","type":"delta","ts":1787954782648,"data":{"s":"BTCUSDT","b":[["77367.90","8.320"],["77364.60","2.540"]],"a":[],"u":101055740,"seq":800573308999},"cts":1787954782647}
{"topic":"orderbook.50.BTCUSDT","type":"delta","ts":1787954782668,"data":{"s":"BTCUSDT","b":[["77367.90","8.345"],["77364.60","2.515"],["77358.60","0.144"]],"a":[],"u":101055741,"seq":800573309043},"cts":1787954782666}
{"topic":"orderbook.50.BTCUSDT","type":"delta","ts":1787954782689,"data":{"s":"BTCUSDT","b":[["77364.50","0.008"],["77360.00","0.018"],["77359.00","0.258"],["77358.50","0"]],"a":[],"u":101055742,"seq":800573309094},"cts":1787954782687}
{"topic":"orderbook.50.BTCUSDT","type":"delta","ts":1787954782708,"data":{"s":"BTCUSDT","b":[["77367.90","8.349"],["77364.60","2.511"],["77362.80","0.002"],["77359.50","0.258"],["77359.00","0"]],"a":[],"u":101055743,"seq":800573309149},"cts":1787954782706}
{"topic":"orderbook.50.BTCUSDT","type":"delta","ts":1787954782728,"data":{"s":"BTCUSDT","b":[["77367.90","8.374"],["77366.70","1.292"],["77366.60","0.006"],["77359.80","2.195"],["77359.50","0"]],"a":[],"u":101055744,"seq":800573309195},"cts":1787954782716}
{"topic":"orderbook.50.BTCUSDT","type":"delta","ts":1787954782748,"data":{"s":"BTCUSDT","b":[["77367.90","8.399"],["77366.80","1.648"],["77366.70","0"],["77366.50","1.167"],["77364.60","3.160"],["77364.10","0.001"],["77362.80","0.777"]],"a":[],"u":101055745,"seq":800573309268},"cts":1787954782745}
{"topic":"orderbook.50.BTCUSDT","type":"delta","ts":1787954782768,"data":{"s":"BTCUSDT","b":[["77366.90","1.292"],["77366.80","0.356"],["77364.60","2.511"],["77364.10","0.688"],["77358.60","0"]],"a":[],"u":101055746,"seq":800573309334},"cts":1787954782766}
{"topic":"orderbook.50.BTCUSDT","type":"delta","ts":1787954782788,"data":{"s":"BTCUSDT","b":[["77367.00","1.298"],["77366.90","0"],["77366.60","0"],["77362.20","0.280"],["77360.30","0.326"]],"a":[],"u":101055747,"seq":800573309390},"cts":1787954782787}
{"topic":"orderbook.50.BTCUSDT","type":"delta","ts":1787954782808,"data":{"s":"BTCUSDT","b":[["77367.80","2.149"],["77367.20","1.292"],["77367.00","0.006"],["77366.40","1.939"],["77366.30","0"],["77359.80","1.937"],["77359.70","0.296"]],"a":[],"u":101055748,"seq":800573309441},"cts":1787954782806}
{"topic":"orderbook.50.BTCUSDT","type":"delta","ts":1787954782828,"data":{"s":"BTCUSDT","b":[["77367.40","1.368"],["77367.20","0"],["77367.00","0"],["77358.60","0.144"],["77358.50","0.253"]],"a":[],"u":101055749,"seq":800573309495},"cts":1787954782825}
{"topic":"orderbook.50.BTCUSDT","type":"delta","ts":1787954782848,"data":{"s":"BTCUSDT","b":[["77367.60","1.292"],["77367.40","0.076"],["77364.50","0.009"],["77358.50","0"]],"a":[],"u":101055750,"seq":800573309550},"cts":1787954782847}
{"topic":"orderbook.50.BTCUSDT","type":"delta","ts":1787954782868,"data":{"s":"BTCUSDT","b":[["77367.70","1.292"],["77367.60","0"],["77367.40","0.070"],["77359.70","0.038"],["77359.50","0.258"],["77358.60","0"]],"a":[],"u":101055751,"seq":800573309584},"cts":1787954782859}
{"topic":"orderbook.50.BTCUSDT","type":"delta","ts":1787954782888,"data":{"s":"BTCUSDT","b":[["77367.80","3.441"],["77367.70","0"],["77358.60","0.144"]],"a":[],"u":101055752,"seq":800573309645},"cts":1787954782882}
{"topic":"orderbook.50.BTCUSDT","type":"delta","ts":1787954782908,"data":{"s":"BTCUSDT","b":[["77367.90","8.341"],["77367.80","2.147"],["77366.60","1.292"],["77358.60","0"]],"a":[],"u":101055753,"seq":800573309719},"cts":1787954782907}
{"topic":"orderbook.50.BTCUSDT","type":"delta","ts":1787954782928,"data":{"s":"BTCUSDT","b":[["77367.90","8.470"],["77366.90","0.006"],["77364.60","2.382"],["77358.70","0"]],"a":[],"u":101055754,"seq":800573309768},"cts":1787954782923}
{"topic":"orderbook.50.BTCUSDT","type":"delta","ts":1787954782948,"data":{"s":"BTCUSDT","b":[["77367.80","2.149"],["77366.90","0"],["77358.70","0.003"]],"a":[],"u":101055755,"seq":800573309824},"cts":1787954782947}
{"topic":"orderbook.50.BTCUSDT","type":"delta","ts":1787954782968,"data":{"s":"BTCUSDT","b":[["77366.90","0.006"],["77364.70","0.520"],["77358.70","0"]],"a":[],"u":101055756,"seq":800573309898},"cts":1787954782967}
{"topic":"orderbook.50.BTCUSDT","type":"delta","ts":1787954782988,"data":{"s":"BTCUSDT","b":[["77364.50","0.008"]],"a":[],"u":101055757,"seq":800573309938},"cts":1787954782985}
{"topic":"orderbook.50.BTCUSDT","type":"delta","ts":1787954783008,"data":{"s":"BTCUSDT","b":[["77367.90","8.469"]],"a":[],"u":101055758,"seq":800573310021},"cts":1787954783006}
{"topic":"orderbook.50.BTCUSDT","type":"delta","ts":1787954783029,"data":{"s":"BTCUSDT","b":[["77360.00","0.083"]],"a":[],"u":101055759,"seq":800573310083},"cts":1787954783024}
{"topic":"orderbook.50.BTCUSDT","type":"delta","ts":1787954783068,"data":{"s":"BTCUSDT","b":[["77367.90","8.468"]],"a":[],"u":101055760,"seq":800573310165},"cts":1787954783066}
{"topic":"orderbook.50.BTCUSDT","type":"delta","ts":1787954783109,"data":{"s":"BTCUSDT","b":[["77366.50","1.168"],["77366.40","1.938"]],"a":[],"u":101055761,"seq":800573310222},"cts":1787954783107}
{"topic":"orderbook.50.BTCUSDT","type":"delta","ts":1787954783148,"data":{"s":"BTCUSDT","b":[["77364.10","0.001"],["77363.40","0.707"]],"a":[],"u":101055762,"seq":800573310289},"cts":1787954783147}
{"topic":"orderbook.50.BTCUSDT","type":"delta","ts":1787954783168,"data":{"s":"BTCUSDT","b":[["77367.80","2.147"],["77364.70","0.150"],["77363.60","0.002"],["77363.50","1.150"],["77363.30","0.001"],["77359.50","0"],["77359.30","0.258"],["77358.90","0"],["77358.80","0"]],"a":[],"u":101055763,"seq":800573310349},"cts":1787954783165}
{"topic":"orderbook.50.BTCUSDT","type":"delta","ts":1787954783188,"data":{"s":"BTCUSDT","b":[["77367.80","2.149"],["77363.60","0.680"],["77363.40","0.003"]],"a":[],"u":101055764,"seq":800573310382},"cts":1787954783183}
{"topic":"orderbook.50.BTCUSDT","type":"delta","ts":1787954783208,"data":{"s":"BTCUSDT","b":[["77366.50","1.167"],["77366.40","1.939"]],"a":[],"u":101055765,"seq":800573310413},"cts":1787954783207}
{"topic":"orderbook.50.BTCUSDT","type":"delta","ts":1787954783248,"data":{"s":"BTCUSDT","b":[["77367.80","2.147"]],"a":[["77368.00","13.379"]],"u":101055766,"seq":800573310511},"cts":1787954783247}
{"topic":"orderbook.50.BTCUSDT","type":"delta","ts":1787954783268,"data":{"s":"BTCUSDT","b":[["77367.80","2.149"]],"a":[],"u":101055767,"seq":800573310553},"cts":1787954783266}
{"topic":"orderbook.50.BTCUSDT","type":"delta","ts":1787954783289,"data":{"s":"BTCUSDT","b":[["77367.80","2.147"]],"a":[],"u":101055768,"seq":800573310601},"cts":1787954783286}
{"topic":"orderbook.50.BTCUSDT","type":"delta","ts":1787954783308,"data":{"s":"BTCUSDT","b":[["77367.80","2.149"]],"a":[],"u":101055769,"seq":800573310639},"cts":1787954783303}
{"topic":"orderbook.50.BTCUSDT","type":"delta","ts":1787954783328,"data":{"s":"BTCUSDT","b":[["77367.80","2.147"],["77364.60","2.282"],["77363.60","0.002"],["77362.90","0.685"],["77359.30","0"],["77358.90","0.001"]],"a":[["77368.00","13.510"]],"u":101055770,"seq":800573310759},"cts":1787954783327}
{"topic":"orderbook.50.BTCUSDT","type":"delta","ts":1787954783348,"data":{"s":"BTCUSDT","b":[["77367.80","2.149"]],"a":[],"u":101055771,"seq":800573310802},"cts":1787954783345}
{"topic":"orderbook.50.BTCUSDT","type":"delta","ts":1787954783368,"data":{"s":"BTCUSDT","b":[["77364.60","2.242"]],"a":[],"u":101055772,"seq":800573310839},"cts":1787954783365}
{"topic":"orderbook.50.BTCUSDT","type":"delta","ts":1787954783388,"data":{"s":"BTCUSDT","b":[["77367.80","2.147"],["77366.80","0"],["77362.90","0.001"],["77362.30","0.682"]],"a":[],"u":101055773,"seq":800573310913},"cts":1787954783386}
{"topic":"orderbook.50.BTCUSDT","type":"delta","ts":1787954783408,"data":{"s":"BTCUSDT","b":[["77366.90","0"],["77366.70","0.006"],["77366.50","0.130"],["77366.40","0.003"],["77365.50","0.212"],["77364.70","0"],["77362.80","0.002"],["77358.80","0.001"]],"a":[["77377.50","0.038"],["77377.80","4.189"],["77378.10","0.002"],["77378.50","0"],["77378.70","0"]],"u":101055774,"seq":800573310974},"cts":1787954783407}
{"topic":"orderbook.50.BTCUSDT","type":"delta","ts":1787954783429,"data":{"s":"BTCUSDT","b":[["77367.90","7.615"],["77367.80","1.611"],["77367.40","0"],["77366.70","0"],["77366.60","0"],["77362.30","0"],["77361.20","0.737"],["77360.20","1.292"],["77358.70","0.003"],["77358.60","0.144"]],"a":[["77371.20","0.007"],["77374.50","0.002"],["77374.90","0.002"],["77376.50","0.002"],["77378.30","0"],["77378.40","0"]],"u":101055775,"seq":800573311051},"cts":1787954783426}
{"topic":"orderbook.50.BTCUSDT","type":"delta","ts":1787954783448,"data":{"s":"BTCUSDT","b":[["77367.80","1.203"],["77364.70","1.298"],["77360.40","0.129"],["77360.20","0"],["77358.60","0"]],"a":[["77374.40","0.002"],["77378.20","0"]],"u":101055776,"seq":800573311105},"cts":1787954783446}
{"topic":"orderbook.50.BTCUSDT","type":"delta","ts":1787954783468,"data":{"s":"BTCUSDT","b":[["77367.90","7.609"],["77360.40","0"],["77358.60","0.144"]],"a":[["77374.50","2.769"]],"u":101055777,"seq":800573311146},"cts":1787954783464}
{"topic":"orderbook.50.BTCUSDT","type":"delta","ts":1787954783489,"data":{"s":"BTCUSDT","b":[["77367.80","1.201"],["77366.40","0.002"],["77364.50","0.009"]],"a":[["77373.30","0.002"],["77373.80","0.003"],["77374.50","0.002"],["77377.50","0.036"],["77377.90","14.002"],["77378.10","0"]],"u":101055778,"seq":800573311205},"cts":1787954783482}
{"topic":"orderbook.50.BTCUSDT","type":"delta","ts":1787954783508,"data":{"s":"BTCUSDT","b":[["77367.90","7.618"],["77364.80","0.336"],["77364.50","0.008"],["77363.40","0.004"],["77358.60","0"]],"a":[["77373.30","0"],["77378.20","0.002"]],"u":101055779,"seq":800573311252},"cts":1787954783507}
{"topic":"orderbook.50.BTCUSDT","type":"delta","ts":1787954783528,"data":{"s":"BTCUSDT","b":[["77367.90","7.235"],["77367.80","1.568"],["77364.90","1.675"],["77364.70","0.006"],["77364.50","0.009"],["77363.40","0.003"],["77358.70","0"]],"a":[["77373.60","0.002"],["77373.80","0.001"],["77375.40","0.002"],["77378.00","0"],["77378.20","0"]],"u":101055780,"seq":800573311330},"cts":1787954783527}
{"topic":"orderbook.50.BTCUSDT","type":"delta","ts":1787954783548,"data":{"s":"BTCUSDT","b":[],"a":[["77373.60","0"],["77378.00","0.001"]],"u":101055781,"seq":800573311374},"cts":1787954783544}
{"topic":"orderbook.50.BTCUSDT","type":"delta","ts":1787954783608,"data":{"s":"BTCUSDT","b":[["77365.10","1.936"],["77365.00","1.292"],["77364.90","0.383"],["77358.90","0"],["77358.80","0"]],"a":[],"u":101055782,"seq":800573311454},"cts":1787954783607}
{"topic":"orderbook.50.BTCUSDT","type":"delta","ts":1787954783628,"data":{"s":"BTCUSDT","b":[["77367.80","2.212"],["77365.20","1.298"],["77365.00","0"],["77364.70","0"],["77359.70","0.032"],["77358.90","0.001"]],"a":[["77374.40","0"],["77375.90","0.004"],["77378.20","0.001"]],"u":101055783,"seq":800573311497},"cts":1787954783623}
{"topic":"orderbook.50.BTCUSDT","type":"delta","ts":1787954783648,"data":{"s":"BTCUSDT","b":[["77367.80","2.214"],["77364.80","0"],["77358.80","0.001"]],"a":[["77374.90","0"],["77377.00","0.003"],["77378.40","0.002"]],"u":101055784,"seq":800573311535},"cts":1787954783640}
{"topic":"orderbook.50.BTCUSDT","type":"delta","ts":1787954783668,"data":{"s":"BTCUSDT","b":[],"a":[["77378.30","0.001"],["77378.40","0"]],"u":101055785,"seq":800573311549},"cts":1787954783654}
{"topic":"orderbook.50.BTCUSDT","type":"delta","ts":1787954783688,"data":{"s":"BTCUSDT","b":[["77364.60","2.005"]],"a":[],"u":101055786,"seq":800573311595},"cts":1787954783687}
{"topic":"orderbook.50.BTCUSDT","type":"delta","ts":1787954783708,"data":{"s":"BTCUSDT","b":[["77365.90","0.006"],["77365.00","0.001"],["77364.50","0.008"],["77362.80","0.004"],["77358.80","0"]],"a":[],"u":101055787,"seq":800573311645},"cts":1787954783706}
{"topic":"orderbook.50.BTCUSDT","type":"delta","ts":1787954783728,"data":{"s":"BTCUSDT","b":[],"a":[["77375.40","0"],["77377.50","0.038"],["77378.40","0.002"]],"u":101055788,"seq":800573311677},"cts":1787954783724}
{"topic":"orderbook.50.BTCUSDT","type":"delta","ts":1787954783828,"data":{"s":"BTCUSDT","b":[["77367.80","2.212"]],"a":[],"u":101055789,"seq":800573311790},"cts":1787954783825}
{"topic":"orderbook.50.BTCUSDT","type":"delta","ts":1787954783848,"data":{"s":"BTCUSDT","b":[["77367.80","2.214"]],"a":[],"u":101055790,"seq":800573311817},"cts":1787954783843}
{"topic":"orderbook.50.BTCUSDT","type":"delta","ts":1787954783988,"data":{"s":"BTCUSDT","b":[],"a":[["77375.90","0.002"],["77378.00","0.003"]],"u":101055791,"seq":800573311944},"cts":1787954783981}
{"topic":"orderbook.50.BTCUSDT","type":"delta","ts":1787954784008,"data":{"s":"BTCUSDT","b":[["77364.50","0.009"]],"a":[],"u":101055792,"seq":800573311964},"cts":1787954784004}
{"topic":"orderbook.50.BTCUSDT","type":"delta","ts":1787954784068,"data":{"s":"BTCUSDT","b":[["77365.30","0.353"],["77358.90","0"]],"a":[["77378.10","0.001"],["77378.30","0"]],"u":101055793,"seq":800573312109},"cts":1787954784066}
