{"topic":"orderbook.50.BTCUSDT","type":"delta","ts":1787954784089,"data":{"s":"BTCUSDT","b":[["77367.80","2.212"],["77365.40","1.292"],["77365.20","0.006"],["77363.60","0.008"],["77359.20","0"]],"a":[["77376.50","0"],["77377.00","0.001"],["77377.50","0.036"],["77378.50","0.011"]],"u":101055794,"seq":800573312163},"cts":1787954784084}
{"topic":"orderbook.50.BTCUSDT","type":"delta","ts":1787954784108,"data":{"s":"BTCUSDT","b":[["77367.80","2.214"],["77365.60","0.006"],["77365.20","0"]],"a":[],"u":101055795,"seq":800573312192},"cts":1787954784106}
{"topic":"orderbook.50.BTCUSDT","type":"delta","ts":1787954784149,"data":{"s":"BTCUSDT","b":[["77367.80","2.212"]],"a":[["77378.00","0.001"]],"u":101055796,"seq":800573312246},"cts":1787954784146}
{"topic":"orderbook.50.BTCUSDT","type":"delta","ts":1787954784189,"data":{"s":"BTCUSDT","b":[["77367.90","7.255"],["77365.80","0.370"],["77359.40","0"]],"a":[["77378.50","0.009"]],"u":101055797,"seq":800573312351},"cts":1787954784185}
{"topic":"orderbook.50.BTCUSDT","type":"delta","ts":1787954784208,"data":{"s":"BTCUSDT","b":[["77367.80","2.214"]],"a":[],"u":101055798,"seq":800573312405},"cts":1787954784206}
{"topic":"orderbook.50.BTCUSDT","type":"delta","ts":1787954784228,"data":{"s":"BTCUSDT","b":[["77367.80","2.212"],["77361.30","0.728"],["77361.20","0"]],"a":[["77378.10","0"],["77378.30","0.001"]],"u":101055799,"seq":800573312478},"cts":1787954784227}
{"topic":"orderbook.50.BTCUSDT","type":"delta","ts":1787954784249,"data":{"s":"BTCUSDT","b":[["77367.80","2.214"],["77361.30","0"],["77361.20","0.735"]],"a":[],"u":101055800,"seq":800573312528},"cts":1787954784246}
{"topic":"orderbook.50.BTCUSDT","type":"delta","ts":1787954784269,"data":{"s":"BTCUSDT","b":[["77367.80","2.212"]],"a":[["77368.00","13.500"],["77368.50","0.002"],["77368.90","0.057"],["77378.20","0.057"],["77378.30","0.009"],["77378.40","0.130"]],"u":101055801,"seq":800573312721},"cts":1787954784266}
{"topic":"orderbook.50.BTCUSDT","type":"delta","ts":1787954784288,"data":{"s":"BTCUSDT","b":[["77367.80","2.214"]],"a":[["77368.10","0.005"]],"u":101055802,"seq":800573312761},"cts":1787954784286}
{"topic":"orderbook.50.BTCUSDT","type":"delta","ts":1787954784308,"data":{"s":"BTCUSDT","b":[],"a":[["77378.30","0.008"]],"u":101055803,"seq":800573312788},"cts":1787954784306}
{"topic":"orderbook.50.BTCUSDT","type":"delta","ts":1787954784328,"data":{"s":"BTCUSDT","b":[["77367.90","9.191"]],"a":[],"u":101055804,"seq":800573312816},"cts":1787954784326}
{"topic":"orderbook.50.BTCUSDT","type":"delta","ts":1787954784348,"data":{"s":"BTCUSDT","b":[["77367.90","9.193"],["77367.80","2.212"]],"a":[],"u":101055805,"seq":800573312863},"cts":1787954784343}
{"topic":"orderbook.50.BTCUSDT","type":"delta","ts":1787954784368,"data":{"s":"BTCUSDT","b":[["77367.80","2.214"],["77364.50","0.008"]],"a":[],"u":101055806,"seq":800573312902},"cts":1787954784363}
{"topic":"orderbook.50.BTCUSDT","type":"delta","ts":1787954784388,"data":{"s":"BTCUSDT","b":[],"a":[["77378.30","0.009"]],"u":101055807,"seq":800573312927},"cts":1787954784379}
{"topic":"orderbook.50.BTCUSDT","type":"delta","ts":1787954784408,"data":{"s":"BTCUSDT","b":[["77365.30","0.354"],["77365.00","0"],["77359.40","0.209"]],"a":[],"u":101055808,"seq":800573312965},"cts":1787954784406}
{"topic":"orderbook.50.BTCUSDT","type":"delta","ts":1787954784548,"data":{"s":"BTCUSDT","b":[["77367.90","9.263"],["77367.80","2.212"]],"a":[],"u":101055809,"seq":800573313145},"cts":1787954784546}
{"topic":"orderbook.50.BTCUSDT","type":"delta","ts":1787954784568,"data":{"s":"BTCUSDT","b":[["77367.80","2.214"],["77365.30","0.001"]],"a":[],"u":101055810,"seq":800573313184},"cts":1787954784566}
{"topic":"orderbook.50.BTCUSDT","type":"delta","ts":1787954784589,"data":{"s":"BTCUSDT","b":[["77365.60","1.298"],["77365.40","0"],["77364.50","0.009"],["77359.20","0.001"]],"a":[],"u":101055811,"seq":800573313218},"cts":1787954784583}
{"topic":"orderbook.50.BTCUSDT","type":"delta","ts":1787954784608,"data":{"s":"BTCUSDT","b":[["77367.80","2.212"],["77365.90","1.298"],["77365.60","0.006"]],"a":[],"u":101055812,"seq":800573313272},"cts":1787954784607}
{"topic":"orderbook.50.BTCUSDT","type":"delta","ts":1787954784628,"data":{"s":"BTCUSDT","b":[["77367.80","2.214"],["77366.00","1.292"],["77365.90","0.006"],["77365.60","0"]],"a":[],"u":101055813,"seq":800573313303},"cts":1787954784625}
{"topic":"orderbook.50.BTCUSDT","type":"delta","ts":1787954784649,"data":{"s":"BTCUSDT","b":[["77367.80","2.212"],["77366.10","1.294"],["77366.00","0"],["77358.90","0.001"]],"a":[],"u":101055814,"seq":800573313341},"cts":1787954784643}
{"topic":"orderbook.50.BTCUSDT","type":"delta","ts":1787954784668,"data":{"s":"BTCUSDT","b":[["77367.80","2.214"],["77366.20","1.294"],["77366.10","0.002"]],"a":[],"u":101055815,"seq":800573313376},"cts":1787954784661}
{"topic":"orderbook.50.BTCUSDT","type":"delta","ts":1787954784688,"data":{"s":"BTCUSDT","b":[["77366.30","1.292"],["77366.20","0.002"],["77365.80","0.371"],["77365.30","0"]],"a":[],"u":101055816,"seq":800573313423},"cts":1787954784685}
{"topic":"orderbook.50.BTCUSDT","type":"delta","ts":1787954784709,"data":{"s":"BTCUSDT","b":[["77367.90","9.243"],["77366.40","1.294"],["77366.30","0"],["77365.90","0.007"],["77365.80","0.370"],["77358.80","0.001"]],"a":[],"u":101055817,"seq":800573313470},"cts":1787954784705}
{"topic":"orderbook.50.BTCUSDT","type":"delta","ts":1787954784728,"data":{"s":"BTCUSDT","b":[["77366.40","0.002"],["77365.20","1.292"],["77358.80","0"]],"a":[],"u":101055818,"seq":800573313503},"cts":1787954784725}
{"topic":"orderbook.50.BTCUSDT","type":"delta","ts":1787954784749,"data":{"s":"BTCUSDT","b":[["77365.30","0.006"],["77364.50","0.008"],["77358.90","0"]],"a":[],"u":101055819,"seq":800573313526},"cts":1787954784742}
{"topic":"orderbook.50.BTCUSDT","type":"delta","ts":1787954784809,"data":{"s":"BTCUSDT","b":[["77365.90","0.006"],["77365.10","1.937"]],"a":[],"u":101055820,"seq":800573313574},"cts":1787954784806}
{"topic":"orderbook.50.BTCUSDT","type":"delta","ts":1787954784848,"data":{"s":"BTCUSDT","b":[["77367.80","2.212"]],"a":[],"u":101055821,"seq":800573313632},"cts":1787954784846}
{"topic":"orderbook.50.BTCUSDT","type":"delta","ts":1787954784868,"data":{"s":"BTCUSDT","b":[["77367.80","2.214"]],"a":[],"u":101055822,"seq":800573313653},"cts":1787954784859}
{"topic":"orderbook.50.BTCUSDT","type":"delta","ts":1787954784888,"data":{"s":"BTCUSDT","b":[],"a":[["77368.90","0.059"]],"u":101055823,"seq":800573313689},"cts":1787954784882}
{"topic":"orderbook.50.BTCUSDT","type":"delta","ts":1787954785468,"data":{"s":"BTCUSDT","b":[["77367.80","2.212"]],"a":[],"u":101055824,"seq":800573314299},"cts":1787954785459}
{"topic":"orderbook.50.BTCUSDT","type":"delta","ts":1787954785488,"data":{"s":"BTCUSDT","b":[["77367.80","2.214"]],"a":[],"u":101055825,"seq":800573314351},"cts":1787954785484}
{"topic":"orderbook.50.BTCUSDT","type":"delta","ts":1787954785528,"data":{"s":"BTCUSDT","b":[["77365.80","0"],["77358.90","0.001"]],"a":[],"u":101055826,"seq":800573314418},"cts":1787954785525}
{"topic":"orderbook.50.BTCUSDT","type":"delta","ts":1787954785608,"data":{"s":"BTCUSDT","b":[["77367.90","12.073"],["77367.80","2.212"],["77365.80","0.370"],["77365.30","0.370"],["77363.70","0.663"],["77362.80","0.779"],["77361.20","0"],["77360.10","1.684"],["77358.90","0"]],"a":[["77368.00","13.491"],["77371.20","0.001"],["77374.50","0.008"],["77376.00","0.001"],["77377.50","0.034"],["77377.80","0"],["77378.70","0.049"]],"u":101055827,"seq":800573314641},"cts":1787954785607}
{"topic":"orderbook.50.BTCUSDT","type":"delta","ts":1787954785628,"data":{"s":"BTCUSDT","b":[["77367.90","12.075"],["77360.10","1.426"]],"a":[["77368.00","13.481"]],"u":101055828,"seq":800573314769},"cts":1787954785623}
{"topic":"orderbook.50.BTCUSDT","type":"delta","ts":1787954785648,"data":{"s":"BTCUSDT","b":[["77367.90","12.081"],["77367.80","2.214"]],"a":[],"u":101055829,"seq":800573314839},"cts":1787954785643}
{"topic":"orderbook.50.BTCUSDT","type":"delta","ts":1787954785668,"data":{"s":"BTCUSDT","b":[["77367.80","2.212"]],"a":[],"u":101055830,"seq":800573314901},"cts":1787954785662}
{"topic":"orderbook.50.BTCUSDT","type":"delta","ts":1787954785689,"data":{"s":"BTCUSDT","b":[["77367.70","0.001"],["77365.30","0"],["77365.10","1.936"]],"a":[["77377.90","14.001"]],"u":101055831,"seq":800573314980},"cts":1787954785687}
{"topic":"orderbook.50.BTCUSDT","type":"delta","ts":1787954785728,"data":{"s":"BTCUSDT","b":[["77363.70","0"],["77362.90","0.661"],["77358.90","0.001"]],"a":[],"u":101055832,"seq":800573315088},"cts":1787954785725}
{"topic":"orderbook.50.BTCUSDT","type":"delta","ts":1787954785748,"data":{"s":"BTCUSDT","b":[],"a":[["77377.80","2.334"],["77378.70","0"]],"u":101055833,"seq":800573315137},"cts":1787954785747}
{"topic":"orderbook.50.BTCUSDT","type":"delta","ts":1787954785769,"data":{"s":"BTCUSDT","b":[],"a":[["77371.20","0.007"],["77374.50","0.002"]],"u":101055834,"seq":800573315187},"cts":1787954785760}
{"topic":"orderbook.50.BTCUSDT","type":"delta","ts":1787954785788,"data":{"s":"BTCUSDT","b":[],"a":[["77371.20","0.001"],["77374.50","0.008"]],"u":101055835,"seq":800573315245},"cts":1787954785786}
{"topic":"orderbook.50.BTCUSDT","type":"delta","ts":1787954785808,"data":{"s":"BTCUSDT","b":[["77364.50","0.009"]],"a":[],"u":101055836,"seq":800573315301},"cts":1787954785806}
{"topic":"orderbook.50.BTCUSDT","type":"delta","ts":1787954785828,"data":{"s":"BTCUSDT","b":[],"a":[["77378.40","0.131"]],"u":101055837,"seq":800573315347},"cts":1787954785825}
{"topic":"orderbook.50.BTCUSDT","type":"delta","ts":1787954785889,"data":{"s":"BTCUSDT","b":[],"a":[["77376.00","0.002"]],"u":101055838,"seq":800573315434},"cts":1787954785886}
{"topic":"orderbook.50.BTCUSDT","type":"delta","ts":1787954785929,"data":{"s":"BTCUSDT","b":[["77364.50","0.008"]],"a":[],"u":101055839,"seq":800573315504},"cts":1787954785922}
{"topic":"orderbook.50.BTCUSDT","type":"delta","ts":1787954786248,"data":{"s":"BTCUSDT","b":[["77362.90","0.001"],["77362.30","0.680"],["77358.90","0"]],"a":[["77371.20","0.007"],["77374.50","0.002"]],"u":101055840,"seq":800573315767},"cts":1787954786246}
{"topic":"orderbook.50.BTCUSDT","type":"delta","ts":1787954786328,"data":{"s":"BTCUSDT","b":[["77360.30","0"],["77358.90","0.001"]],"a":[],"u":101055841,"seq":800573315850},"cts":1787954786325}
{"topic":"orderbook.50.BTCUSDT","type":"delta","ts":1787954786349,"data":{"s":"BTCUSDT","b":[],"a":[["77377.80","4.008"]],"u":101055842,"seq":800573315886},"cts":1787954786343}
{"topic":"orderbook.50.BTCUSDT","type":"delta","ts":1787954786408,"data":{"s":"BTCUSDT","b":[["77362.80","1.425"],["77362.30","0"],["77358.80","0.001"]],"a":[["77371.20","0.001"],["77374.50","0.008"]],"u":101055843,"seq":800573315957},"cts":1787954786407}
{"topic":"orderbook.50.BTCUSDT","type":"delta","ts":1787954786428,"data":{"s":"BTCUSDT","b":[],"a":[["77377.90","14.002"],["77378.40","0.130"]],"u":101055844,"seq":800573315991},"cts":1787954786426}
{"topic":"orderbook.50.BTCUSDT","type":"delta","ts":1787954786468,"data":{"s":"BTCUSDT","b":[["77365.80","0"],["77362.80","0.779"],["77362.30","0.687"]],"a":[],"u":101055845,"seq":800573316044},"cts":1787954786463}
{"topic":"orderbook.50.BTCUSDT","type":"delta","ts":1787954786488,"data":{"s":"BTCUSDT","b":[["77362.80","1.425"],["77362.30","0"],["77358.70","0.003"]],"a":[],"u":101055846,"seq":800573316075},"cts":1787954786485}
{"topic":"orderbook.50.BTCUSDT","type":"delta","ts":1787954786589,"data":{"s":"BTCUSDT","b":[["77362.80","0.779"],["77362.30","0.683"],["77358.70","0"]],"a":[],"u":101055847,"seq":800573316181},"cts":1787954786580}
{"topic":"orderbook.50.BTCUSDT","type":"delta","ts":1787954786628,"data":{"s":"BTCUSDT","b":[["77364.60","2.211"]],"a":[],"u":101055848,"seq":800573316235},"cts":1787954786625}
{"topic":"orderbook.50.BTCUSDT","type":"delta","ts":1787954786748,"data":{"s":"BTCUSDT","b":[["77362.80","1.425"],["77362.30","0"],["77358.70","0.003"]],"a":[],"u":101055849,"seq":800573316345},"cts":1787954786741}
{"topic":"orderbook.50.BTCUSDT","type":"delta","ts":1787954786868,"data":{"s":"BTCUSDT","b":[["77362.80","0.779"],["77362.30","0.688"],["77358.70","0"]],"a":[],"u":101055850,"seq":800573316448},"cts":1787954786863}
{"topic":"orderbook.50.BTCUSDT","type":"delta","ts":1787954786928,"data":{"s":"BTCUSDT","b":[["77364.50","0.009"]],"a":[],"u":101055851,"seq":800573316515},"cts":1787954786913}
{"topic":"orderbook.50.BTCUSDT","type":"delta","ts":1787954786948,"data":{"s":"BTCUSDT","b":[],"a":[["77371.20","0.007"],["77374.50","0.002"]],"u":101055852,"seq":800573316574},"cts":1787954786942}
{"topic":"orderbook.50.BTCUSDT","type":"delta","ts":1787954786968,"data":{"s":"BTCUSDT","b":[],"a":[["77371.20","0.001"],["77374.50","0.008"]],"u":101055853,"seq":800573316609},"cts":1787954786967}
{"topic":"orderbook.50.BTCUSDT","type":"delta","ts":1787954787048,"data":{"s":"BTCUSDT","b":[["77364.50","0.008"]],"a":[],"u":101055854,"seq":800573316695},"cts":1787954787043}
{"topic":"orderbook.50.BTCUSDT","type":"delta","ts":1787954787108,"data":{"s":"BTCUSDT","b":[["77362.30","0.687"]],"a":[],"u":101055855,"seq":800573316754},"cts":1787954787102}
{"topic":"orderbook.50.BTCUSDT","type":"delta","ts":1787954787148,"data":{"s":"BTCUSDT","b":[["77367.90","12.181"]],"a":[],"u":101055856,"seq":800573316835},"cts":1787954787146}
{"topic":"orderbook.50.BTCUSDT","type":"delta","ts":1787954787168,"data":{"s":"BTCUSDT","b":[["77364.60","2.185"],["77362.80","1.425"],["77362.30","0"],["77358.70","0.003"]],"a":[],"u":101055857,"seq":800573316865},"cts":1787954787165}
{"topic":"orderbook.50.BTCUSDT","type":"delta","ts":1787954787189,"data":{"s":"BTCUSDT","b":[["77364.50","0.009"]],"a":[],"u":101055858,"seq":800573316902},"cts":1787954787187}
{"topic":"orderbook.50.BTCUSDT","type":"delta","ts":1787954787228,"data":{"s":"BTCUSDT","b":[["77362.90","0.652"],["77362.80","0.779"]],"a":[],"u":101055859,"seq":800573316958},"cts":1787954787227}
{"topic":"orderbook.50.BTCUSDT","type":"delta","ts":1787954787268,"data":{"s":"BTCUSDT","b":[],"a":[["77368.00","13.467"]],"u":101055860,"seq":800573317013},"cts":1787954787266}
{"topic":"orderbook.50.BTCUSDT","type":"delta","ts":1787954787288,"data":{"s":"BTCUSDT","b":[["77367.90","12.207"],["77358.70","0.067"]],"a":[["77368.90","0.058"],["77369.50","0.004"],["77377.10","0.001"]],"u":101055861,"seq":800573317084},"cts":1787954787286}
{"topic":"orderbook.50.BTCUSDT","type":"delta","ts":1787954787309,"data":{"s":"BTCUSDT","b":[["77364.50","0.008"]],"a":[],"u":101055862,"seq":800573317112},"cts":1787954787305}
{"success":true,"ret_msg":"pong","conn_id":"da7tn48ppdl4sp3gt52g-iavr","req_id":"","op":"ping"}
{"topic":"orderbook.50.BTCUSDT","type":"delta","ts":1787954787648,"data":{"s":"BTCUSDT","b":[["77362.90","0.001"],["77362.80","1.433"]],"a":[],"u":101055863,"seq":800573317406},"cts":1787954787647}
{"topic":"orderbook.50.BTCUSDT","type":"delta","ts":1787954787669,"data":{"s":"BTCUSDT","b":[["77359.70","0"],["77358.60","0.144"]],"a":[],"u":101055864,"seq":800573317428},"cts":1787954787666}
{"topic":"orderbook.50.BTCUSDT","type":"delta","ts":1787954787848,"data":{"s":"BTCUSDT","b":[["77364.60","1.979"],["77362.20","0.004"]],"a":[],"u":101055865,"seq":800573317550},"cts":1787954787845}
{"topic":"orderbook.50.BTCUSDT","type":"delta","ts":1787954788008,"data":{"s":"BTCUSDT","b":[["77364.60","2.183"],["77363.70","0.036"],["77362.60","0.300"],["77358.60","0"]],"a":[],"u":101055866,"seq":800573317679},"cts":1787954788007}
{"topic":"orderbook.50.BTCUSDT","type":"delta","ts":1787954788088,"data":{"s":"BTCUSDT","b":[["77362.80","0.779"],["77362.70","2.592"]],"a":[],"u":101055867,"seq":800573317768},"cts":1787954788084}
{"topic":"orderbook.50.BTCUSDT","type":"delta","ts":1787954788288,"data":{"s":"BTCUSDT","b":[],"a":[["77371.20","0.007"],["77374.50","0.002"]],"u":101055868,"seq":800573317946},"cts":1787954788286}
{"topic":"orderbook.50.BTCUSDT","type":"delta","ts":1787954788309,"data":{"s":"BTCUSDT","b":[["77364.50","0.009"]],"a":[["77371.20","0.001"],["77374.50","0.008"]],"u":101055869,"seq":800573317976},"cts":1787954788300}
{"topic":"orderbook.50.BTCUSDT","type":"delta","ts":1787954788408,"data":{"s":"BTCUSDT","b":[["77364.50","0.008"]],"a":[],"u":101055870,"seq":800573318056},"cts":1787954788402}
{"topic":"orderbook.50.BTCUSDT","type":"delta","ts":1787954788448,"data":{"s":"BTCUSDT","b":[],"a":[["77371.20","0.007"],["77374.50","0.002"]],"u":101055871,"seq":800573318104},"cts":1787954788444}
{"topic":"orderbook.50.BTCUSDT","type":"delta","ts":1787954788469,"data":{"s":"BTCUSDT","b":[["77367.90","12.149"],["77362.70","2.588"]],"a":[["77371.20","0.001"],["77374.50","0.008"]],"u":101055872,"seq":800573318165},"cts":1787954788463}
{"topic":"orderbook.50.BTCUSDT","type":"delta","ts":1787954788568,"data":{"s":"BTCUSDT","b":[],"a":[["77368.00","13.469"]],"u":101055873,"seq":800573318331},"cts":1787954788558}
{"topic":"orderbook.50.BTCUSDT","type":"delta","ts":1787954788668,"data":{"s":"BTCUSDT","b":[],"a":[["77371.20","0.007"],["77374.50","0.002"]],"u":101055874,"seq":800573318475},"cts":1787954788661}
{"topic":"orderbook.50.BTCUSDT","type":"delta","ts":1787954788689,"data":{"s":"BTCUSDT","b":[["77367.90","12.368"]],"a":[["77371.20","0.001"],["77374.50","0.008"]],"u":101055875,"seq":800573318530},"cts":1787954788686}
{"topic":"orderbook.50.BTCUSDT","type":"delta","ts":1787954788728,"data":{"s":"BTCUSDT","b":[],"a":[["77371.20","0.007"],["77374.50","0.002"]],"u":101055876,"seq":800573318556},"cts":1787954788716}
{"topic":"orderbook.50.BTCUSDT","type":"delta","ts":1787954788769,"data":{"s":"BTCUSDT","b":[["77362.70","1.938"],["77361.20","0.771"],["77358.70","0"]],"a":[],"u":101055877,"seq":800573318603},"cts":1787954788754}
{"topic":"orderbook.50.BTCUSDT","type":"delta","ts":1787954789028,"data":{"s":"BTCUSDT","b":[["77359.00","0.200"],["77358.80","0"]],"a":[],"u":101055878,"seq":800573318864},"cts":1787954789021}
{"topic":"orderbook.50.BTCUSDT","type":"delta","ts":1787954789089,"data":{"s":"BTCUSDT","b":[["77367.90","12.373"],["77364.60","2.178"]],"a":[],"u":101055879,"seq":800573318933},"cts":1787954789083}
{"topic":"orderbook.50.BTCUSDT","type":"delta","ts":1787954789328,"data":{"s":"BTCUSDT","b":[["77362.30","0.075"],["77358.90","0"]],"a":[],"u":101055880,"seq":800573319142},"cts":1787954789327}
{"topic":"orderbook.50.BTCUSDT","type":"delta","ts":1787954789428,"data":{"s":"BTCUSDT","b":[["77364.50","0.009"]],"a":[],"u":101055881,"seq":800573319241},"cts":1787954789422}
{"topic":"orderbook.50.BTCUSDT","type":"delta","ts":1787954789528,"data":{"s":"BTCUSDT","b":[["77364.50","0.008"]],"a":[],"u":101055882,"seq":800573319329},"cts":1787954789525}
{"topic":"orderbook.50.BTCUSDT","type":"delta","ts":1787954790208,"data":{"s":"BTCUSDT","b":[["77367.90","12.348"]],"a":[],"u":101055883,"seq":800573319891},"cts":1787954790207}
{"topic":"orderbook.50.BTCUSDT","type":"delta","ts":1787954790228,"data":{"s":"BTCUSDT","b":[],"a":[["77373.60","0.001"],["77378.50","0"]],"u":101055884,"seq":800573319946},"cts":1787954790227}
{"topic":"orderbook.50.BTCUSDT","type":"delta","ts":1787954790469,"data":{"s":"BTCUSDT","b":[["77367.90","12.425"]],"a":[],"u":101055885,"seq":800573320151},"cts":1787954790463}
{"topic":"orderbook.50.BTCUSDT","type":"delta","ts":1787954790549,"data":{"s":"BTCUSDT","b":[["77364.50","0.009"]],"a":[],"u":101055886,"seq":800573320222},"cts":1787954790547}
{"topic":"orderbook.50.BTCUSDT","type":"delta","ts":1787954790669,"data":{"s":"BTCUSDT","b":[["77364.50","0.008"]],"a":[],"u":101055887,"seq":800573320320},"cts":1787954790666}
{"topic":"orderbook.50.BTCUSDT","type":"delta","ts":1787954790929,"data":{"s":"BTCUSDT","b":[["77360.80","0"],["77358.90","0.001"]],"a":[],"u":101055888,"seq":800573320538},"cts":1787954790925}
{"topic":"orderbook.50.BTCUSDT","type":"delta","ts":1787954791148,"data":{"s":"BTCUSDT","b":[],"a":[["77368.00","13.479"]],"u":101055889,"seq":800573320725},"cts":1787954791147}
{"topic":"orderbook.50.BTCUSDT","type":"delta","ts":1787954791208,"data":{"s":"BTCUSDT","b":[["77367.90","12.444"],["77364.60","2.159"]],"a":[],"u":101055890,"seq":800573320793},"cts":1787954791208}
{"topic":"orderbook.50.BTCUSDT","type":"delta","ts":1787954791708,"data":{"s":"BTCUSDT","b":[["77364.50","0.009"]],"a":[],"u":101055891,"seq":800573321265},"cts":1787954791706}
{"topic":"orderbook.50.BTCUSDT","type":"delta","ts":1787954791808,"data":{"s":"BTCUSDT","b":[["77364.50","0.008"]],"a":[],"u":101055892,"seq":800573321368},"cts":1787954791806}
{"topic":"orderbook.50.BTCUSDT","type":"delta","ts":1787954792608,"data":{"s":"BTCUSDT","b":[["77367.90","12.374"]],"a":[],"u":101055893,"seq":800573322025},"cts":1787954792607}
{"topic":"orderbook.50.BTCUSDT","type":"delta","ts":1787954792748,"data":{"s":"BTCUSDT","b":[],"a":[["77368.00","13.477"]],"u":101055894,"seq":800573322142},"cts":1787954792747}
{"topic":"orderbook.50.BTCUSDT","type":"delta","ts":1787954792809,"data":{"s":"BTCUSDT","b":[["77364.50","0.009"]],"a":[],"u":101055895,"seq":800573322213},"cts":1787954792806}
{"topic":"orderbook.50.BTCUSDT","type":"delta","ts":1787954792848,"data":{"s":"BTCUSDT","b":[["77367.90","1.324"],["77367.80","1.964"],["77367.50","0"],["77367.30","0"],["77367.10","0"],["77366.50","0"],["77365.50","0.002"],["77365.20","0"],["77365.10","0"],["77364.90","0"],["77364.70","0.383"],["77364.60","1.885"],["77364.50","0.007"],["77364.00","0.050"],["77363.40","0.001"],["77362.80","0.004"],["77362.70","0"],["77362.60","0.001"],["77362.20","0.002"],["77361.20","0"],["77361.00","0.191"],["77360.10","0.389"],["77360.00","0.018"],["77359.80","0.015"],["77359.20","0.131"],["77358.80","0.001"],["77358.70","0.002"],["77358.60","0.069"],["77358.50","0.253"],["77358.30","0.006"],["77358.20","0.002"],["77357.90","0.001"],["77357.60","0.004"]],"a":[["77368.00","14.683"],["77368.90","0.060"],["77369.90","0.002"],["77370.90","0.002"],["77371.20","4.190"],["77372.00","0.002"],["77374.40","0.002"],["77374.50","0.131"],["77375.50","0.386"],["77377.70","0.259"],["77377.80","4.263"],["77377.90","0"],["77378.00","0"],["77378.20","0"],["77378.30","0"],["77378.40","0"]],"u":101055896,"seq":800573322852},"cts":1787954792847}
{"topic":"orderbook.50.BTCUSDT","type":"delta","ts":1787954792868,"data":{"s":"BTCUSDT","b":[["77367.90","0"],["77367.80","0"],["77367.70","0"],["77366.40","0"],["77366.20","0"],["77366.10","0"],["77365.90","0.027"],["77365.50","0.001"],["77365.10","0.001"],["77364.70","0.949"],["77364.10","0"],["77364.00","0"],["77363.50","0"],["77362.20","0"],["77360.70","0.003"],["77360.20","0.370"],["77360.10","0.002"],["77360.00","0.015"],["77359.90","1.233"],["77359.50","1.037"],["77358.50","0"],["77357.60","2.308"],["77357.50","0.072"],["77357.40","0.002"],["77357.30","0.001"],["77357.20","0.002"],["77357.10","0.064"],["77357.00","0.001"],["77356.90","0.001"]],"a":[["77366.00","9.633"],["77366.20","0.010"],["77366.30","0.487"],["77366.40","1.871"],["77366.50","6.942"],["77367.90","0.806"],["77368.00","13.463"],["77368.10","0.004"],["77368.80","0.001"],["77369.50","0.003"],["77370.90","0"],["77371.20","4.184"],["77372.00","0"],["77372.90","0.002"],["77374.40","0"],["77374.50","4.414"],["77375.80","0.322"],["77376.50","0.258"],["77377.00","0.002"],["77377.10","0"],["77377.20","0"],["77377.50","0"],["77377.60","0"],["77377.70","0"],["77377.80","0"]],"u":101055897,"seq":800573325233},"cts":1787954792866}
{"topic":"orderbook.50.BTCUSDT","type":"delta","ts":1787954792888,"data":{"s":"BTCUSDT","b":[["77365.90","0.035"],["77365.80","0.001"],["77365.10","0"],["77364.60","1.882"],["77364.30","0.004"],["77364.10","0.002"],["77362.30","0"],["77362.00","0.050"],["77359.50","0"],["77358.10","0.387"],["77357.20","0"],["77357.10","0"],["77356.80","0.003"],["77356.60","0.001"]],"a":[["77366.00","10.186"],["77366.10","0.001"],["77366.20","0.016"],["77366.30","0.003"],["77366.40","0.072"],["77366.50","3.420"],["77367.90","0.444"],["77368.00","13.462"],["77369.90","0.050"],["77373.70","0.003"],["77376.50","0.301"],["77377.00","0"]],"u":101055898,"seq":800573327176},"cts":1787954792887}
{"topic":"orderbook.50.BTCUSDT","type":"delta","ts":1787954792908,"data":{"s":"BTCUSDT","b":[["77365.90","0.161"],["77365.10","0.001"],["77364.30","0.003"],["77362.70","0.001"],["77362.30","0.001"],["77361.00","0.193"],["77360.30","0.008"],["77360.20","0"],["77359.80","0.014"],["77359.60","0.003"],["77359.20","0.001"],["77359.00","0.202"],["77358.10","0.388"],["77357.70","1.661"],["77357.60","1.938"],["77357.00","0"],["77356.90","0"],["77356.80","0"],["77356.60","0"]],"a":[["77366.00","6.364"],["77366.20","0.010"],["77366.40","0.448"],["77366.50","0.508"],["77367.90","3.879"],["77368.00","13.463"],["77368.40","0.001"],["77371.10","0.129"],["77372.00","0.002"],["77372.90","0"],["77373.70","0.005"],["77376.50","0"],["77376.60","0"]],"u":101055899,"seq":800573329271},"cts":1787954792907}
{"topic":"orderbook.50.BTCUSDT","type":"delta","ts":1787954792928,"data":{"s":"BTCUSDT","b":[["77365.90","0.067"],["77365.10","0"],["77362.30","0.002"],["77361.00","0.191"],["77360.90","0.003"],["77360.30","0.002"],["77360.00","2.327"],["77359.10","1.039"],["77359.00","0.200"],["77358.60","0.071"],["77358.20","1.294"],["77358.10","0.389"],["77357.70","0.367"]],"a":[["77366.00","5.876"],["77366.30","0.005"],["77366.40","0.443"],["77366.50","0.506"],["77367.00","0.002"],["77367.80","0.006"],["77367.90","0.444"],["77368.40","0.002"],["77371.20","4.186"],["77372.00","0"],["77374.80","0.001"],["77374.90","0.258"],["77375.30","0.191"],["77375.80","0"],["77375.90","0"],["77376.00","0"],["77376.20","0"]],"u":101055900,"seq":800573331245},"cts":1787954792927}
{"topic":"orderbook.50.BTCUSDT","type":"delta","ts":1787954792948,"data":{"s":"BTCUSDT","b":[["77365.90","0.092"],["77360.90","0.001"],["77360.60","0.004"],["77360.30","0"],["77360.10","2.506"],["77359.90","0"],["77358.20","0.002"],["77358.10","0.391"],["77357.70","0"],["77357.00","0.001"],["77356.90","0.001"],["77356.80","0.001"]],"a":[["77366.60","0.002"],["77368.10","0.002"],["77371.00","0.002"],["77371.20","4.184"],["77371.40","0.003"],["77374.70","0"],["77374.80","0"],["77375.50","0"]],"u":101055901,"seq":800573332464},"cts":1787954792943}
{"topic":"orderbook.50.BTCUSDT","type":"delta","ts":1787954792968,"data":{"s":"BTCUSDT","b":[["77360.60","0.002"],["77360.20","0.002"],["77356.80","0"]],"a":[["77366.60","0"],["77368.00","13.465"],["77375.50","0.386"]],"u":101055902,"seq":800573334007},"cts":1787954792967}
{"topic":"orderbook.50.BTCUSDT","type":"delta","ts":1787954792988,"data":{"s":"BTCUSDT","b":[["77365.90","0.093"],["77360.20","0"],["77356.80","0.001"]],"a":[],"u":101055903,"seq":800573335174},"cts":1787954792985}
{"topic":"orderbook.50.BTCUSDT","type":"delta","ts":1787954793008,"data":{"s":"BTCUSDT","b":[["77360.20","0.006"],["77360.10","2.508"],["77360.00","2.321"],["77356.80","0"]],"a":[["77366.40","0.073"],["77371.00","0"],["77371.20","4.186"],["77374.90","0"],["77375.10","0.258"],["77375.80","0.322"]],"u":101055904,"seq":800573336411},"cts":1787954793006}
{"topic":"orderbook.50.BTCUSDT","type":"delta","ts":1787954793028,"data":{"s":"BTCUSDT","b":[["77365.10","0.002"],["77360.60","0.004"],["77358.10","0.389"],["77356.90","0"]],"a":[["77368.10","0"],["77374.70","0.001"],["77375.00","0.015"],["77375.40","0.001"],["77375.80","0"]],"u":101055905,"seq":800573337445},"cts":1787954793024}
{"topic":"orderbook.50.BTCUSDT","type":"delta","ts":1787954793048,"data":{"s":"BTCUSDT","b":[["77365.90","0.104"],["77362.60","0.265"],["77362.50","0.003"],["77361.70","0.370"],["77361.10","0.108"],["77359.10","1.037"],["77358.60","0.069"],["77357.00","0"]],"a":[["77371.20","4.184"],["77371.30","14.003"]],"u":101055906,"seq":800573338881},"cts":1787954793047}
{"topic":"orderbook.50.BTCUSDT","type":"delta","ts":1787954793068,"data":{"s":"BTCUSDT","b":[["77364.70","1.192"],["77363.40","0.003"],["77360.10","1.877"],["77359.60","0.001"]],"a":[["77366.30","0.003"],["77367.00","0"],["77367.20","0.002"]],"u":101055907,"seq":800573340019},"cts":1787954793067}
{"topic":"orderbook.50.BTCUSDT","type":"delta","ts":1787954793088,"data":{"s":"BTCUSDT","b":[["77363.40","0.001"]],"a":[["77366.20","0.012"],["77371.30","14.001"],["77371.40","0.005"],["77375.00","0.014"],["77375.40","0"],["77375.60","0.001"]],"u":101055908,"seq":800573341085},"cts":1787954793086}
{"topic":"orderbook.50.BTCUSDT","type":"delta","ts":1787954793108,"data":{"s":"BTCUSDT","b":[["77365.90","0.135"],["77363.30","0.003"],["77362.80","0.006"],["77362.50","0.001"],["77362.10","0.002"],["77360.60","0.279"],["77360.10","1.875"],["77357.30","0"]],"a":[["77366.00","5.919"],["77366.20","0.010"],["77375.10","0"],["77375.50","0.644"],["77375.80","0.322"]],"u":101055909,"seq":800573342271},"cts":1787954793107}
{"topic":"orderbook.50.BTCUSDT","type":"delta","ts":1787954793128,"data":{"s":"BTCUSDT","b":[["77363.30","0.001"],["77362.80","0.004"],["77362.10","0"],["77362.00","0.052"],["77361.40","0.002"],["77361.10","0.106"],["77360.90","0.003"],["77360.60","0.277"],["77360.20","0.008"],["77359.70","0.002"],["77357.40","0"]],"a":[["77366.00","5.921"],["77368.00","13.393"],["77371.40","0.003"],["77371.50","0.007"]],"u":101055910,"seq":800573343167},"cts":1787954793123}
{"topic":"orderbook.50.BTCUSDT","type":"delta","ts":1787954793148,"data":{"s":"BTCUSDT","b":[["77365.90","0.136"],["77362.60","0.267"],["77359.70","0"],["77357.40","0.002"]],"a":[["77366.00","5.919"],["77366.50","0.508"],["77368.00","13.382"]],"u":101055911,"seq":800573344258},"cts":1787954793145}
{"topic":"orderbook.50.BTCUSDT","type":"delta","ts":1787954793168,"data":{"s":"BTCUSDT","b":[["77363.40","0.003"],["77360.20","0.006"]],"a":[["77366.00","5.857"],["77366.50","0.506"],["77375.10","0.001"],["77375.80","0"]],"u":101055912,"seq":800573344767},"cts":1787954793166}
{"topic":"orderbook.50.BTCUSDT","type":"delta","ts":1787954793188,"data":{"s":"BTCUSDT","b":[["77363.40","0.001"],["77363.30","0.003"]],"a":[["77371.50","0.005"],["77371.70","0.002"],["77375.60","0"]],"u":101055913,"seq":800573344908},"cts":1787954793186}
{"topic":"orderbook.50.BTCUSDT","type":"delta","ts":1787954793208,"data":{"s":"BTCUSDT","b":[["77365.90","0.135"],["77362.60","0.003"]],"a":[["77366.40","0.001"],["77368.00","13.380"],["77368.10","0.002"],["77375.50","0"]],"u":101055914,"seq":800573345067},"cts":1787954793205}
{"topic":"orderbook.50.BTCUSDT","type":"delta","ts":1787954793228,"data":{"s":"BTCUSDT","b":[["77364.50","0.006"]],"a":[],"u":101055915,"seq":800573345197},"cts":1787954793219}
{"topic":"orderbook.50.BTCUSDT","type":"delta","ts":1787954793248,"data":{"s":"BTCUSDT","b":[],"a":[["77371.40","0"],["77373.70","0.007"],["77375.50","0.386"]],"u":101055916,"seq":800573345377},"cts":1787954793246}
{"topic":"orderbook.50.BTCUSDT","type":"delta","ts":1787954793268,"data":{"s":"BTCUSDT","b":[["77365.90","0.133"],["77364.20","0.007"],["77363.30","0.001"],["77362.60","0.001"],["77360.40","0.002"],["77357.40","0"]],"a":[["77366.00","5.814"],["77367.20","0"],["77368.00","13.378"],["77368.40","0.004"],["77369.40","0.002"],["77371.70","0.045"],["77373.70","0.013"]],"u":101055917,"seq":800573345582},"cts":1787954793266}
{"topic":"orderbook.50.BTCUSDT","type":"delta","ts":1787954793288,"data":{"s":"BTCUSDT","b":[["77365.90","0.138"],["77360.40","0"],["77357.40","0.002"]],"a":[["77371.60","0.003"],["77371.70","0.043"],["77373.70","0.011"],["77374.60","14.002"]],"u":101055918,"seq":800573345794},"cts":1787954793286}
{"topic":"orderbook.50.BTCUSDT","type":"delta","ts":1787954793308,"data":{"s":"BTCUSDT","b":[["77365.90","0.159"],["77364.80","0.002"],["77357.40","0"]],"a":[],"u":101055919,"seq":800573345995},"cts":1787954793307}
{"topic":"orderbook.50.BTCUSDT","type":"delta","ts":1787954793328,"data":{"s":"BTCUSDT","b":[["77365.90","0.138"],["77364.80","0"],["77358.30","0.007"],["77357.40","0.002"]],"a":[["77374.60","14.003"]],"u":101055920,"seq":800573346321},"cts":1787954793326}
{"topic":"orderbook.50.BTCUSDT","type":"delta","ts":1787954793348,"data":{"s":"BTCUSDT","b":[],"a":[["77371.60","0.001"],["77371.70","0.045"]],"u":101055921,"seq":800573346458},"cts":1787954793347}
{"topic":"orderbook.50.BTCUSDT","type":"delta","ts":1787954793368,"data":{"s":"BTCUSDT","b":[["77365.90","0.137"]],"a":[],"u":101055922,"seq":800573346520},"cts":1787954793366}
{"topic":"orderbook.50.BTCUSDT","type":"delta","ts":1787954793388,"data":{"s":"BTCUSDT","b":[],"a":[["77367.80","0.371"]],"u":101055923,"seq":800573346573},"cts":1787954793386}
{"topic":"orderbook.50.BTCUSDT","type":"delta","ts":1787954793408,"data":{"s":"BTCUSDT","b":[["77365.90","0.209"],["77364.80","0.002"],["77357.40","0"]],"a":[["77368.40","0.002"],["77370.40","0.002"],["77375.50","0"]],"u":101055924,"seq":800573346708},"cts":1787954793403}
{"topic":"orderbook.50.BTCUSDT","type":"delta","ts":1787954793448,"data":{"s":"BTCUSDT","b":[["77358.30","0.006"]],"a":[],"u":101055925,"seq":800573346849},"cts":1787954793440}
{"topic":"orderbook.50.BTCUSDT","type":"delta","ts":1787954793468,"data":{"s":"BTCUSDT","b":[],"a":[["77371.40","0.003"],["77374.60","14.000"],["77375.30","0"]],"u":101055926,"seq":800573346875},"cts":1787954793462}
{"topic":"orderbook.50.BTCUSDT","type":"delta","ts":1787954793488,"data":{"s":"BTCUSDT","b":[["77364.80","1.938"]],"a":[],"u":101055927,"seq":800573346914},"cts":1787954793479}
{"topic":"orderbook.50.BTCUSDT","type":"delta","ts":1787954793508,"data":{"s":"BTCUSDT","b":[["77365.90","0.195"],["77365.80","0.003"],["77364.90","1.578"],["77364.70","0.383"],["77360.90","0.001"],["77360.00","1.951"],["77357.50","0"]],"a":[["77368.90","0.058"],["77369.40","0"],["77370.90","0.002"],["77371.40","0.005"]],"u":101055928,"seq":800573346994},"cts":1787954793507}
{"topic":"orderbook.50.BTCUSDT","type":"delta","ts":1787954793549,"data":{"s":"BTCUSDT","b":[["77361.70","0"],["77357.50","0.072"]],"a":[],"u":101055929,"seq":800573347177},"cts":1787954793545}
{"topic":"orderbook.50.BTCUSDT","type":"delta","ts":1787954793568,"data":{"s":"BTCUSDT","b":[["77365.80","0.001"],["77365.40","0.002"],["77363.80","0.001"],["77357.60","0"],["77357.50","0"]],"a":[["77368.00","13.384"]],"u":101055930,"seq":800573347258},"cts":1787954793563}
{"topic":"orderbook.50.BTCUSDT","type":"delta","ts":1787954793588,"data":{"s":"BTCUSDT","b":[["77360.20","0"],["77357.60","1.938"]],"a":[["77369.30","0.004"]],"u":101055931,"seq":800573347387},"cts":1787954793585}
{"topic":"orderbook.50.BTCUSDT","type":"delta","ts":1787954793608,"data":{"s":"BTCUSDT","b":[["77360.20","0.006"],["77357.60","0"]],"a":[],"u":101055932,"seq":800573347429},"cts":1787954793605}
{"topic":"orderbook.50.BTCUSDT","type":"delta","ts":1787954793628,"data":{"s":"BTCUSDT","b":[["77365.40","0"],["77365.30","0.002"],["77360.20","0"],["77357.60","1.938"]],"a":[],"u":101055933,"seq":800573347470},"cts":1787954793615}
{"topic":"orderbook.50.BTCUSDT","type":"delta","ts":1787954793649,"data":{"s":"BTCUSDT","b":[["77365.90","0.194"],["77365.80","0.003"],["77361.40","0"],["77360.60","0.286"],["77360.20","0.006"],["77358.00","0.005"],["77357.60","0"]],"a":[["77369.30","0.002"],["77369.90","0.048"],["77371.90","0.002"],["77375.20","0"]],"u":101055934,"seq":800573347682},"cts":1787954793640}
{"topic":"orderbook.50.BTCUSDT","type":"delta","ts":1787954793669,"data":{"s":"BTCUSDT","b":[["77360.20","0"],["77357.60","1.938"]],"a":[],"u":101055935,"seq":800573347735},"cts":1787954793659}
{"topic":"orderbook.50.BTCUSDT","type":"delta","ts":1787954793688,"data":{"s":"BTCUSDT","b":[["77360.20","0.006"],["77357.60","0"]],"a":[],"u":101055936,"seq":800573347774},"cts":1787954793687}
{"topic":"orderbook.50.BTCUSDT","type":"delta","ts":1787954793708,"data":{"s":"BTCUSDT","b":[["77360.20","0"],["77357.60","1.938"]],"a":[],"u":101055937,"seq":800573347809},"cts":1787954793706}
{"topic":"orderbook.50.BTCUSDT","type":"delta","ts":1787954793729,"data":{"s":"BTCUSDT","b":[["77365.90","0.219"],["77360.20","0.006"],["77357.60","0"]],"a":[],"u":101055938,"seq":800573347847},"cts":1787954793726}
{"topic":"orderbook.50.BTCUSDT","type":"delta","ts":1787954793748,"data":{"s":"BTCUSDT","b":[],"a":[["77369.90","0.050"]],"u":101055939,"seq":800573347992},"cts":1787954793744}
{"topic":"orderbook.50.BTCUSDT","type":"delta","ts":1787954793809,"data":{"s":"BTCUSDT","b":[["77365.90","0.515"],["77365.50","0"],["77357.60","1.938"]],"a":[["77369.90","0.048"],["77370.40","0"],["77370.90","0"],["77371.70","0.043"],["77371.80","0.003"],["77372.30","0.004"],["77372.80","0.002"],["77375.20","0.002"]],"u":101055940,"seq":800573348296},"cts":1787954793806}
{"topic":"orderbook.50.BTCUSDT","type":"delta","ts":1787954793829,"data":{"s":"BTCUSDT","b":[["77364.10","0.003"],["77361.80","0.003"]],"a":[["77371.40","0.003"],["77371.90","0"],["77373.30","0.002"],["77373.80","0.003"]],"u":101055941,"seq":800573348378},"cts":1787954793827}
{"topic":"orderbook.50.BTCUSDT","type":"delta","ts":1787954793848,"data":{"s":"BTCUSDT","b":[["77365.90","0.923"],["77361.80","0.002"],["77360.20","0.330"]],"a":[["77366.50","0.466"],["77367.80","0.006"],["77371.30","14.003"],["77371.80","0.001"],["77372.00","0.002"],["77372.30","0.002"],["77374.30","0.002"],["77375.10","0"],["77375.20","0"]],"u":101055942,"seq":800573348551},"cts":1787954793843}
{"topic":"orderbook.50.BTCUSDT","type":"delta","ts":1787954793868,"data":{"s":"BTCUSDT","b":[["77365.90","0.519"],["77365.80","0.001"],["77360.30","0.006"],["77357.60","0"]],"a":[["77369.30","0.004"],["77370.10","0.002"],["77373.80","0.001"],["77374.30","0"]],"u":101055943,"seq":800573348700},"cts":1787954793867}
{"topic":"orderbook.50.BTCUSDT","type":"delta","ts":1787954793888,"data":{"s":"BTCUSDT","b":[["77360.30","0"],["77357.60","1.938"]],"a":[["77371.70","0.045"],["77372.00","0"],["77375.10","0.001"]],"u":101055944,"seq":800573348753},"cts":1787954793886}
{"topic":"orderbook.50.BTCUSDT","type":"delta","ts":1787954793908,"data":{"s":"BTCUSDT","b":[["77360.30","0.006"],["77357.60","0"]],"a":[],"u":101055945,"seq":800573348781},"cts":1787954793907}
{"topic":"orderbook.50.BTCUSDT","type":"delta","ts":1787954793929,"data":{"s":"BTCUSDT","b":[["77365.90","0.480"],["77365.30","0"],["77365.20","0.002"],["77364.80","1.936"],["77363.80","0.003"],["77360.30","0"],["77358.90","0.002"],["77357.60","1.938"]],"a":[["77371.40","0"],["77373.30","0"],["77374.60","14.003"],["77375.20","0.002"],["77375.30","0.191"]],"u":101055946,"seq":800573348897},"cts":1787954793925}
{"topic":"orderbook.50.BTCUSDT","type":"delta","ts":1787954793948,"data":{"s":"BTCUSDT","b":[["77360.30","0.006"],["77358.90","0.001"],["77358.00","0.006"],["77357.60","0"]],"a":[],"u":101055947,"seq":800573349000},"cts":1787954793940}
{"topic":"orderbook.50.BTCUSDT","type":"delta","ts":1787954793968,"data":{"s":"BTCUSDT","b":[["77360.30","0"],["77357.60","1.938"]],"a":[],"u":101055948,"seq":800573349086},"cts":1787954793962}
{"topic":"orderbook.50.BTCUSDT","type":"delta","ts":1787954793989,"data":{"s":"BTCUSDT","b":[["77360.30","0.006"],["77357.60","0"]],"a":[],"u":101055949,"seq":800573349118},"cts":1787954793987}
{"topic":"orderbook.50.BTCUSDT","type":"delta","ts":1787954794009,"data":{"s":"BTCUSDT","b":[["77360.30","0"],["77357.70","0.775"]],"a":[],"u":101055950,"seq":800573349162},"cts":1787954794006}
{"topic":"orderbook.50.BTCUSDT","type":"delta","ts":1787954794048,"data":{"s":"BTCUSDT","b":[["77360.30","0.006"],["77357.70","0"]],"a":[],"u":101055951,"seq":800573349232},"cts":1787954794043}
{"topic":"orderbook.50.BTCUSDT","type":"delta","ts":1787954794108,"data":{"s":"BTCUSDT","b":[["77365.90","0.939"],["77365.80","0.003"]],"a":[["77369.30","0.002"],["77370.60","0.006"],["77371.70","0.043"],["77372.00","0.002"],["77375.30","0"]],"u":101055952,"seq":800573349409},"cts":1787954794105}
{"topic":"orderbook.50.BTCUSDT","type":"delta","ts":1787954794149,"data":{"s":"BTCUSDT","b":[["77360.30","0"],["77357.70","0.775"]],"a":[],"u":101055953,"seq":800573349440},"cts":1787954794140}
{"topic":"orderbook.50.BTCUSDT","type":"delta","ts":1787954794168,"data":{"s":"BTCUSDT","b":[["77360.30","0.006"],["77357.70","0"]],"a":[],"u":101055954,"seq":800573349469},"cts":1787954794159}
{"topic":"orderbook.50.BTCUSDT","type":"delta","ts":1787954794189,"data":{"s":"BTCUSDT","b":[["77360.30","0"],["77358.90","0.002"],["77358.00","0.005"],["77357.70","0.775"]],"a":[],"u":101055955,"seq":800573349483},"cts":1787954794184}
{"topic":"orderbook.50.BTCUSDT","type":"delta","ts":1787954794208,"data":{"s":"BTCUSDT","b":[["77360.30","0.006"],["77357.70","0"]],"a":[],"u":101055956,"seq":800573349503},"cts":1787954794207}
{"topic":"orderbook.50.BTCUSDT","type":"delta","ts":1787954794228,"data":{"s":"BTCUSDT","b":[["77360.30","0"],["77357.70","0.775"]],"a":[],"u":101055957,"seq":800573349531},"cts":1787954794221}
{"topic":"orderbook.50.BTCUSDT","type":"delta","ts":1787954794249,"data":{"s":"BTCUSDT","b":[["77360.30","0.006"],["77357.70","0"]],"a":[],"u":101055958,"seq":800573349550},"cts":1787954794246}
{"topic":"orderbook.50.BTCUSDT","type":"delta","ts":1787954794269,"data":{"s":"BTCUSDT","b":[["77360.30","0"],["77357.70","0.775"]],"a":[],"u":101055959,"seq":800573349565},"cts":1787954794266}
{"topic":"orderbook.50.BTCUSDT","type":"delta","ts":1787954794289,"data":{"s":"BTCUSDT","b":[["77360.30","0.006"],["77357.70","0"]],"a":[],"u":101055960,"seq":800573349580},"cts":1787954794286}
{"topic":"orderbook.50.BTCUSDT","type":"delta","ts":1787954794308,"data":{"s":"BTCUSDT","b":[["77360.30","0"],["77357.70","0.775"]],"a":[["77371.70","0.045"],["77372.00","0"],["77375.30","0.191"]],"u":101055961,"seq":800573349601},"cts":1787954794304}
{"topic":"orderbook.50.BTCUSDT","type":"delta","ts":1787954794328,"data":{"s":"BTCUSDT","b":[["77360.30","0.006"],["77357.70","0"]],"a":[],"u":101055962,"seq":800573349619},"cts":1787954794325}
{"topic":"orderbook.50.BTCUSDT","type":"delta","ts":1787954794428,"data":{"s":"BTCUSDT","b":[["77365.90","0.180"],["77365.80","0.001"],["77365.20","0"],["77364.80","0"],["77364.70","0"],["77364.20","0.005"],["77363.80","0.001"],["77362.00","0.050"],["77360.60","0.011"],["77360.20","0"],["77360.00","0.015"],["77359.20","0.003"],["77359.10","0"],["77358.30","0.008"],["77357.80","0.002"],["77357.60","0.002"],["77357.50","0.072"],["77357.40","0.002"],["77357.30","0.003"]],"a":[["77366.00","5.816"],["77367.80","0.376"],["77367.90","3.754"],["77369.40","0.002"],["77371.40","0.002"],["77371.70","0.043"],["77372.80","0"],["77374.10","0.306"],["77375.30","0"]],"u":101055963,"seq":800573350177},"cts":1787954794427}
{"topic":"orderbook.50.BTCUSDT","type":"delta","ts":1787954794448,"data":{"s":"BTCUSDT","b":[["77365.90","0.150"],["77364.90","0.693"],["77361.60","0"],["77361.20","0.383"],["77360.30","0"],["77360.20","3.343"],["77360.10","0.369"],["77359.20","0.001"],["77358.30","0.006"],["77357.80","0"],["77357.50","0.442"],["77357.30","0.001"],["77357.00","0.001"]],"a":[["77366.00","5.888"],["77371.00","0.002"],["77371.40","0"],["77374.10","0.051"]],"u":101055964,"seq":800573351354},"cts":1787954794447}
{"topic":"orderbook.50.BTCUSDT","type":"delta","ts":1787954794468,"data":{"s":"BTCUSDT","b":[["77360.30","1.407"],["77360.10","0.002"],["77357.40","0.004"],["77357.00","0"]],"a":[],"u":101055965,"seq":800573352349},"cts":1787954794467}
{"topic":"orderbook.50.BTCUSDT","type":"delta","ts":1787954794488,"data":{"s":"BTCUSDT","b":[],"a":[["77371.00","0"],["77371.20","4.186"],["77375.30","0.191"]],"u":101055966,"seq":800573353076},"cts":1787954794482}
{"topic":"orderbook.50.BTCUSDT","type":"delta","ts":1787954794508,"data":{"s":"BTCUSDT","b":[["77364.70","1.936"],["77358.90","0.001"],["77357.60","0.777"],["77357.30","0"]],"a":[["77371.40","0.003"],["77374.60","14.000"],["77374.70","0.002"],["77375.30","0"]],"u":101055967,"seq":800573354213},"cts":1787954794506}
{"topic":"orderbook.50.BTCUSDT","type":"delta","ts":1787954794528,"data":{"s":"BTCUSDT","b":[["77364.90","1.296"],["77358.10","0.391"],["77357.50","0.072"]],"a":[["77371.10","0.131"],["77371.20","4.184"]],"u":101055968,"seq":800573355102},"cts":1787954794523}
{"topic":"orderbook.50.BTCUSDT","type":"delta","ts":1787954794548,"data":{"s":"BTCUSDT","b":[["77365.90","0.151"],["77364.60","1.881"]],"a":[["77371.10","0.129"],["77371.20","4.186"],["77374.60","14.001"],["77374.70","0.001"]],"u":101055969,"seq":800573356208},"cts":1787954794547}
{"topic":"orderbook.50.BTCUSDT","type":"delta","ts":1787954794568,"data":{"s":"BTCUSDT","b":[["77365.90","0.394"],["77359.70","0.002"],["77358.80","0.003"],["77357.40","0"]],"a":[],"u":101055970,"seq":800573357176},"cts":1787954794566}
{"topic":"orderbook.50.BTCUSDT","type":"delta","ts":1787954794588,"data":{"s":"BTCUSDT","b":[],"a":[["77371.20","4.184"],["77371.30","14.005"]],"u":101055971,"seq":800573357306},"cts":1787954794584}
{"topic":"orderbook.50.BTCUSDT","type":"delta","ts":1787954794629,"data":{"s":"BTCUSDT","b":[],"a":[["77375.10","0"],["77375.30","0.191"]],"u":101055972,"seq":800573357408},"cts":1787954794624}
{"topic":"orderbook.50.BTCUSDT","type":"delta","ts":1787954794648,"data":{"s":"BTCUSDT","b":[["77365.90","0.797"],["77360.60","0.002"],["77360.50","0.010"],["77357.50","0"]],"a":[["77367.80","0.006"],["77371.30","14.003"],["77371.40","0.005"]],"u":101055973,"seq":800573357523},"cts":1787954794642}
{"topic":"orderbook.50.BTCUSDT","type":"delta","ts":1787954794668,"data":{"s":"BTCUSDT","b":[["77365.90","0.373"],["77358.90","0.147"]],"a":[["77371.30","14.005"],["77371.40","0.003"]],"u":101055974,"seq":800573357640},"cts":1787954794665}
{"topic":"orderbook.50.BTCUSDT","type":"delta","ts":1787954794688,"data":{"s":"BTCUSDT","b":[["77365.90","0.151"],["77359.70","0"],["77357.50","0.072"]],"a":[],"u":101055975,"seq":800573357806},"cts":1787954794685}
{"topic":"orderbook.50.BTCUSDT","type":"delta","ts":1787954794708,"data":{"s":"BTCUSDT","b":[],"a":[["77371.20","4.186"],["77371.30","14.003"],["77375.10","0.001"],["77375.30","0"]],"u":101055976,"seq":800573358811},"cts":1787954794706}
{"topic":"orderbook.50.BTCUSDT","type":"delta","ts":1787954794728,"data":{"s":"BTCUSDT","b":[["77357.50","0.073"]],"a":[],"u":101055977,"seq":800573359508},"cts":1787954794721}
{"topic":"orderbook.50.BTCUSDT","type":"delta","ts":1787954794748,"data":{"s":"BTCUSDT","b":[["77357.50","0.072"]],"a":[],"u":101055978,"seq":800573360633},"cts":1787954794745}
{"topic":"orderbook.50.BTCUSDT","type":"delta","ts":1787954794768,"data":{"s":"BTCUSDT","b":[["77358.80","0.001"],["77358.10","0.389"]],"a":[["77366.00","5.956"],["77371.70","0"],["77375.30","0.191"]],"u":101055979,"seq":800573361165},"cts":1787954794756}
{"topic":"orderbook.50.BTCUSDT","type":"delta","ts":1787954794788,"data":{"s":"BTCUSDT","b":[],"a":[["77366.00","6.006"]],"u":101055980,"seq":800573362641},"cts":1787954794787}
{"topic":"orderbook.50.BTCUSDT","type":"delta","ts":1787954794808,"data":{"s":"BTCUSDT","b":[],"a":[["77371.20","4.184"],["77371.30","14.005"]],"u":101055981,"seq":800573363508},"cts":1787954794805}
{"topic":"orderbook.50.BTCUSDT","type":"delta","ts":1787954794908,"data":{"s":"BTCUSDT","b":[["77358.00","0.007"]],"a":[],"u":101055982,"seq":800573366334},"cts":1787954794907}
{"topic":"orderbook.50.BTCUSDT","type":"delta","ts":1787954794928,"data":{"s":"BTCUSDT","b":[],"a":[["77371.20","4.186"],["77371.30","14.003"]],"u":101055983,"seq":800573366456},"cts":1787954794927}
{"topic":"orderbook.50.BTCUSDT","type":"delta","ts":1787954795088,"data":{"s":"BTCUSDT","b":[],"a":[["77371.20","4.184"],["77371.30","14.005"]],"u":101055984,"seq":800573367179},"cts":1787954795078}
{"topic":"orderbook.50.BTCUSDT","type":"delta","ts":1787954795108,"data":{"s":"BTCUSDT","b":[["77358.00","0.005"]],"a":[],"u":101055985,"seq":800573367293},"cts":1787954795104}
{"topic":"orderbook.50.BTCUSDT","type":"delta","ts":1787954795269,"data":{"s":"BTCUSDT","b":[["77365.90","1.226"],["77365.80","0.003"],["77365.00","0.372"],["77360.60","0.004"],["77358.50","0.253"],["77357.60","0"],["77357.50","0"]],"a":[["77366.00","3.062"],["77367.80","0.376"],["77368.00","13.344"],["77369.40","0"],["77370.10","0"],["77370.60","0.004"],["77371.30","14.003"],["77371.70","0.002"],["77371.80","0.003"],["77372.30","0.033"],["77372.80","0.002"],["77375.30","0"],["77375.50","0.386"]],"u":101055986,"seq":800573368016},"cts":1787954795266}
{"topic":"orderbook.50.BTCUSDT","type":"delta","ts":1787954795288,"data":{"s":"BTCUSDT","b":[],"a":[["77370.60","0.006"]],"u":101055987,"seq":800573368039},"cts":1787954795286}
{"topic":"orderbook.50.BTCUSDT","type":"delta","ts":1787954795308,"data":{"s":"BTCUSDT","b":[["77358.50","0.639"]],"a":[],"u":101055988,"seq":800573368056},"cts":1787954795304}
{"topic":"orderbook.50.BTCUSDT","type":"delta","ts":1787954795328,"data":{"s":"BTCUSDT","b":[["77365.90","2.521"],["77358.00","0.006"]],"a":[["77366.00","1.136"],["77367.80","0.006"],["77370.60","0.004"],["77371.30","14.001"],["77371.80","0.001"],["77372.30","0.031"],["77372.80","0"],["77374.60","14.000"],["77375.60","0.001"]],"u":101055989,"seq":800573368139},"cts":1787954795327}
{"topic":"orderbook.50.BTCUSDT","type":"delta","ts":1787954795348,"data":{"s":"BTCUSDT","b":[["77365.90","2.948"],["77365.10","0.008"],["77361.70","0.370"],["77360.40","1.292"],["77358.50","0.640"],["77358.00","0"],["77357.90","0"]],"a":[["77366.00","0.665"],["77366.50","0.223"],["77367.90","0"],["77371.10","0"],["77371.20","0.002"],["77371.70","0"],["77373.70","0.007"],["77373.90","0.002"],["77374.40","0.129"],["77375.50","0"],["77375.80","0.322"],["77375.90","0.002"]],"u":101055990,"seq":800573368478},"cts":1787954795345}
{"topic":"orderbook.50.BTCUSDT","type":"delta","ts":1787954795368,"data":{"s":"BTCUSDT","b":[["77365.90","2.977"],["77365.80","0.004"],["77362.70","0"],["77359.80","0"],["77358.00","0.005"],["77357.90","0.001"]],"a":[],"u":101055991,"seq":800573368670},"cts":1787954795364}
{"topic":"orderbook.50.BTCUSDT","type":"delta","ts":1787954795388,"data":{"s":"BTCUSDT","b":[["77365.90","3.049"]],"a":[["77366.00","0.886"],["77373.60","0.003"],["77373.90","0"],["77376.00","0.002"]],"u":101055992,"seq":800573368809},"cts":1787954795385}
{"topic":"orderbook.50.BTCUSDT","type":"delta","ts":1787954795408,"data":{"s":"BTCUSDT","b":[["77365.10","0.002"],["77365.00","0.378"],["77360.10","0.003"],["77358.50","0.639"]],"a":[["77367.80","0"],["77367.90","0.006"],["77371.40","0"],["77373.50","0.002"],["77373.60","0.001"],["77374.60","14.003"],["77375.60","0"],["77376.20","0.001"]],"u":101055993,"seq":800573368937},"cts":1787954795407}
{"topic":"orderbook.50.BTCUSDT","type":"delta","ts":1787954795428,"data":{"s":"BTCUSDT","b":[["77365.90","3.178"],["77365.00","0.372"],["77364.80","0.006"],["77358.00","0.135"],["77357.90","0"]],"a":[["77374.60","14.002"],["77374.70","0"],["77376.60","0.003"]],"u":101055994,"seq":800573369037},"cts":1787954795425}
{"topic":"orderbook.50.BTCUSDT","type":"delta","ts":1787954795448,"data":{"s":"BTCUSDT","b":[["77365.90","3.179"],["77364.80","0"],["77364.60","1.880"],["77357.90","0.001"]],"a":[],"u":101055995,"seq":800573369087},"cts":1787954795446}
{"topic":"orderbook.50.BTCUSDT","type":"delta","ts":1787954795468,"data":{"s":"BTCUSDT","b":[["77365.00","0.378"]],"a":[],"u":101055996,"seq":800573369134},"cts":1787954795466}
{"topic":"orderbook.50.BTCUSDT","type":"delta","ts":1787954795488,"data":{"s":"BTCUSDT","b":[["77365.90","3.050"],["77361.60","0.001"],["77357.90","0"]],"a":[["77373.70","0.009"],["77374.70","0.001"],["77376.60","0"]],"u":101055997,"seq":800573369173},"cts":1787954795486}
{"topic":"orderbook.50.BTCUSDT","type":"delta","ts":1787954795508,"data":{"s":"BTCUSDT","b":[["77365.00","0.372"]],"a":[["77374.60","14.000"],["77374.70","0.003"],["77375.10","0"],["77376.60","0.003"]],"u":101055998,"seq":800573369208},"cts":1787954795507}
{"topic":"orderbook.50.BTCUSDT","type":"delta","ts":1787954795528,"data":{"s":"BTCUSDT","b":[["77365.90","3.179"]],"a":[],"u":101055999,"seq":800573369253},"cts":1787954795525}
{"topic":"orderbook.50.BTCUSDT","type":"delta","ts":1787954795548,"data":{"s":"BTCUSDT","b":[["77365.90","3.050"],["77364.80","0.006"],["77358.00","0"]],"a":[],"u":101056000,"seq":800573369307},"cts":1787954795543}
{"topic":"orderbook.50.BTCUSDT","type":"delta","ts":1787954795568,"data":{"s":"BTCUSDT","b":[],"a":[["77375.10","0.001"],["77376.60","0"]],"u":101056001,"seq":800573369354},"cts":1787954795562}
{"topic":"orderbook.50.BTCUSDT","type":"delta","ts":1787954795588,"data":{"s":"BTCUSDT","b":[],"a":[["77374.80","0.001"],["77375.10","0"]],"u":101056002,"seq":800573369379},"cts":1787954795586}
{"topic":"orderbook.50.BTCUSDT","type":"delta","ts":1787954795608,"data":{"s":"BTCUSDT","b":[["77365.90","3.179"],["77364.80","0"],["77358.00","0.135"]],"a":[["77373.70","0.011"]],"u":101056003,"seq":800573369448},"cts":1787954795607}
{"topic":"orderbook.50.BTCUSDT","type":"delta","ts":1787954795648,"data":{"s":"BTCUSDT","b":[["77360.50","0"],["77358.30","0.013"],["77358.00","0.130"],["77357.90","0.001"]],"a":[],"u":101056004,"seq":800573369488},"cts":1787954795643}
{"topic":"orderbook.50.BTCUSDT","type":"delta","ts":1787954795729,"data":{"s":"BTCUSDT","b":[],"a":[["77366.00","1.068"],["77373.00","0.004"],["77373.50","0"],["77374.20","0.004"],["77376.60","0.003"]],"u":101056005,"seq":800573369638},"cts":1787954795725}
{"topic":"orderbook.50.BTCUSDT","type":"delta","ts":1787954795748,"data":{"s":"BTCUSDT","b":[],"a":[["77374.20","0.002"]],"u":101056006,"seq":800573369680},"cts":1787954795747}
{"topic":"orderbook.50.BTCUSDT","type":"delta","ts":1787954795788,"data":{"s":"BTCUSDT","b":[],"a":[["77376.20","0.003"]],"u":101056007,"seq":800573369727},"cts":1787954795784}
{"topic":"orderbook.50.BTCUSDT","type":"delta","ts":1787954795849,"data":{"s":"BTCUSDT","b":[],"a":[["77376.20","0.001"]],"u":101056008,"seq":800573369809},"cts":1787954795843}
{"topic":"orderbook.50.BTCUSDT","type":"delta","ts":1787954795908,"data":{"s":"BTCUSDT","b":[],"a":[["77366.00","1.268"],["77376.20","0.003"]],"u":101056009,"seq":800573369865},"cts":1787954795906}
{"topic":"orderbook.50.BTCUSDT","type":"delta","ts":1787954795928,"data":{"s":"BTCUSDT","b":[],"a":[["77371.20","2.724"],["77372.90","0.002"],["77373.00","0.002"],["77375.50","0.002"],["77376.20","0"],["77376.60","0"]],"u":101056010,"seq":800573369923},"cts":1787954795922}
{"topic":"orderbook.50.BTCUSDT","type":"delta","ts":1787954796048,"data":{"s":"BTCUSDT","b":[["77364.30","0"],["77357.60","0.777"]],"a":[],"u":101056011,"seq":800573370003},"cts":1787954796047}
{"topic":"orderbook.50.BTCUSDT","type":"delta","ts":1787954796068,"data":{"s":"BTCUSDT","b":[["77364.20","0"],["77357.50","0.072"]],"a":[],"u":101056012,"seq":800573370052},"cts":1787954796066}
{"topic":"orderbook.50.BTCUSDT","type":"delta","ts":1787954796088,"data":{"s":"BTCUSDT","b":[["77360.90","0"],["77357.40","0.004"]],"a":[],"u":101056013,"seq":800573370077},"cts":1787954796084}
{"topic":"orderbook.50.BTCUSDT","type":"delta","ts":1787954796109,"data":{"s":"BTCUSDT","b":[["77357.40","0.134"]],"a":[],"u":101056014,"seq":800573370097},"cts":1787954796106}
{"topic":"orderbook.50.BTCUSDT","type":"delta","ts":1787954796169,"data":{"s":"BTCUSDT","b":[["77361.00","0.017"]],"a":[["77375.00","0.016"]],"u":101056015,"seq":800573370153},"cts":1787954796166}
{"topic":"orderbook.50.BTCUSDT","type":"delta","ts":1787954796188,"data":{"s":"BTCUSDT","b":[["77364.40","0.174"],["77357.40","0"]],"a":[["77372.30","0.002"]],"u":101056016,"seq":800573370180},"cts":1787954796186}
{"topic":"orderbook.50.BTCUSDT","type":"delta","ts":1787954796269,"data":{"s":"BTCUSDT","b":[],"a":[["77375.00","0.014"]],"u":101056017,"seq":800573370272},"cts":1787954796266}
{"topic":"orderbook.50.BTCUSDT","type":"delta","ts":1787954796288,"data":{"s":"BTCUSDT","b":[],"a":[["77375.50","0"],["77376.20","0.001"]],"u":101056018,"seq":800573370296},"cts":1787954796287}
{"topic":"orderbook.50.BTCUSDT","type":"delta","ts":1787954796308,"data":{"s":"BTCUSDT","b":[],"a":[["77372.90","0"],["77373.50","0.002"]],"u":101056019,"seq":800573370321},"cts":1787954796305}
{"topic":"orderbook.50.BTCUSDT","type":"delta","ts":1787954796609,"data":{"s":"BTCUSDT","b":[],"a":[["77366.00","1.068"]],"u":101056020,"seq":800573370562},"cts":1787954796607}
{"topic":"orderbook.50.BTCUSDT","type":"delta","ts":1787954796648,"data":{"s":"BTCUSDT","b":[["77358.30","0.006"],["77358.20","0.007"]],"a":[],"u":101056021,"seq":800573370598},"cts":1787954796642}
{"topic":"orderbook.50.BTCUSDT","type":"delta","ts":1787954796688,"data":{"s":"BTCUSDT","b":[["77364.80","0.006"],["77357.50","0"]],"a":[["77366.00","0.847"]],"u":101056022,"seq":800573370713},"cts":1787954796684}
{"topic":"orderbook.50.BTCUSDT","type":"delta","ts":1787954796728,"data":{"s":"BTCUSDT","b":[["77364.80","0"],["77357.50","0.072"]],"a":[],"u":101056023,"seq":800573370879},"cts":1787954796723}
{"topic":"orderbook.50.BTCUSDT","type":"delta","ts":1787954796828,"data":{"s":"BTCUSDT","b":[["77365.90","4.371"],["77364.80","0.006"],["77357.70","0.370"],["77357.60","0"],["77357.50","0"]],"a":[["77366.00","0.407"],["77366.50","0.001"],["77371.20","0.002"],["77373.50","0"],["77373.70","0.013"],["77376.60","0.003"]],"u":101056024,"seq":800573371719},"cts":1787954796827}
{"topic":"orderbook.50.BTCUSDT","type":"delta","ts":1787954796848,"data":{"s":"BTCUSDT","b":[["77365.10","0.008"],["77364.80","0.003"],["77360.70","0"],["77360.30","2.125"],["77357.60","0.777"]],"a":[["77373.70","0.007"],["77374.30","0.002"],["77374.50","0.002"],["77376.60","0"]],"u":101056025,"seq":800573372137},"cts":1787954796844}
{"topic":"orderbook.50.BTCUSDT","type":"delta","ts":1787954796868,"data":{"s":"BTCUSDT","b":[["77365.90","4.373"],["77357.70","0"],["77357.50","0.072"]],"a":[["77366.00","0.248"],["77374.40","0"],["77374.50","0.131"],["77376.60","0.003"]],"u":101056026,"seq":800573372381},"cts":1787954796865}
{"topic":"orderbook.50.BTCUSDT","type":"delta","ts":1787954796888,"data":{"s":"BTCUSDT","b":[["77365.90","4.377"]],"a":[["77366.00","0.099"],["77366.40","0"],["77377.00","0.002"]],"u":101056027,"seq":800573373198},"cts":1787954796882}
{"topic":"orderbook.50.BTCUSDT","type":"delta","ts":1787954796908,"data":{"s":"BTCUSDT","b":[["77365.90","4.407"],["77360.70","0.130"],["77358.00","0"]],"a":[["77366.00","0.256"],["77374.30","0"],["77374.40","0.002"],["77374.50","4.063"]],"u":101056028,"seq":800573374087},"cts":1787954796905}
{"topic":"orderbook.50.BTCUSDT","type":"delta","ts":1787954796928,"data":{"s":"BTCUSDT","b":[["77365.90","4.377"]],"a":[["77374.30","0.002"],["77374.40","0.129"],["77374.50","3.934"],["77374.80","0"],["77377.00","0.001"]],"u":101056029,"seq":800573374234},"cts":1787954796925}
{"topic":"orderbook.50.BTCUSDT","type":"delta","ts":1787954796948,"data":{"s":"BTCUSDT","b":[],"a":[["77366.00","0.099"]],"u":101056030,"seq":800573375054},"cts":1787954796943}
{"topic":"orderbook.50.BTCUSDT","type":"delta","ts":1787954796988,"data":{"s":"BTCUSDT","b":[["77365.90","4.382"]],"a":[],"u":101056031,"seq":800573377377},"cts":1787954796986}
{"topic":"orderbook.50.BTCUSDT","type":"delta","ts":1787954797008,"data":{"s":"BTCUSDT","b":[["77365.90","4.412"]],"a":[["77374.10","0.053"],["77374.30","0"],["77377.10","0.001"]],"u":101056032,"seq":800573378503},"cts":1787954797006}
{"topic":"orderbook.50.BTCUSDT","type":"delta","ts":1787954797068,"data":{"s":"BTCUSDT","b":[],"a":[["77374.80","0.001"],["77377.10","0"]],"u":101056033,"seq":800573381690},"cts":1787954797064}
{"topic":"orderbook.50.BTCUSDT","type":"delta","ts":1787954797088,"data":{"s":"BTCUSDT","b":[],"a":[["77374.00","0.003"],["77374.10","0.051"]],"u":101056034,"seq":800573382705},"cts":1787954797083}
{"topic":"orderbook.50.BTCUSDT","type":"delta","ts":1787954797268,"data":{"s":"BTCUSDT","b":[["77367.90","6.817"],["77367.80","0.002"],["77366.40","1.037"],["77366.20","0.001"],["77366.00","2.654"],["77365.90","0.913"],["77365.80","0.003"],["77365.10","0.002"],["77364.90","0"],["77364.00","0.001"],["77362.00","0.002"],["77360.40","0"],["77360.20","2.973"],["77358.60","0.133"],["77358.10","0"],["77357.90","0"],["77357.60","0"],["77357.50","0"]],"a":[["77366.00","0"],["77366.10","0"],["77366.20","0"],["77366.30","0"],["77366.50","0"],["77367.90","0"],["77368.00","13.345"],["77368.40","0"],["77369.90","0"],["77373.50","0.002"],["77374.00","0.001"],["77377.10","0.001"],["77377.20","0.001"],["77377.50","0.036"],["77377.60","0.259"],["77377.70","0.001"],["77377.80","4.008"],["77377.90","14.001"]],"u":101056035,"seq":800573390298},"cts":1787954797267}
{"topic":"orderbook.50.BTCUSDT","type":"delta","ts":1787954797289,"data":{"s":"BTCUSDT","b":[["77367.90","7.409"],["77367.80","0.003"],["77366.50","0.357"],["77366.10","0.002"],["77366.00","1.579"],["77365.90","0.475"],["77365.80","0.002"],["77365.00","0.002"],["77364.10","0.001"],["77364.00","0.049"],["77361.80","0.304"],["77361.70","0"],["77360.10","0.390"],["77358.20","0"]],"a":[["77368.10","0.004"],["77371.20","0.004"],["77371.90","0.048"],["77373.50","0"],["77373.60","0.003"],["77377.60","0.001"]],"u":101056036,"seq":800573390396},"cts":1787954797286}
{"topic":"orderbook.50.BTCUSDT","type":"delta","ts":1787954797309,"data":{"s":"BTCUSDT","b":[["77367.90","7.406"],["77361.80","0.193"],["77358.50","0.641"]],"a":[["77373.60","0.001"],["77373.70","0.009"]],"u":101056037,"seq":800573390431},"cts":1787954797307}
{"topic":"orderbook.50.BTCUSDT","type":"delta","ts":1787954797328,"data":{"s":"BTCUSDT","b":[["77365.50","0.002"],["77364.80","0.004"],["77358.30","0"]],"a":[],"u":101056038,"seq":800573390460},"cts":1787954797327}
{"topic":"orderbook.50.BTCUSDT","type":"delta","ts":1787954797348,"data":{"s":"BTCUSDT","b":[["77367.90","7.432"],["77365.90","0.470"],["77364.60","1.881"],["77360.10","0.389"]],"a":[["77373.60","0.003"],["77373.70","0.007"]],"u":101056039,"seq":800573390514},"cts":1787954797345}
{"topic":"orderbook.50.BTCUSDT","type":"delta","ts":1787954797368,"data":{"s":"BTCUSDT","b":[],"a":[["77373.60","0.001"],["77373.70","0.009"]],"u":101056040,"seq":800573390540},"cts":1787954797364}
{"topic":"orderbook.50.BTCUSDT","type":"delta","ts":1787954797408,"data":{"s":"BTCUSDT","b":[],"a":[["77373.70","0.007"],["77373.90","0.002"],["77377.90","0"]],"u":101056041,"seq":800573390567},"cts":1787954797407}
{"topic":"orderbook.50.BTCUSDT","type":"delta","ts":1787954797448,"data":{"s":"BTCUSDT","b":[["77360.40","1.292"],["77358.50","0"]],"a":[],"u":101056042,"seq":800573390595},"cts":1787954797435}
{"topic":"orderbook.50.BTCUSDT","type":"delta","ts":1787954797468,"data":{"s":"BTCUSDT","b":[["77361.80","0.555"],["77360.50","1.292"],["77360.40","0"]],"a":[],"u":101056043,"seq":800573390611},"cts":1787954797465}
{"topic":"orderbook.50.BTCUSDT","type":"delta","ts":1787954797488,"data":{"s":"BTCUSDT","b":[["77360.60","1.296"],["77360.50","0"],["77358.50","0.641"]],"a":[["77377.40","0.258"],["77377.80","0"]],"u":101056044,"seq":800573390644},"cts":1787954797487}
{"topic":"orderbook.50.BTCUSDT","type":"delta","ts":1787954797508,"data":{"s":"BTCUSDT","b":[["77364.60","1.880"],["77364.50","0.007"],["77360.70","1.422"],["77360.60","0.004"]],"a":[["77377.40","0"],["77377.60","0.259"],["77377.80","4.008"]],"u":101056045,"seq":800573390674},"cts":1787954797507}
{"topic":"orderbook.50.BTCUSDT","type":"delta","ts":1787954797529,"data":{"s":"BTCUSDT","b":[["77367.90","7.438"],["77365.90","0.464"],["77360.80","1.292"],["77360.70","0.130"],["77358.50","0"]],"a":[["77373.90","0"],["77374.00","0.003"],["77377.90","14.001"]],"u":101056046,"seq":800573390711},"cts":1787954797527}
{"topic":"orderbook.50.BTCUSDT","type":"delta","ts":1787954797548,"data":{"s":"BTCUSDT","b":[["77360.90","1.292"],["77360.80","0"]],"a":[],"u":101056047,"seq":800573390730},"cts":1787954797543}
{"topic":"orderbook.50.BTCUSDT","type":"delta","ts":1787954797568,"data":{"s":"BTCUSDT","b":[["77360.90","0"],["77358.50","0.641"]],"a":[],"u":101056048,"seq":800573390756},"cts":1787954797563}
{"topic":"orderbook.50.BTCUSDT","type":"delta","ts":1787954797589,"data":{"s":"BTCUSDT","b":[["77361.80","0.193"],["77360.40","1.292"],["77358.50","0"]],"a":[["77377.60","0.001"]],"u":101056049,"seq":800573390792},"cts":1787954797587}
{"topic":"orderbook.50.BTCUSDT","type":"delta","ts":1787954797608,"data":{"s":"BTCUSDT","b":[["77361.80","0.555"],["77360.50","1.292"],["77360.40","0"]],"a":[],"u":101056050,"seq":800573390815},"cts":1787954797604}
{"topic":"orderbook.50.BTCUSDT","type":"delta","ts":1787954797629,"data":{"s":"BTCUSDT","b":[["77360.60","1.296"],["77360.50","0"],["77358.50","0.641"]],"a":[],"u":101056051,"seq":800573390828},"cts":1787954797616}
{"topic":"orderbook.50.BTCUSDT","type":"delta","ts":1787954797649,"data":{"s":"BTCUSDT","b":[["77360.70","1.422"],["77360.60","0.004"]],"a":[],"u":101056052,"seq":800573390850},"cts":1787954797641}
{"topic":"orderbook.50.BTCUSDT","type":"delta","ts":1787954797668,"data":{"s":"BTCUSDT","b":[["77366.50","0"],["77360.80","1.292"],["77360.70","0.130"]],"a":[],"u":101056053,"seq":800573390879},"cts":1787954797661}
{"topic":"orderbook.50.BTCUSDT","type":"delta","ts":1787954797688,"data":{"s":"BTCUSDT","b":[["77360.90","1.292"],["77360.80","0"]],"a":[],"u":101056054,"seq":800573390910},"cts":1787954797687}
{"topic":"orderbook.50.BTCUSDT","type":"delta","ts":1787954797708,"data":{"s":"BTCUSDT","b":[["77366.40","0"],["77365.90","0.434"],["77361.30","1.292"],["77360.90","0"],["77358.30","0.006"]],"a":[],"u":101056055,"seq":800573390948},"cts":1787954797705}
{"topic":"orderbook.50.BTCUSDT","type":"delta","ts":1787954797728,"data":{"s":"BTCUSDT","b":[["77367.90","7.306"],["77361.30","0"],["77358.20","0.002"]],"a":[["77373.60","0.003"],["77374.00","0.001"],["77376.50","0.002"],["77377.40","0.002"],["77377.60","0.259"],["77377.80","0"],["77377.90","0"]],"u":101056056,"seq":800573391003},"cts":1787954797723}
{"topic":"orderbook.50.BTCUSDT","type":"delta","ts":1787954797748,"data":{"s":"BTCUSDT","b":[["77361.80","0.193"],["77360.40","1.292"],["77358.20","0"]],"a":[["77375.50","0.386"],["77376.50","0"]],"u":101056057,"seq":800573391038},"cts":1787954797747}
{"topic":"orderbook.50.BTCUSDT","type":"delta","ts":1787954797768,"data":{"s":"BTCUSDT","b":[["77361.80","0.555"]],"a":[["77373.50","0.002"],["77373.60","0.001"],["77377.60","0.001"],["77377.70","0"]],"u":101056058,"seq":800573391073},"cts":1787954797766}
{"topic":"orderbook.50.BTCUSDT","type":"delta","ts":1787954797789,"data":{"s":"BTCUSDT","b":[["77365.90","0.409"]],"a":[],"u":101056059,"seq":800573391093},"cts":1787954797783}
{"topic":"orderbook.50.BTCUSDT","type":"delta","ts":1787954797809,"data":{"s":"BTCUSDT","b":[["77365.90","0.359"]],"a":[],"u":101056060,"seq":800573391131},"cts":1787954797807}
{"topic":"orderbook.50.BTCUSDT","type":"delta","ts":1787954797828,"data":{"s":"BTCUSDT","b":[],"a":[["77368.10","0.006"]],"u":101056061,"seq":800573391156},"cts":1787954797826}
{"topic":"orderbook.50.BTCUSDT","type":"delta","ts":1787954797848,"data":{"s":"BTCUSDT","b":[["77367.90","7.331"]],"a":[["77376.60","0.005"]],"u":101056062,"seq":800573391174},"cts":1787954797842}
{"topic":"orderbook.50.BTCUSDT","type":"delta","ts":1787954797868,"data":{"s":"BTCUSDT","b":[["77367.90","7.356"],["77365.90","0.355"]],"a":[],"u":101056063,"seq":800573391203},"cts":1787954797867}
{"topic":"orderbook.50.BTCUSDT","type":"delta","ts":1787954797888,"data":{"s":"BTCUSDT","b":[["77367.90","7.381"],["77363.70","0"],["77363.60","0.002"],["77358.20","0.002"]],"a":[],"u":101056064,"seq":800573391234},"cts":1787954797886}
{"topic":"orderbook.50.BTCUSDT","type":"delta","ts":1787954797949,"data":{"s":"BTCUSDT","b":[["77360.50","1.292"],["77360.40","0"]],"a":[],"u":101056065,"seq":800573391276},"cts":1787954797940}
{"topic":"orderbook.50.BTCUSDT","type":"delta","ts":1787954797968,"data":{"s":"BTCUSDT","b":[["77361.00","1.017"],["77360.60","1.296"],["77360.50","0"],["77358.10","0.002"]],"a":[],"u":101056066,"seq":800573391298},"cts":1787954797966}
{"topic":"orderbook.50.BTCUSDT","type":"delta","ts":1787954797988,"data":{"s":"BTCUSDT","b":[["77361.80","0.807"],["77360.60","0.004"]],"a":[["77376.60","0.003"]],"u":101056067,"seq":800573391319},"cts":1787954797987}
{"topic":"orderbook.50.BTCUSDT","type":"delta","ts":1787954798009,"data":{"s":"BTCUSDT","b":[["77361.80","0.492"]],"a":[["77376.80","0.002"],["77377.60","0"]],"u":101056068,"seq":800573391350},"cts":1787954798005}
{"topic":"orderbook.50.BTCUSDT","type":"delta","ts":1787954798028,"data":{"s":"BTCUSDT","b":[],"a":[["77376.10","0.002"],["77377.50","0"]],"u":101056069,"seq":800573391366},"cts":1787954798022}
{"topic":"orderbook.50.BTCUSDT","type":"delta","ts":1787954798048,"data":{"s":"BTCUSDT","b":[],"a":[["77376.10","0"],["77376.80","0"],["77377.40","0"],["77377.50","0.036"],["77377.60","0.001"],["77377.70","0.001"]],"u":101056070,"seq":800573391407},"cts":1787954798047}
{"topic":"orderbook.50.BTCUSDT","type":"delta","ts":1787954798068,"data":{"s":"BTCUSDT","b":[["77367.90","6.586"]],"a":[["77376.40","0.002"],["77377.70","0"]],"u":101056071,"seq":800573391445},"cts":1787954798066}
{"topic":"orderbook.50.BTCUSDT","type":"delta","ts":1787954798108,"data":{"s":"BTCUSDT","b":[],"a":[["77376.40","0"],["77377.20","0.003"],["77377.70","0.001"]],"u":101056072,"seq":800573391474},"cts":1787954798107}
{"topic":"orderbook.50.BTCUSDT","type":"delta","ts":1787954798129,"data":{"s":"BTCUSDT","b":[["77364.50","0.006"],["77361.70","0.001"],["77358.10","0"]],"a":[],"u":101056073,"seq":800573391498},"cts":1787954798124}
{"topic":"orderbook.50.BTCUSDT","type":"delta","ts":1787954798189,"data":{"s":"BTCUSDT","b":[],"a":[["77377.20","0.001"]],"u":101056074,"seq":800573391537},"cts":1787954798174}
{"topic":"orderbook.50.BTCUSDT","type":"delta","ts":1787954798228,"data":{"s":"BTCUSDT","b":[],"a":[["77376.90","0.002"],["77377.70","0"]],"u":101056075,"seq":800573391579},"cts":1787954798226}
{"topic":"orderbook.50.BTCUSDT","type":"delta","ts":1787954798408,"data":{"s":"BTCUSDT","b":[["77364.20","0.006"],["77358.20","0"]],"a":[],"u":101056076,"seq":800573391684},"cts":1787954798407}
{"topic":"orderbook.50.BTCUSDT","type":"delta","ts":1787954798428,"data":{"s":"BTCUSDT","b":[["77364.10","0.037"]],"a":[],"u":101056077,"seq":800573391704},"cts":1787954798426}
{"topic":"orderbook.50.BTCUSDT","type":"delta","ts":1787954798469,"data":{"s":"BTCUSDT","b":[],"a":[["77376.90","0"],["77377.10","0.003"],["77377.70","0.001"]],"u":101056078,"seq":800573391721},"cts":1787954798467}
{"topic":"orderbook.50.BTCUSDT","type":"delta","ts":1787954798488,"data":{"s":"BTCUSDT","b":[],"a":[["77368.00","13.347"]],"u":101056079,"seq":800573391738},"cts":1787954798486}
{"topic":"orderbook.50.BTCUSDT","type":"delta","ts":1787954798608,"data":{"s":"BTCUSDT","b":[["77360.70","0.194"],["77358.60","0.069"]],"a":[["77376.50","0.002"],["77377.70","0"]],"u":101056080,"seq":800573391820},"cts":1787954798606}
{"topic":"orderbook.50.BTCUSDT","type":"delta","ts":1787954798828,"data":{"s":"BTCUSDT","b":[],"a":[["77376.50","0"],["77377.70","0.001"]],"u":101056081,"seq":800573391946},"cts":1787954798825}
{"topic":"orderbook.50.BTCUSDT","type":"delta","ts":1787954798928,"data":{"s":"BTCUSDT","b":[],"a":[["77375.70","0.002"],["77376.40","0.002"],["77377.60","0"],["77377.70","0"]],"u":101056082,"seq":800573392002},"cts":1787954798926}
{"topic":"orderbook.50.BTCUSDT","type":"delta","ts":1787954799109,"data":{"s":"BTCUSDT","b":[],"a":[["77375.70","0"],["77377.60","0.001"]],"u":101056083,"seq":800573392118},"cts":1787954799107}
{"topic":"orderbook.50.BTCUSDT","type":"delta","ts":1787954799128,"data":{"s":"BTCUSDT","b":[],"a":[["77375.80","0.324"]],"u":101056084,"seq":800573392155},"cts":1787954799126}
{"topic":"orderbook.50.BTCUSDT","type":"delta","ts":1787954799148,"data":{"s":"BTCUSDT","b":[],"a":[["77375.80","0.322"]],"u":101056085,"seq":800573392176},"cts":1787954799147}
{"topic":"orderbook.50.BTCUSDT","type":"delta","ts":1787954799188,"data":{"s":"BTCUSDT","b":[["77361.30","0.373"],["77358.30","0"]],"a":[],"u":101056086,"seq":800573392205},"cts":1787954799186}
{"topic":"orderbook.50.BTCUSDT","type":"delta","ts":1787954799208,"data":{"s":"BTCUSDT","b":[["77361.90","0.373"],["77358.50","0"]],"a":[["77376.40","0"],["77377.70","0.001"]],"u":101056087,"seq":800573392241},"cts":1787954799207}
{"topic":"orderbook.50.BTCUSDT","type":"delta","ts":1787954799249,"data":{"s":"BTCUSDT","b":[],"a":[["77377.10","0.001"],["77377.30","0.002"],["77377.70","0"]],"u":101056088,"seq":800573392278},"cts":1787954799246}
{"topic":"orderbook.50.BTCUSDT","type":"delta","ts":1787954799349,"data":{"s":"BTCUSDT","b":[["77367.90","6.715"],["77366.10","0.375"]],"a":[["77377.30","0"],["77377.70","0.001"]],"u":101056089,"seq":800573392343},"cts":1787954799345}
{"topic":"orderbook.50.BTCUSDT","type":"delta","ts":1787954799369,"data":{"s":"BTCUSDT","b":[["77364.80","0.377"]],"a":[],"u":101056090,"seq":800573392360},"cts":1787954799365}
{"topic":"orderbook.50.BTCUSDT","type":"delta","ts":1787954799388,"data":{"s":"BTCUSDT","b":[["77366.20","0.007"],["77361.40","1.292"],["77358.60","0"]],"a":[["77373.50","0"],["77374.60","14.002"],["77377.80","4.008"]],"u":101056091,"seq":800573392433},"cts":1787954799387}
{"topic":"orderbook.50.BTCUSDT","type":"delta","ts":1787954799408,"data":{"s":"BTCUSDT","b":[["77361.80","0.947"],["77361.70","0"],["77358.60","0.069"]],"a":[["77374.50","3.936"],["77374.60","14.000"]],"u":101056092,"seq":800573392493},"cts":1787954799407}
{"topic":"orderbook.50.BTCUSDT","type":"delta","ts":1787954799428,"data":{"s":"BTCUSDT","b":[["77367.90","6.586"],["77365.90","0.322"],["77364.30","0.001"],["77362.00","1.294"],["77361.80","0.946"],["77361.40","0"]],"a":[["77374.40","0"],["77374.50","0.002"],["77375.50","0"],["77375.70","0.002"],["77377.50","0.034"],["77377.70","0.130"],["77377.80","0"],["77377.90","14.001"],["77378.00","0.001"]],"u":101056093,"seq":800573392602},"cts":1787954799424}
{"topic":"orderbook.50.BTCUSDT","type":"delta","ts":1787954799449,"data":{"s":"BTCUSDT","b":[["77367.90","6.716"],["77362.10","1.118"],["77361.80","0.002"],["77361.30","0"]],"a":[["77377.70","0.001"],["77377.80","4.518"],["77378.00","0"]],"u":101056094,"seq":800573392658},"cts":1787954799446}
{"topic":"orderbook.50.BTCUSDT","type":"delta","ts":1787954799468,"data":{"s":"BTCUSDT","b":[["77367.90","6.715"],["77361.90","0"],["77358.50","0.641"]],"a":[["77377.50","0.036"]],"u":101056095,"seq":800573392698},"cts":1787954799467}
{"topic":"orderbook.50.BTCUSDT","type":"delta","ts":1787954799488,"data":{"s":"BTCUSDT","b":[["77362.20","1.292"],["77362.00","0.002"],["77358.50","0"]],"a":[["77374.50","4.285"]],"u":101056096,"seq":800573392722},"cts":1787954799487}
{"topic":"orderbook.50.BTCUSDT","type":"delta","ts":1787954799508,"data":{"s":"BTCUSDT","b":[["77362.30","2.189"],["77362.20","0"],["77362.10","0"],["77358.50","0.641"],["77358.30","0.006"]],"a":[["77374.80","0"],["77377.70","0.130"],["77377.80","4.389"],["77378.00","0.001"]],"u":101056097,"seq":800573392761},"cts":1787954799507}
{"topic":"orderbook.50.BTCUSDT","type":"delta","ts":1787954799529,"data":{"s":"BTCUSDT","b":[["77362.40","2.188"],["77362.30","0.002"],["77358.30","0"]],"a":[],"u":101056098,"seq":800573392807},"cts":1787954799527}
{"topic":"orderbook.50.BTCUSDT","type":"delta","ts":1787954799549,"data":{"s":"BTCUSDT","b":[["77362.50","2.188"],["77362.40","0"],["77358.30","0.006"]],"a":[["77378.00","0"],["77378.20","0.057"]],"u":101056099,"seq":800573392834},"cts":1787954799543}
{"topic":"orderbook.50.BTCUSDT","type":"delta","ts":1787954799568,"data":{"s":"BTCUSDT","b":[["77362.60","2.189"],["77362.50","0.001"]],"a":[["77377.70","0.132"]],"u":101056100,"seq":800573392860},"cts":1787954799561}
{"topic":"orderbook.50.BTCUSDT","type":"delta","ts":1787954799588,"data":{"s":"BTCUSDT","b":[["77362.70","0.896"],["77362.60","0.001"],["77361.30","1.292"],["77358.50","0"],["77358.30","0"]],"a":[],"u":101056101,"seq":800573392875},"cts":1787954799579}
{"topic":"orderbook.50.BTCUSDT","type":"delta","ts":1787954799609,"data":{"s":"BTCUSDT","b":[],"a":[["77374.80","0.001"],["77378.20","0"]],"u":101056102,"seq":800573392902},"cts":1787954799607}
{"topic":"orderbook.50.BTCUSDT","type":"delta","ts":1787954799908,"data":{"s":"BTCUSDT","b":[["77364.50","0.007"],["77364.30","0"],["77358.50","0.641"]],"a":[],"u":101056103,"seq":800573393100},"cts":1787954799907}
{"topic":"orderbook.50.BTCUSDT","type":"delta","ts":1787954799968,"data":{"s":"BTCUSDT","b":[],"a":[["77377.10","0.003"]],"u":101056104,"seq":800573393142},"cts":1787954799967}
{"topic":"orderbook.50.BTCUSDT","type":"delta","ts":1787954800048,"data":{"s":"BTCUSDT","b":[],"a":[["77374.50","4.414"],["77377.70","0.003"]],"u":101056105,"seq":800573393200},"cts":1787954800047}
{"topic":"orderbook.50.BTCUSDT","type":"delta","ts":1787954800088,"data":{"s":"BTCUSDT","b":[],"a":[["77374.50","4.285"],["77377.70","0.132"]],"u":101056106,"seq":800573393229},"cts":1787954800084}
{"topic":"orderbook.50.BTCUSDT","type":"delta","ts":1787954800128,"data":{"s":"BTCUSDT","b":[],"a":[["77374.50","4.414"],["77377.70","0.003"]],"u":101056107,"seq":800573393268},"cts":1787954800125}
{"topic":"orderbook.50.BTCUSDT","type":"delta","ts":1787954800148,"data":{"s":"BTCUSDT","b":[],"a":[["77374.50","4.285"],["77377.10","0.001"],["77377.70","0.132"]],"u":101056108,"seq":800573393283},"cts":1787954800145}
{"topic":"orderbook.50.BTCUSDT","type":"delta","ts":1787954800248,"data":{"s":"BTCUSDT","b":[["77367.90","6.725"]],"a":[["77377.70","0.130"]],"u":101056109,"seq":800573393391},"cts":1787954800246}
{"topic":"orderbook.50.BTCUSDT","type":"delta","ts":1787954801168,"data":{"s":"BTCUSDT","b":[["77361.00","1.003"]],"a":[],"u":101056110,"seq":800573393952},"cts":1787954801166}
{"topic":"orderbook.50.BTCUSDT","type":"delta","ts":1787954801489,"data":{"s":"BTCUSDT","b":[],"a":[["77368.00","13.348"]],"u":101056111,"seq":800573394144},"cts":1787954801485}
{"topic":"orderbook.50.BTCUSDT","type":"delta","ts":1787954801508,"data":{"s":"BTCUSDT","b":[],"a":[["77368.10","0.007"]],"u":101056112,"seq":800573394159},"cts":1787954801507}
{"topic":"orderbook.50.BTCUSDT","type":"delta","ts":1787954801549,"data":{"s":"BTCUSDT","b":[],"a":[["77377.10","0.003"]],"u":101056113,"seq":800573394181},"cts":1787954801543}
{"topic":"orderbook.50.BTCUSDT","type":"delta","ts":1787954801788,"data":{"s":"BTCUSDT","b":[],"a":[["77377.10","0.001"],["77377.60","0.003"]],"u":101056114,"seq":800573394355},"cts":1787954801778}
{"topic":"orderbook.50.BTCUSDT","type":"delta","ts":1787954802029,"data":{"s":"BTCUSDT","b":[["77358.70","0.659"]],"a":[["77375.70","0"],["77375.90","0.004"],["77377.60","0.001"],["77377.80","4.391"],["77378.00","0.001"]],"u":101056115,"seq":800573394534},"cts":1787954802022}
{"topic":"orderbook.50.BTCUSDT","type":"delta","ts":1787954802048,"data":{"s":"BTCUSDT","b":[],"a":[["77377.80","4.389"]],"u":101056116,"seq":800573394552},"cts":1787954802047}
{"topic":"orderbook.50.BTCUSDT","type":"delta","ts":1787954802068,"data":{"s":"BTCUSDT","b":[],"a":[["77375.90","0.002"],["77376.10","0.002"],["77378.00","0"]],"u":101056117,"seq":800573394568},"cts":1787954802066}
{"topic":"orderbook.50.BTCUSDT","type":"delta","ts":1787954802128,"data":{"s":"BTCUSDT","b":[["77359.00","0.848"],["77358.70","0.002"]],"a":[],"u":101056118,"seq":800573394610},"cts":1787954802120}
{"topic":"orderbook.50.BTCUSDT","type":"delta","ts":1787954802588,"data":{"s":"BTCUSDT","b":[],"a":[["77368.00","13.350"]],"u":101056119,"seq":800573394882},"cts":1787954802587}
{"topic":"orderbook.50.BTCUSDT","type":"delta","ts":1787954802828,"data":{"s":"BTCUSDT","b":[["77359.10","0.657"],["77359.00","0.200"],["77358.50","0"]],"a":[["77376.10","0"],["77376.50","0.002"]],"u":101056120,"seq":800573395037},"cts":1787954802825}
{"topic":"orderbook.50.BTCUSDT","type":"delta","ts":1787954802848,"data":{"s":"BTCUSDT","b":[["77359.10","0"],["77358.70","0.662"],["77358.50","0.641"]],"a":[["77375.90","0.004"],["77376.50","0"],["77377.10","0.003"],["77378.00","0.001"]],"u":101056121,"seq":800573395061},"cts":1787954802846}
{"topic":"orderbook.50.BTCUSDT","type":"delta","ts":1787954802868,"data":{"s":"BTCUSDT","b":[],"a":[["77377.10","0.001"],["77377.60","0.003"]],"u":101056122,"seq":800573395078},"cts":1787954802866}
{"topic":"orderbook.50.BTCUSDT","type":"delta","ts":1787954802909,"data":{"s":"BTCUSDT","b":[],"a":[["77375.80","0.324"],["77375.90","0.002"]],"u":101056123,"seq":800573395100},"cts":1787954802905}
{"topic":"orderbook.50.BTCUSDT","type":"delta","ts":1787954802948,"data":{"s":"BTCUSDT","b":[["77358.70","0.002"],["77358.60","0.723"]],"a":[],"u":101056124,"seq":800573395135},"cts":1787954802945}
{"topic":"orderbook.50.BTCUSDT","type":"delta","ts":1787954802968,"data":{"s":"BTCUSDT","b":[],"a":[["77375.70","0.002"],["77375.80","0.322"],["77378.00","0"]],"u":101056125,"seq":800573395154},"cts":1787954802967}
{"topic":"orderbook.50.BTCUSDT","type":"delta","ts":1787954803008,"data":{"s":"BTCUSDT","b":[],"a":[["77377.60","0.001"]],"u":101056126,"seq":800573395182},"cts":1787954803007}
{"topic":"orderbook.50.BTCUSDT","type":"delta","ts":1787954803028,"data":{"s":"BTCUSDT","b":[],"a":[["77377.40","0.002"],["77377.90","0"]],"u":101056127,"seq":800573395203},"cts":1787954803025}
{"topic":"orderbook.50.BTCUSDT","type":"delta","ts":1787954803049,"data":{"s":"BTCUSDT","b":[],"a":[["77377.70","0.001"]],"u":101056128,"seq":800573395216},"cts":1787954803045}
{"topic":"orderbook.50.BTCUSDT","type":"delta","ts":1787954803069,"data":{"s":"BTCUSDT","b":[],"a":[["77377.40","0"],["77377.50","0.038"],["77377.90","14.001"]],"u":101056129,"seq":800573395230},"cts":1787954803067}
{"topic":"orderbook.50.BTCUSDT","type":"delta","ts":1787954803089,"data":{"s":"BTCUSDT","b":[["77358.60","0.069"]],"a":[["77377.70","0.130"]],"u":101056130,"seq":800573395240},"cts":1787954803081}
{"topic":"orderbook.50.BTCUSDT","type":"delta","ts":1787954803108,"data":{"s":"BTCUSDT","b":[["77367.90","6.748"]],"a":[],"u":101056131,"seq":800573395263},"cts":1787954803106}
{"topic":"orderbook.50.BTCUSDT","type":"delta","ts":1787954803328,"data":{"s":"BTCUSDT","b":[["77358.90","0.001"]],"a":[],"u":101056132,"seq":800573395407},"cts":1787954803327}
{"topic":"orderbook.50.BTCUSDT","type":"delta","ts":1787954803448,"data":{"s":"BTCUSDT","b":[["77360.40","0.212"],["77358.50","0"]],"a":[],"u":101056133,"seq":800573395476},"cts":1787954803440}
{"topic":"orderbook.50.BTCUSDT","type":"delta","ts":1787954803508,"data":{"s":"BTCUSDT","b":[],"a":[["77368.00","12.850"],["77377.50","0.036"]],"u":101056134,"seq":800573395522},"cts":1787954803507}
{"topic":"orderbook.50.BTCUSDT","type":"delta","ts":1787954803529,"data":{"s":"BTCUSDT","b":[["77364.60","1.867"],["77360.70","0.130"],["77359.80","0.064"],["77358.60","0"]],"a":[["77368.10","0.006"],["77368.50","0.003"]],"u":101056135,"seq":800573395573},"cts":1787954803526}
{"topic":"orderbook.50.BTCUSDT","type":"delta","ts":1787954803588,"data":{"s":"BTCUSDT","b":[],"a":[["77368.00","12.844"],["77368.10","0.004"],["77369.90","0.002"],["77377.90","0"]],"u":101056136,"seq":800573395610},"cts":1787954803584}
{"topic":"orderbook.50.BTCUSDT","type":"delta","ts":1787954803608,"data":{"s":"BTCUSDT","b":[["77361.60","0.350"]],"a":[["77375.70","0"],["77375.80","0.324"],["77377.70","0.001"],["77377.90","14.001"]],"u":101056137,"seq":800573395642},"cts":1787954803607}
{"topic":"orderbook.50.BTCUSDT","type":"delta","ts":1787954803628,"data":{"s":"BTCUSDT","b":[],"a":[["77375.70","0.002"],["77375.80","0.322"],["77377.70","0.130"],["77377.90","0"]],"u":101056138,"seq":800573395672},"cts":1787954803627}
{"topic":"orderbook.50.BTCUSDT","type":"delta","ts":1787954803708,"data":{"s":"BTCUSDT","b":[["77367.90","6.725"]],"a":[],"u":101056139,"seq":800573395743},"cts":1787954803707}
{"topic":"orderbook.50.BTCUSDT","type":"delta","ts":1787954803748,"data":{"s":"BTCUSDT","b":[["77361.40","0.373"],["77358.70","0"]],"a":[["77375.70","0"],["77376.50","0.002"]],"u":101056140,"seq":800573395796},"cts":1787954803747}
{"topic":"orderbook.50.BTCUSDT","type":"delta","ts":1787954803769,"data":{"s":"BTCUSDT","b":[["77367.90","6.900"],["77365.90","0.320"],["77364.90","1.292"],["77364.40","0"],["77361.70","0.129"],["77361.30","0"],["77359.90","0.651"],["77358.80","0"]],"a":[["77374.50","0.002"],["77376.50","0"],["77377.50","0.038"],["77377.90","14.001"]],"u":101056141,"seq":800573395914},"cts":1787954803763}
{"topic":"orderbook.50.BTCUSDT","type":"delta","ts":1787954803789,"data":{"s":"BTCUSDT","b":[["77367.90","6.902"],["77360.50","0.671"],["77359.90","0"]],"a":[],"u":101056142,"seq":800573395962},"cts":1787954803780}
{"topic":"orderbook.50.BTCUSDT","type":"delta","ts":1787954803828,"data":{"s":"BTCUSDT","b":[["77360.50","0"],["77360.40","0.862"],["77358.80","0.001"]],"a":[["77377.50","0.036"],["77377.60","0.003"]],"u":101056143,"seq":800573396026},"cts":1787954803825}
{"topic":"orderbook.50.BTCUSDT","type":"delta","ts":1787954803848,"data":{"s":"BTCUSDT","b":[],"a":[["77374.80","0"],["77377.90","14.002"],["77378.00","0.001"]],"u":101056144,"seq":800573396055},"cts":1787954803840}
{"topic":"orderbook.50.BTCUSDT","type":"delta","ts":1787954803868,"data":{"s":"BTCUSDT","b":[["77361.70","0"],["77361.50","0.129"]],"a":[],"u":101056145,"seq":800573396070},"cts":1787954803856}
{"topic":"orderbook.50.BTCUSDT","type":"delta","ts":1787954803888,"data":{"s":"BTCUSDT","b":[],"a":[["77377.60","0.001"],["77377.70","0.132"]],"u":101056146,"seq":800573396086},"cts":1787954803886}
{"topic":"orderbook.50.BTCUSDT","type":"delta","ts":1787954803929,"data":{"s":"BTCUSDT","b":[["77367.90","6.900"],["77360.50","0.656"],["77360.40","0.212"],["77358.80","0"]],"a":[],"u":101056147,"seq":800573396145},"cts":1787954803926}
{"topic":"orderbook.50.BTCUSDT","type":"delta","ts":1787954803949,"data":{"s":"BTCUSDT","b":[["77367.90","6.902"],["77364.60","1.818"]],"a":[],"u":101056148,"seq":800573396182},"cts":1787954803945}
{"topic":"orderbook.50.BTCUSDT","type":"delta","ts":1787954803968,"data":{"s":"BTCUSDT","b":[],"a":[["77377.70","0.130"],["77377.80","4.391"]],"u":101056149,"seq":800573396203},"cts":1787954803966}
{"topic":"orderbook.50.BTCUSDT","type":"delta","ts":1787954804048,"data":{"s":"BTCUSDT","b":[],"a":[["77377.80","4.389"],["77377.90","14.004"]],"u":101056150,"seq":800573396303},"cts":1787954804048}
{"topic":"orderbook.50.BTCUSDT","type":"delta","ts":1787954804069,"data":{"s":"BTCUSDT","b":[["77367.90","6.915"]],"a":[],"u":101056151,"seq":800573396342},"cts":1787954804066}
{"topic":"orderbook.50.BTCUSDT","type":"delta","ts":1787954804089,"data":{"s":"BTCUSDT","b":[["77367.90","6.914"]],"a":[],"u":101056152,"seq":800573396369},"cts":1787954804087}
{"topic":"orderbook.50.BTCUSDT","type":"delta","ts":1787954804248,"data":{"s":"BTCUSDT","b":[["77367.90","6.915"]],"a":[],"u":101056153,"seq":800573396570},"cts":1787954804246}
{"topic":"orderbook.50.BTCUSDT","type":"delta","ts":1787954804309,"data":{"s":"BTCUSDT","b":[["77361.50","0"],["77361.30","0.129"]],"a":[["77368.80","0"],["77377.80","4.391"],["77377.90","14.002"],["77378.20","0.057"]],"u":101056154,"seq":800573396636},"cts":1787954804306}
{"topic":"orderbook.50.BTCUSDT","type":"delta","ts":1787954804329,"data":{"s":"BTCUSDT","b":[["77367.90","6.914"]],"a":[],"u":101056155,"seq":800573396673},"cts":1787954804319}
{"topic":"orderbook.50.BTCUSDT","type":"delta","ts":1787954804448,"data":{"s":"BTCUSDT","b":[["77367.40","0.100"],["77358.90","0"]],"a":[],"u":101056156,"seq":800573396813},"cts":1787954804445}
{"topic":"orderbook.50.BTCUSDT","type":"delta","ts":1787954804468,"data":{"s":"BTCUSDT","b":[["77367.90","6.963"]],"a":[],"u":101056157,"seq":800573396847},"cts":1787954804465}
{"topic":"orderbook.50.BTCUSDT","type":"delta","ts":1787954804489,"data":{"s":"BTCUSDT","b":[["77361.50","0.129"],["77361.30","0"],["77360.80","0.648"],["77360.50","0"]],"a":[["77377.80","4.389"],["77377.90","14.004"]],"u":101056158,"seq":800573396871},"cts":1787954804485}
{"topic":"orderbook.50.BTCUSDT","type":"delta","ts":1787954804509,"data":{"s":"BTCUSDT","b":[["77361.50","0"],["77361.30","0.129"],["77360.80","0"],["77360.50","0.666"]],"a":[["77377.80","4.391"],["77377.90","14.002"]],"u":101056159,"seq":800573396903},"cts":1787954804505}
{"topic":"orderbook.50.BTCUSDT","type":"delta","ts":1787954804528,"data":{"s":"BTCUSDT","b":[["77364.90","0"],["77361.70","1.292"],["77360.50","0"],["77359.90","0.662"]],"a":[["77377.40","0.002"],["77377.80","4.389"],["77378.20","0"]],"u":101056160,"seq":800573396940},"cts":1787954804526}
{"topic":"orderbook.50.BTCUSDT","type":"delta","ts":1787954804549,"data":{"s":"BTCUSDT","b":[["77364.60","1.819"],["77364.50","0.006"],["77361.30","0"],["77358.90","0.001"]],"a":[["77377.10","0.003"],["77377.40","0"],["77378.20","0.057"]],"u":101056161,"seq":800573396974},"cts":1787954804545}
{"topic":"orderbook.50.BTCUSDT","type":"delta","ts":1787954804608,"data":{"s":"BTCUSDT","b":[["77364.60","1.818"],["77364.50","0.007"]],"a":[["77377.00","0.003"],["77377.10","0.001"]],"u":101056162,"seq":800573397027},"cts":1787954804607}
{"topic":"orderbook.50.BTCUSDT","type":"delta","ts":1787954804648,"data":{"s":"BTCUSDT","b":[["77359.90","0"],["77359.50","0.679"]],"a":[],"u":101056163,"seq":800573397059},"cts":1787954804642}
{"topic":"orderbook.50.BTCUSDT","type":"delta","ts":1787954804669,"data":{"s":"BTCUSDT","b":[["77359.50","0.659"]],"a":[["77376.90","0.002"],["77377.00","0.001"],["77378.20","0"]],"u":101056164,"seq":800573397094},"cts":1787954804664}
{"topic":"orderbook.50.BTCUSDT","type":"delta","ts":1787954804768,"data":{"s":"BTCUSDT","b":[["77367.90","6.961"]],"a":[],"u":101056165,"seq":800573397163},"cts":1787954804763}
{"topic":"orderbook.50.BTCUSDT","type":"delta","ts":1787954804809,"data":{"s":"BTCUSDT","b":[["77367.90","6.963"],["77359.50","0.647"]],"a":[],"u":101056166,"seq":800573397222},"cts":1787954804806}
{"topic":"orderbook.50.BTCUSDT","type":"delta","ts":1787954804829,"data":{"s":"BTCUSDT","b":[["77367.90","6.964"]],"a":[],"u":101056167,"seq":800573397279},"cts":1787954804827}
{"topic":"orderbook.50.BTCUSDT","type":"delta","ts":1787954804848,"data":{"s":"BTCUSDT","b":[["77366.10","0.002"],["77364.80","0.004"],["77361.60","0.001"],["77361.40","0"],["77359.50","0"],["77358.80","0.001"],["77358.70","0.002"]],"a":[["77374.50","0.131"],["77377.50","0.038"],["77377.70","0.001"]],"u":101056168,"seq":800573397330},"cts":1787954804847}
{"topic":"orderbook.50.BTCUSDT","type":"delta","ts":1787954804868,"data":{"s":"BTCUSDT","b":[["77367.90","6.893"],["77366.20","0.001"],["77361.70","0"],["77361.30","1.292"]],"a":[["77368.80","0.001"],["77374.00","0.003"],["77374.30","0.002"],["77374.50","4.413"],["77375.50","0.386"],["77375.90","0.004"],["77376.90","0"],["77377.00","0.003"],["77377.50","0.296"],["77377.90","0"],["77378.00","0"]],"u":101056169,"seq":800573397394},"cts":1787954804867}
{"topic":"orderbook.50.BTCUSDT","type":"delta","ts":1787954804888,"data":{"s":"BTCUSDT","b":[["77367.90","6.891"],["77364.00","0.048"]],"a":[["77373.80","0.003"]],"u":101056170,"seq":800573397438},"cts":1787954804884}
{"topic":"orderbook.50.BTCUSDT","type":"delta","ts":1787954804909,"data":{"s":"BTCUSDT","b":[],"a":[["77373.80","0.001"],["77373.90","0.002"],["77374.00","0.001"],["77374.40","0.129"],["77374.50","4.284"],["77377.70","0"],["77377.80","0"]],"u":101056171,"seq":800573397473},"cts":1787954804907}
{"topic":"orderbook.50.BTCUSDT","type":"delta","ts":1787954804928,"data":{"s":"BTCUSDT","b":[["77364.50","0.006"],["77362.60","0.002"]],"a":[],"u":101056172,"seq":800573397503},"cts":1787954804924}
{"topic":"orderbook.50.BTCUSDT","type":"delta","ts":1787954804949,"data":{"s":"BTCUSDT","b":[],"a":[["77374.30","0"],["77374.80","0.003"]],"u":101056173,"seq":800573397541},"cts":1787954804948}
{"topic":"orderbook.50.BTCUSDT","type":"delta","ts":1787954804988,"data":{"s":"BTCUSDT","b":[["77367.90","6.528"],["77361.30","0"],["77358.60","0.069"]],"a":[["77373.50","0.004"],["77373.90","0"]],"u":101056174,"seq":800573397593},"cts":1787954804987}
{"topic":"orderbook.50.BTCUSDT","type":"delta","ts":1787954805008,"data":{"s":"BTCUSDT","b":[["77362.70","0.867"],["77360.50","1.292"],["77358.60","0"]],"a":[["77373.40","0.002"],["77373.50","0.002"],["77377.40","0.258"],["77377.50","0"],["77377.60","0"]],"u":101056175,"seq":800573397631},"cts":1787954805007}
{"topic":"orderbook.50.BTCUSDT","type":"delta","ts":1787954805028,"data":{"s":"BTCUSDT","b":[["77360.60","1.296"],["77360.50","0"],["77358.60","0.069"]],"a":[["77377.40","0"],["77377.50","0.038"]],"u":101056176,"seq":800573397658},"cts":1787954805026}
{"topic":"orderbook.50.BTCUSDT","type":"delta","ts":1787954805048,"data":{"s":"BTCUSDT","b":[["77360.70","1.422"],["77360.60","0.004"]],"a":[],"u":101056177,"seq":800573397678},"cts":1787954805041}
{"topic":"orderbook.50.BTCUSDT","type":"delta","ts":1787954805069,"data":{"s":"BTCUSDT","b":[["77360.80","1.292"],["77360.70","0.130"],["77358.60","0"]],"a":[],"u":101056178,"seq":800573397707},"cts":1787954805062}
{"topic":"orderbook.50.BTCUSDT","type":"delta","ts":1787954805088,"data":{"s":"BTCUSDT","b":[["77360.80","0"],["77358.60","0.069"]],"a":[],"u":101056179,"seq":800573397734},"cts":1787954805084}
{"topic":"orderbook.50.BTCUSDT","type":"delta","ts":1787954805109,"data":{"s":"BTCUSDT","b":[["77362.70","0.552"]],"a":[["77377.40","0.258"],["77377.50","0"]],"u":101056180,"seq":800573397760},"cts":1787954805106}
{"topic":"orderbook.50.BTCUSDT","type":"delta","ts":1787954805129,"data":{"s":"BTCUSDT","b":[],"a":[["77377.40","0"],["77377.50","0.296"]],"u":101056181,"seq":800573397786},"cts":1787954805127}
{"topic":"orderbook.50.BTCUSDT","type":"delta","ts":1787954805148,"data":{"s":"BTCUSDT","b":[["77367.90","5.323"],["77360.50","1.292"],["77358.60","0"]],"a":[["77372.10","0.003"],["77372.90","0.002"],["77377.00","0.001"],["77377.50","0"]],"u":101056182,"seq":800573397848},"cts":1787954805147}
{"topic":"orderbook.50.BTCUSDT","type":"delta","ts":1787954805168,"data":{"s":"BTCUSDT","b":[["77367.80","0.001"],["77367.60","0.002"],["77362.70","0.867"],["77359.80","0"]],"a":[["77371.40","0.002"],["77375.90","0.002"],["77377.20","0"]],"u":101056183,"seq":800573397884},"cts":1787954805167}
{"topic":"orderbook.50.BTCUSDT","type":"delta","ts":1787954805188,"data":{"s":"BTCUSDT","b":[],"a":[["77371.40","0"],["77377.20","0.001"]],"u":101056184,"seq":800573397903},"cts":1787954805187}
{"topic":"orderbook.50.BTCUSDT","type":"delta","ts":1787954805229,"data":{"s":"BTCUSDT","b":[["77362.60","0.001"],["77360.90","0.001"],["77358.70","0"]],"a":[["77372.10","0.001"],["77372.90","0"],["77374.00","0.003"],["77375.30","0.002"]],"u":101056185,"seq":800573397946},"cts":1787954805226}
{"topic":"orderbook.50.BTCUSDT","type":"delta","ts":1787954805489,"data":{"s":"BTCUSDT","b":[["77367.90","5.324"]],"a":[],"u":101056186,"seq":800573398088},"cts":1787954805485}
{"topic":"orderbook.50.BTCUSDT","type":"delta","ts":1787954805508,"data":{"s":"BTCUSDT","b":[["77364.60","1.816"]],"a":[],"u":101056187,"seq":800573398107},"cts":1787954805507}
{"topic":"orderbook.50.BTCUSDT","type":"delta","ts":1787954805528,"data":{"s":"BTCUSDT","b":[["77367.90","5.346"]],"a":[["77373.50","0"],["77374.00","0.001"],["77375.80","0.324"],["77376.20","0.003"],["77377.50","0.036"]],"u":101056188,"seq":800573398134},"cts":1787954805527}
{"topic":"orderbook.50.BTCUSDT","type":"delta","ts":1787954805548,"data":{"s":"BTCUSDT","b":[],"a":[["77373.30","0.002"],["77373.40","0"]],"u":101056189,"seq":800573398151},"cts":1787954805543}
{"topic":"orderbook.50.BTCUSDT","type":"delta","ts":1787954805569,"data":{"s":"BTCUSDT","b":[],"a":[["77373.30","0"],["77373.50","0.002"]],"u":101056190,"seq":800573398160},"cts":1787954805561}
{"topic":"orderbook.50.BTCUSDT","type":"delta","ts":1787954805608,"data":{"s":"BTCUSDT","b":[["77367.90","5.345"]],"a":[],"u":101056191,"seq":800573398190},"cts":1787954805607}
{"topic":"orderbook.50.BTCUSDT","type":"delta","ts":1787954805728,"data":{"s":"BTCUSDT","b":[],"a":[["77373.50","0.004"]],"u":101056192,"seq":800573398246},"cts":1787954805723}
{"topic":"orderbook.50.BTCUSDT","type":"delta","ts":1787954805749,"data":{"s":"BTCUSDT","b":[],"a":[["77373.40","0.002"],["77373.50","0.002"],["77377.50","0"]],"u":101056193,"seq":800573398265},"cts":1787954805741}
{"topic":"orderbook.50.BTCUSDT","type":"delta","ts":1787954806048,"data":{"s":"BTCUSDT","b":[["77367.90","5.089"]],"a":[["77368.00","12.845"],["77368.50","0.002"],["77371.80","0.003"],["77376.20","0.001"]],"u":101056194,"seq":800573398494},"cts":1787954806047}
